Workbook

Sheet README
B2: README sheet
B5: General information
B7: Main paper title | C7: Residual biomass to bio-based chemicals and plastics: ex-ante screening methodology for prioritizing high-impact substitutions
B8: Authors | C8: Nicolas LIENART, Thibaut LECOMPTE, Lorie HAMELIN
B9: Contact (Nicolas Lienart) | C9: nicolas.lienart@insa-toulouse.fr
B10: Contact (Thibaut Lecompte) | C10: thibaut.lecompte@univ-ubs.fr
B11: Contact (Lorie Hamelin) | C11: lorie.hamelin@insa-toulouse.fr
B12: Description | C12: This file is used to compute the estimation of France (EXIOBASE FR region) and the European Union (EU27, 2020) sectors GHG footprint with respect to what is imported and locally produced based on EXIOBASE data and the code available in the git repository. Sectors (or products in EXIOBASE terms) are not cumulative as they depend on each other.
B13: EXIOBASE version | C13: v3.10.2 - IOT_2019_pxp and IOT_2022_pxp
B14: Note | C14: This file is part of a set of supplementary materials. Please refer to the main manuscript and the accompanying document to find other materials and for a description of their usage.
B15: Git repository (Forge INRAE) | C15: https://forge.inrae.fr/nicolas.lienart/screen-lca-paper-supplementary-code
B16: Git repository (GitHub) | C16: https://github.com/nicolnt/screen-lca-paper-supplementary-code
B19: Updates
B21: Date | C21: Note
B22: 46146 | C22: Ready for submission
B23: 46240 | C23: Updated sheet names for consistency with the Python notebook. Clarified each sheet and table content. Corrected small typos
B24: 46241 | C24: Updated values with corrected and complete characterization factors
B27: Sheet structure
B29: Sheet name | C29: Description
B30: README | C30: This sheet. Contains meta information about this Excel file and its structure.
B31: 1.1 Y_FR_imports_2019 | C31: ='1.1 Y_FR_imports_2019'!$B$1 -> Imported data from the Prodcom Python notebook: Imported final demand footprint in France per product (2019)
B32: 1.2 Z_FR_imports_2019 | C32: ='1.2 Z_FR_imports_2019'!$B$1 -> Imported data from the Prodcom Python notebook: Imported intermediate demand footprint in France per product (2019)
B33: 2.1 Y_FR_production_2019 | C33: ='2.1 Y_FR_production_2019'!$B$1 -> Imported data from the Prodcom Python notebook: Production footprint in France per product, for final demand (France and exports) (2019)
B34: 2.2 Z_FR_production_2019 | C34: ='2.2 Z_FR_production_2019'!$B$1 -> Imported data from the Prodcom Python notebook: Production footprint in France per product, for intermediate demand (France and exports) (2019)
B35: Summary_FR_2019 | C35: =Summary_FR_2019!$B$1 -> Combines and summarizes the data of the four footprint sheets for France and year 2019
B36: 1.1 Y_FR_imports_2022 | C36: ='1.1 Y_FR_imports_2022'!$B$1 -> Imported data from the Prodcom Python notebook: Imported final demand footprint in France per product (2022)
B37: 1.2 Z_FR_imports_2022 | C37: ='1.2 Z_FR_imports_2022'!$B$1 -> Imported data from the Prodcom Python notebook: Imported intermediate demand footprint in France per product (2022)
B38: 2.1 Y_FR_production_2022 | C38: ='2.1 Y_FR_production_2022'!$B$1 -> Imported data from the Prodcom Python notebook: Production footprint in France per product, for final demand (France and exports) (2022)
B39: 2.2 Z_FR_production_2022 | C39: ='2.2 Z_FR_production_2022'!$B$1 -> Imported data from the Prodcom Python notebook: Production footprint in France per product, for intermediate demand (France and exports) (2022)
B40: Summary_FR_2022 | C40: =Summary_FR_2022!$B$1 -> Combines and summarizes the data of the four footprint sheets for France and year 2022
B41: 1.1 Y_EU27_imports_2019 | C41: ='1.1 Y_EU27_imports_2019'!$B$1 -> Imported data from the Prodcom Python notebook: Imported final demand footprint in the European Union (EU27 2020) per product (2019)
B42: 1.2 Z_EU27_imports_2019 | C42: ='1.2 Z_EU27_imports_2019'!$B$1 -> Imported data from the Prodcom Python notebook: Imported intermediate demand footprint in the European Union (EU27 2020) per product (2019)
B43: 2.1 Y_EU27_production_2019 | C43: ='2.1 Y_EU27_production_2019'!$B$1 -> Imported data from the Prodcom Python notebook: Production footprint in the European Union (EU27 2020) per product, for final demand (EU27 and exports) (2019)
B44: 2.2 Z_EU27_production_2019 | C44: ='2.2 Z_EU27_production_2019'!$B$1 -> Imported data from the Prodcom Python notebook: Production footprint in the European Union (EU27 2020) per product, for intermediate demand (EU27 and exports) (2019)
B45: Summary_EU27_2019 | C45: =Summary_EU27_2019!$B$1 -> Combines and summarizes the data of the four footprint sheets for the European Union (EU27 2020) and year 2019
B46: 1.1 Y_EU27_imports_2022 | C46: ='1.1 Y_EU27_imports_2022'!$B$1 -> Imported data from the Prodcom Python notebook: Imported final demand footprint in the European Union (EU27 2020) per product (2022)
B47: 1.2 Z_EU27_imports_2022 | C47: ='1.2 Z_EU27_imports_2022'!$B$1 -> Imported data from the Prodcom Python notebook: Imported intermediate demand footprint in the European Union (EU27 2020) per product (2022)
B48: 2.1 Y_EU27_production_2022 | C48: ='2.1 Y_EU27_production_2022'!$B$1 -> Imported data from the Prodcom Python notebook: Production footprint in the European Union (EU27 2020) per product, for final demand (EU27 and exports) (2022)
B49: 2.2 Z_EU27_production_2022 | C49: ='2.2 Z_EU27_production_2022'!$B$1 -> Imported data from the Prodcom Python notebook: Production footprint in the European Union (EU27 2020) per product, for intermediate demand (EU27 and exports) (2022)
B50: Summary_EU27_2022 | C50: =Summary_EU27_2022!$B$1 -> Combines and summarizes the data of the four footprint sheets for the European Union (EU27 2020) and year 2022
...

Sheet 1.1 Y_FR_imports_2019
A1: Sheet description: | B1: Imported data from the Prodcom Python notebook: Imported final demand footprint in France per product (2019)
A2: Indicator | B2: GHG characterized with IPCC 2021 - climate change: total (excl. biogenic CO2) (GWP100, kg CO2-Eq) - see EXIOBASE calculation notebook in the SI.
A4: sector | B4: climate change: total (excl. biogenic CO2)
A5: Additives/Blending Components | B5: 0.059331955
A6: Air transport services (62) | B6: 2.0975694e+10
A7: Aluminium and aluminium products | B7: 18290370
A8: Aluminium ores and concentrates | B8: 300801.52
A9: Animal products nec | B9: 60817812
A10: Anthracite | B10: 158.34746
A11: Ash for treatment, Re-processing of ash into clinker | B11: 0
A12: Aviation Gasoline | B12: 0.00094241806
A13: BKB/Peat Briquettes | B13: 0.0013709437
A14: Basic iron and steel and of ferro-alloys and first products thereof | B14: 70363734
A15: Beverages | B15: 1.2883615e+09
A16: Biodiesels | B16: 0
... A204: products of Vegetable oils and fats | B204: 1.7560371e+08

Sheet 1.2 Z_FR_imports_2019
A1: Sheet description: | B1: Imported data from the Prodcom Python notebook: Imported intermediate demand footprint in France per product (2019)
A2: Indicator | B2: GHG characterized with IPCC 2021 - climate change: total (excl. biogenic CO2) (GWP100, kg CO2-Eq) - see EXIOBASE calculation notebook in the SI.
A4: sector | B4: climate change: total (excl. biogenic CO2)
A5: Additives/Blending Components | B5: 1.5219609e+08
A6: Air transport services (62) | B6: 3.9493023e+09
A7: Aluminium and aluminium products | B7: 5.0754362e+09
A8: Aluminium ores and concentrates | B8: 48147564
A9: Animal products nec | B9: 1.3193221e+08
A10: Anthracite | B10: 1.8190744e+08
A11: Ash for treatment, Re-processing of ash into clinker | B11: 0
A12: Aviation Gasoline | B12: 900764.46
A13: BKB/Peat Briquettes | B13: 34754855
A14: Basic iron and steel and of ferro-alloys and first products thereof | B14: 1.4203273e+10
A15: Beverages | B15: 6.8745622e+08
A16: Biodiesels | B16: 1.4927272e+08
... A204: products of Vegetable oils and fats | B204: 8.8417183e+08

Sheet 2.1 Y_FR_production_2019
A1: Sheet description: | B1: Imported data from the Prodcom Python notebook: Production footprint in France per product, for final demand (France and exports) (2019)
A2: Indicator | B2: GHG characterized with IPCC 2021 - climate change: total (excl. biogenic CO2) (GWP100, kg CO2-Eq) - see EXIOBASE calculation notebook in the SI.
A4: sector | B4: climate change: total (excl. biogenic CO2)
A5: Additives/Blending Components | B5: 4210292.1
A6: Air transport services (62) | B6: 1.8479111e+10
A7: Aluminium and aluminium products | B7: 73836479
A8: Aluminium ores and concentrates | B8: 161193.05
A9: Animal products nec | B9: 3.5981677e+08
A10: Anthracite | B10: 0
A11: Ash for treatment, Re-processing of ash into clinker | B11: 0
A12: Aviation Gasoline | B12: 3636.6809
A13: BKB/Peat Briquettes | B13: 0
A14: Basic iron and steel and of ferro-alloys and first products thereof | B14: 5.6655079e+08
A15: Beverages | B15: 8.1896294e+09
A16: Biodiesels | B16: 1.8501883e+08
... A204: products of Vegetable oils and fats | B204: 14685855

Sheet 2.2 Z_FR_production_2019
A1: Sheet description: | B1: Imported data from the Prodcom Python notebook: Production footprint in France per product, for intermediate demand (France and exports) (2019)
A2: Indicator | B2: GHG characterized with IPCC 2021 - climate change: total (excl. biogenic CO2) (GWP100, kg CO2-Eq) - see EXIOBASE calculation notebook in the SI.
A4: sector | B4: climate change: total (excl. biogenic CO2)
A5: Additives/Blending Components | B5: 1.6047978e+08
A6: Air transport services (62) | B6: 1.1300554e+10
A7: Aluminium and aluminium products | B7: 2.026107e+09
A8: Aluminium ores and concentrates | B8: 5336596.9
A9: Animal products nec | B9: 1.7671064e+08
A10: Anthracite | B10: 0
A11: Ash for treatment, Re-processing of ash into clinker | B11: 0
A12: Aviation Gasoline | B12: 1675422.5
A13: BKB/Peat Briquettes | B13: 0
A14: Basic iron and steel and of ferro-alloys and first products thereof | B14: 1.6027617e+10
A15: Beverages | B15: 5.7701377e+09
A16: Biodiesels | B16: 8.8845238e+08
... A204: products of Vegetable oils and fats | B204: 67325138

Sheet Summary_FR_2019
A1: Sheet description: | B1: Combines and summarizes the data of the four footprint sheets for France and year 2019
A2: Indicator | B2: GHG characterized with IPCC 2021 - climate change: total (excl. biogenic CO2) (GWP100, kg CO2-Eq) - see EXIOBASE calculation notebook in the SI.
D4: % Plastics, basic | E4: % Chemicals nec
A5: D_cba | B5: consumption-based accounts | C5: 582000000000 | D5: =VLOOKUP("Plastics, basic", $A$10:$B$209, 2, FALSE)/$C5 -> 0.036618748 | E5: =VLOOKUP("Chemicals nec", $A$10:$B$209, 2, FALSE)/$C5 -> 0.040855233
A6: D_pba | B6: production-based accounts | C6: 416000000000 | D6: =VLOOKUP("Plastics, basic", $A$10:$B$209, 2, FALSE)/$C6 -> 0.051231037 | E6: =VLOOKUP("Chemicals nec", $A$10:$B$209, 2, FALSE)/$C6 -> 0.057158042
A7: F_Y | B7: factor production final demand | C7: 74900000000 | D7: =VLOOKUP("Plastics, basic", $A$10:$B$209, 2, FALSE)/$C7 -> 0.28454087 | E7: =VLOOKUP("Chemicals nec", $A$10:$B$209, 2, FALSE)/$C7 -> 0.31745988
A9: Product | B9: Total (kg CO2 eq.) | C9: 1.1 Y_imports | D9: 1.2 Z_imports | E9: 2.1 Y_production | F9: 2.2 Z_production | G9: Imports | H9: Production
A10: Construction work (45) | B10: =SUM(C10:F10) -> 8.5893511e+10 | C10: =VLOOKUP(A10, output_exiobase_v3.10.2_EXIO_IOT_2019_pxp_Y_imports_footprint_FR[], 2, FALSE) -> 74759583 | D10: =VLOOKUP(A10, output_exiobase_v3.10.2_EXIO_IOT_2019_pxp_Z_imports_footprint_FR[], 2, FALSE) -> 3.3569713e+09 | E10: =VLOOKUP(A10, output_exiobase_v3.10.2_EXIO_IOT_2019_pxp_Y_production_footprint_FR[], 2, FALSE) -> 6.459968e+10 | F10: =VLOOKUP(A10, output_exiobase_v3.10.2_EXIO_IOT_2019_pxp_Z_production_footprint_FR[], 2, FALSE) -> 1.7862101e+10 | G10: =(C10+D10)/B10 -> 0.039953319 | H10: =(E10+F10)/B10 -> 0.96004668
A11: Sea and coastal water transportation services | B11: =SUM(C11:F11) -> 6.5082726e+10 | C11: =VLOOKUP(A11, output_exiobase_v3.10.2_EXIO_IOT_2019_pxp_Y_imports_footprint_FR[], 2, FALSE) -> 2.9143207e+10 | D11: =VLOOKUP(A11, output_exiobase_v3.10.2_EXIO_IOT_2019_pxp_Z_imports_footprint_FR[], 2, FALSE) -> 8.9033167e+09 | E11: =VLOOKUP(A11, output_exiobase_v3.10.2_EXIO_IOT_2019_pxp_Y_production_footprint_FR[], 2, FALSE) -> 4.6571727e+09 | F11: =VLOOKUP(A11, output_exiobase_v3.10.2_EXIO_IOT_2019_pxp_Z_production_footprint_FR[], 2, FALSE) -> 2.237903e+10 | G11: =(C11+D11)/B11 -> 0.58458712 | H11: =(E11+F11)/B11 -> 0.41541288
A12: Air transport services (62) | B12: =SUM(C12:F12) -> 5.4704661e+10 | C12: =VLOOKUP(A12, output_exiobase_v3.10.2_EXIO_IOT_2019_pxp_Y_imports_footprint_FR[], 2, FALSE) -> 2.0975694e+10 | D12: =VLOOKUP(A12, output_exiobase_v3.10.2_EXIO_IOT_2019_pxp_Z_imports_footprint_FR[], 2, FALSE) -> 3.9493023e+09 | E12: =VLOOKUP(A12, output_exiobase_v3.10.2_EXIO_IOT_2019_pxp_Y_production_footprint_FR[], 2, FALSE) -> 1.8479111e+10 | F12: =VLOOKUP(A12, output_exiobase_v3.10.2_EXIO_IOT_2019_pxp_Z_production_footprint_FR[], 2, FALSE) -> 1.1300554e+10 | G12: =(C12+D12)/B12 -> 0.45562838 | H12: =(E12+F12)/B12 -> 0.54437162
A13: Other business services (74) | B13: =SUM(C13:F13) -> 5.3326698e+10 | C13: =VLOOKUP(A13, output_exiobase_v3.10.2_EXIO_IOT_2019_pxp_Y_imports_footprint_FR[], 2, FALSE) -> 6.7768294e+08 | D13: =VLOOKUP(A13, output_exiobase_v3.10.2_EXIO_IOT_2019_pxp_Z_imports_footprint_FR[], 2, FALSE) -> 4.4686696e+09 | E13: =VLOOKUP(A13, output_exiobase_v3.10.2_EXIO_IOT_2019_pxp_Y_production_footprint_FR[], 2, FALSE) -> 8.2328075e+09 | F13: =VLOOKUP(A13, output_exiobase_v3.10.2_EXIO_IOT_2019_pxp_Z_production_footprint_FR[], 2, FALSE) -> 3.9947538e+10 | G13: =(C13+D13)/B13 -> 0.096506116 | H13: =(E13+F13)/B13 -> 0.90349388
A14: Food products nec | B14: =SUM(C14:F14) -> 4.4252501e+10 | C14: =VLOOKUP(A14, output_exiobase_v3.10.2_EXIO_IOT_2019_pxp_Y_imports_footprint_FR[], 2, FALSE) -> 1.1632526e+10 | D14: =VLOOKUP(A14, output_exiobase_v3.10.2_EXIO_IOT_2019_pxp_Z_imports_footprint_FR[], 2, FALSE) -> 2.4354086e+09 | E14: =VLOOKUP(A14, output_exiobase_v3.10.2_EXIO_IOT_2019_pxp_Y_production_footprint_FR[], 2, FALSE) -> 2.0325394e+10 | F14: =VLOOKUP(A14, output_exiobase_v3.10.2_EXIO_IOT_2019_pxp_Z_production_footprint_FR[], 2, FALSE) -> 9.8591722e+09 | G14: =(C14+D14)/B14 -> 0.31790146 | H14: =(E14+F14)/B14 -> 0.68209854
A15: Hotel and restaurant services (55) | B15: =SUM(C15:F15) -> 4.053255e+10 | C15: =VLOOKUP(A15, output_exiobase_v3.10.2_EXIO_IOT_2019_pxp_Y_imports_footprint_FR[], 2, FALSE) -> 1.3806979e+09 | D15: =VLOOKUP(A15, output_exiobase_v3.10.2_EXIO_IOT_2019_pxp_Z_imports_footprint_FR[], 2, FALSE) -> 1.0612552e+10 | E15: =VLOOKUP(A15, output_exiobase_v3.10.2_EXIO_IOT_2019_pxp_Y_production_footprint_FR[], 2, FALSE) -> 1.6847624e+10 | F15: =VLOOKUP(A15, output_exiobase_v3.10.2_EXIO_IOT_2019_pxp_Z_production_footprint_FR[], 2, FALSE) -> 1.1691676e+10 | G15: =(C15+D15)/B15 -> 0.29589181 | H15: =(E15+F15)/B15 -> 0.70410819
A16: Dairy products | B16: =SUM(C16:F16) -> 4.0401349e+10 | C16: =VLOOKUP(A16, output_exiobase_v3.10.2_EXIO_IOT_2019_pxp_Y_imports_footprint_FR[], 2, FALSE) -> 3.6388201e+09 | D16: =VLOOKUP(A16, output_exiobase_v3.10.2_EXIO_IOT_2019_pxp_Z_imports_footprint_FR[], 2, FALSE) -> 2.2578102e+09 | E16: =VLOOKUP(A16, output_exiobase_v3.10.2_EXIO_IOT_2019_pxp_Y_production_footprint_FR[], 2, FALSE) -> 1.5898147e+10 | F16: =VLOOKUP(A16, output_exiobase_v3.10.2_EXIO_IOT_2019_pxp_Z_production_footprint_FR[], 2, FALSE) -> 1.8606571e+10 | G16: =(C16+D16)/B16 -> 0.14595132 | H16: =(E16+F16)/B16 -> 0.85404868
A17: Wholesale trade and commission trade services, except of motor vehicles and motorcycles (51) | B17: =SUM(C17:F17) -> 3.8338633e+10 | C17: =VLOOKUP(A17, output_exiobase_v3.10.2_EXIO_IOT_2019_pxp_Y_imports_footprint_FR[], 2, FALSE) -> 0 | D17: =VLOOKUP(A17, output_exiobase_v3.10.2_EXIO_IOT_2019_pxp_Z_imports_footprint_FR[], 2, FALSE) -> 1.6944478e+09 | E17: =VLOOKUP(A17, output_exiobase_v3.10.2_EXIO_IOT_2019_pxp_Y_production_footprint_FR[], 2, FALSE) -> 1.3558666e+10 | F17: =VLOOKUP(A17, output_exiobase_v3.10.2_EXIO_IOT_2019_pxp_Z_production_footprint_FR[], 2, FALSE) -> 2.3085519e+10 | G17: =(C17+D17)/B17 -> 0.044196876 | H17: =(E17+F17)/B17 -> 0.95580312
A18: Motor vehicles, trailers and semi-trailers (34) | B18: =SUM(C18:F18) -> 3.7570119e+10 | C18: =VLOOKUP(A18, output_exiobase_v3.10.2_EXIO_IOT_2019_pxp_Y_imports_footprint_FR[], 2, FALSE) -> 1.9021241e+10 | D18: =VLOOKUP(A18, output_exiobase_v3.10.2_EXIO_IOT_2019_pxp_Z_imports_footprint_FR[], 2, FALSE) -> 4.4384985e+09 | E18: =VLOOKUP(A18, output_exiobase_v3.10.2_EXIO_IOT_2019_pxp_Y_production_footprint_FR[], 2, FALSE) -> 7.903323e+09 | F18: =VLOOKUP(A18, output_exiobase_v3.10.2_EXIO_IOT_2019_pxp_Z_production_footprint_FR[], 2, FALSE) -> 6.2070565e+09 | G18: =(C18+D18)/B18 -> 0.62442548 | H18: =(E18+F18)/B18 -> 0.37557452
A19: Cattle | B19: =SUM(C19:F19) -> 3.4048714e+10 | C19: =VLOOKUP(A19, output_exiobase_v3.10.2_EXIO_IOT_2019_pxp_Y_imports_footprint_FR[], 2, FALSE) -> 1.0292354e+08 | D19: =VLOOKUP(A19, output_exiobase_v3.10.2_EXIO_IOT_2019_pxp_Z_imports_footprint_FR[], 2, FALSE) -> 4.3287925e+08 | E19: =VLOOKUP(A19, output_exiobase_v3.10.2_EXIO_IOT_2019_pxp_Y_production_footprint_FR[], 2, FALSE) -> 3.5546999e+09 | F19: =VLOOKUP(A19, output_exiobase_v3.10.2_EXIO_IOT_2019_pxp_Z_production_footprint_FR[], 2, FALSE) -> 2.9958211e+10 | G19: =(C19+D19)/B19 -> 0.015736359 | H19: =(E19+F19)/B19 -> 0.98426364
A20: Raw milk | B20: =SUM(C20:F20) -> 3.1022705e+10 | C20: =VLOOKUP(A20, output_exiobase_v3.10.2_EXIO_IOT_2019_pxp_Y_imports_footprint_FR[], 2, FALSE) -> 0 | D20: =VLOOKUP(A20, output_exiobase_v3.10.2_EXIO_IOT_2019_pxp_Z_imports_footprint_FR[], 2, FALSE) -> 0 | E20: =VLOOKUP(A20, output_exiobase_v3.10.2_EXIO_IOT_2019_pxp_Y_production_footprint_FR[], 2, FALSE) -> 1.5798576e+08 | F20: =VLOOKUP(A20, output_exiobase_v3.10.2_EXIO_IOT_2019_pxp_Z_production_footprint_FR[], 2, FALSE) -> 3.0864719e+10 | G20: =(C20+D20)/B20 -> 0 | H20: =(E20+F20)/B20 -> 1
A21: Basic iron and steel and of ferro-alloys and first products thereof | B21: =SUM(C21:F21) -> 3.0867805e+10 | C21: =VLOOKUP(A21, output_exiobase_v3.10.2_EXIO_IOT_2019_pxp_Y_imports_footprint_FR[], 2, FALSE) -> 70363734 | D21: =VLOOKUP(A21, output_exiobase_v3.10.2_EXIO_IOT_2019_pxp_Z_imports_footprint_FR[], 2, FALSE) -> 1.4203273e+10 | E21: =VLOOKUP(A21, output_exiobase_v3.10.2_EXIO_IOT_2019_pxp_Y_production_footprint_FR[], 2, FALSE) -> 5.6655079e+08 | F21: =VLOOKUP(A21, output_exiobase_v3.10.2_EXIO_IOT_2019_pxp_Z_production_footprint_FR[], 2, FALSE) -> 1.6027617e+10 | G21: =(C21+D21)/B21 -> 0.4624118 | H21: =(E21+F21)/B21 -> 0.5375882
... A209: Extra-territorial organizations and bodies | B209: =SUM(C209:F209) -> 0 | C209: =VLOOKUP(A209, output_exiobase_v3.10.2_EXIO_IOT_2019_pxp_Y_imports_footprint_FR[], 2, FALSE) -> 0 | D209: =VLOOKUP(A209, output_exiobase_v3.10.2_EXIO_IOT_2019_pxp_Z_imports_footprint_FR[], 2, FALSE) -> 0 | E209: =VLOOKUP(A209, output_exiobase_v3.10.2_EXIO_IOT_2019_pxp_Y_production_footprint_FR[], 2, FALSE) -> 0 | F209: =VLOOKUP(A209, output_exiobase_v3.10.2_EXIO_IOT_2019_pxp_Z_production_footprint_FR[], 2, FALSE) -> 0 | G209: =(C209+D209)/B209 -> #DIV/0! | H209: =(E209+F209)/B209 -> #DIV/0!

Sheet 1.1 Y_FR_imports_2022
A1: Sheet description: | B1: Imported data from the Prodcom Python notebook: Imported final demand footprint in France per product (2022)
A2: Indicator | B2: GHG characterized with IPCC 2021 - climate change: total (excl. biogenic CO2) (GWP100, kg CO2-Eq) - see EXIOBASE calculation notebook in the SI.
A4: sector | B4: climate change: total (excl. biogenic CO2)
A5: Additives/Blending Components | B5: 0.00041375711
A6: Air transport services (62) | B6: 1.0591607e+10
A7: Aluminium and aluminium products | B7: 3111617.3
A8: Aluminium ores and concentrates | B8: 175819.45
A9: Animal products nec | B9: 2.7620994e+08
A10: Anthracite | B10: 77833234
A11: Ash for treatment, Re-processing of ash into clinker | B11: 0
A12: Aviation Gasoline | B12: 0.00099112837
A13: BKB/Peat Briquettes | B13: 979159.96
A14: Basic iron and steel and of ferro-alloys and first products thereof | B14: 12092.279
A15: Beverages | B15: 1.2629256e+09
A16: Biodiesels | B16: 5054971.4
... A204: products of Vegetable oils and fats | B204: 78681648

Sheet 1.2 Z_FR_imports_2022
A1: Sheet description: | B1: Imported data from the Prodcom Python notebook: Imported intermediate demand footprint in France per product (2022)
A2: Indicator | B2: GHG characterized with IPCC 2021 - climate change: total (excl. biogenic CO2) (GWP100, kg CO2-Eq) - see EXIOBASE calculation notebook in the SI.
A4: sector | B4: climate change: total (excl. biogenic CO2)
A5: Additives/Blending Components | B5: 53044298
A6: Air transport services (62) | B6: 5.1304293e+09
A7: Aluminium and aluminium products | B7: 4.4568715e+09
A8: Aluminium ores and concentrates | B8: 15951756
A9: Animal products nec | B9: 10491474
A10: Anthracite | B10: 68956809
A11: Ash for treatment, Re-processing of ash into clinker | B11: 0
A12: Aviation Gasoline | B12: 1038475.7
A13: BKB/Peat Briquettes | B13: 37450456
A14: Basic iron and steel and of ferro-alloys and first products thereof | B14: 1.3665794e+10
A15: Beverages | B15: 1.0818215e+09
A16: Biodiesels | B16: 1.3826346e+08
... A204: products of Vegetable oils and fats | B204: 1.2568509e+09

Sheet 2.1 Y_FR_production_2022
A1: Sheet description: | B1: Imported data from the Prodcom Python notebook: Production footprint in France per product, for final demand (France and exports) (2022)
A2: Indicator | B2: GHG characterized with IPCC 2021 - climate change: total (excl. biogenic CO2) (GWP100, kg CO2-Eq) - see EXIOBASE calculation notebook in the SI.
A4: sector | B4: climate change: total (excl. biogenic CO2)
A5: Additives/Blending Components | B5: 1182797.8
A6: Air transport services (62) | B6: 1.8203824e+10
A7: Aluminium and aluminium products | B7: 66268213
A8: Aluminium ores and concentrates | B8: 545958.52
A9: Animal products nec | B9: 4.2787602e+08
A10: Anthracite | B10: 20200.103
A11: Ash for treatment, Re-processing of ash into clinker | B11: 0
A12: Aviation Gasoline | B12: 6248.7311
A13: BKB/Peat Briquettes | B13: 0
A14: Basic iron and steel and of ferro-alloys and first products thereof | B14: 9.9997229e+08
A15: Beverages | B15: 7.6650222e+09
A16: Biodiesels | B16: 43078663
... A204: products of Vegetable oils and fats | B204: 1471590.5

Sheet 2.2 Z_FR_production_2022
A1: Sheet description: | B1: Imported data from the Prodcom Python notebook: Production footprint in France per product, for intermediate demand (France and exports) (2022)
A2: Indicator | B2: GHG characterized with IPCC 2021 - climate change: total (excl. biogenic CO2) (GWP100, kg CO2-Eq) - see EXIOBASE calculation notebook in the SI.
A4: sector | B4: climate change: total (excl. biogenic CO2)
A5: Additives/Blending Components | B5: 54315645
A6: Air transport services (62) | B6: 7.0452956e+09
A7: Aluminium and aluminium products | B7: 1.547454e+09
A8: Aluminium ores and concentrates | B8: 14874329
A9: Animal products nec | B9: 1.2548723e+08
A10: Anthracite | B10: 246625.12
A11: Ash for treatment, Re-processing of ash into clinker | B11: 0
A12: Aviation Gasoline | B12: 6795820.9
A13: BKB/Peat Briquettes | B13: 0
A14: Basic iron and steel and of ferro-alloys and first products thereof | B14: 2.6418046e+10
A15: Beverages | B15: 5.999738e+09
A16: Biodiesels | B16: 1.3366727e+08
... A204: products of Vegetable oils and fats | B204: 28161992

Sheet Summary_FR_2022
A1: Sheet description: | B1: Combines and summarizes the data of the four footprint sheets for France and year 2022
A2: Indicator | B2: GHG characterized with IPCC 2021 - climate change: total (excl. biogenic CO2) (GWP100, kg CO2-Eq) - see EXIOBASE calculation notebook in the SI.
D4: % Plastics, basic | E4: % Chemicals nec
A5: D_cba | B5: consumption-based accounts | C5: 592000000000 | D5: =VLOOKUP("Plastics, basic", $A$10:$B$209, 2, FALSE)/$C5 -> 0.036734844 | E5: =VLOOKUP("Chemicals nec", $A$10:$B$209, 2, FALSE)/$C5 -> 0.037470005
A6: D_pba | B6: production-based accounts | C6: 390000000000 | D6: =VLOOKUP("Plastics, basic", $A$10:$B$209, 2, FALSE)/$C6 -> 0.05576161 | E6: =VLOOKUP("Chemicals nec", $A$10:$B$209, 2, FALSE)/$C6 -> 0.056877546
A7: F_Y | B7: factor production final demand | C7: 116000000000 | D7: =VLOOKUP("Plastics, basic", $A$10:$B$209, 2, FALSE)/$C7 -> 0.18747438 | E7: =VLOOKUP("Chemicals nec", $A$10:$B$209, 2, FALSE)/$C7 -> 0.19122623
A9: Product | B9: Total (kg CO2 eq.) | C9: 1.1 Y_imports | D9: 1.2 Z_imports | E9: 2.1 Y_production | F9: 2.2 Z_production | G9: Imports | H9: Production
A10: Sea and coastal water transportation services | B10: =SUM(C10:F10) -> 9.9021067e+10 | C10: =VLOOKUP(A10, output_exiobase_v3.10.2_EXIO_IOT_2022_pxp_Y_imports_footprint_FR[], 2, FALSE) -> 2.1951983e+10 | D10: =VLOOKUP(A10, output_exiobase_v3.10.2_EXIO_IOT_2022_pxp_Z_imports_footprint_FR[], 2, FALSE) -> 1.201688e+10 | E10: =VLOOKUP(A10, output_exiobase_v3.10.2_EXIO_IOT_2022_pxp_Y_production_footprint_FR[], 2, FALSE) -> 6.1653931e+09 | F10: =VLOOKUP(A10, output_exiobase_v3.10.2_EXIO_IOT_2022_pxp_Z_production_footprint_FR[], 2, FALSE) -> 5.8886811e+10 | G10: =(C10+D10)/B10 -> 0.34304683 | H10: =(E10+F10)/B10 -> 0.65695317
A11: Construction work (45) | B11: =SUM(C11:F11) -> 6.9080863e+10 | C11: =VLOOKUP(A11, output_exiobase_v3.10.2_EXIO_IOT_2022_pxp_Y_imports_footprint_FR[], 2, FALSE) -> 2.8673788e+09 | D11: =VLOOKUP(A11, output_exiobase_v3.10.2_EXIO_IOT_2022_pxp_Z_imports_footprint_FR[], 2, FALSE) -> 9.1253857e+08 | E11: =VLOOKUP(A11, output_exiobase_v3.10.2_EXIO_IOT_2022_pxp_Y_production_footprint_FR[], 2, FALSE) -> 5.4367563e+10 | F11: =VLOOKUP(A11, output_exiobase_v3.10.2_EXIO_IOT_2022_pxp_Z_production_footprint_FR[], 2, FALSE) -> 1.0933382e+10 | G11: =(C11+D11)/B11 -> 0.054717286 | H11: =(E11+F11)/B11 -> 0.94528271
A12: Motor vehicles, trailers and semi-trailers (34) | B12: =SUM(C12:F12) -> 4.9602501e+10 | C12: =VLOOKUP(A12, output_exiobase_v3.10.2_EXIO_IOT_2022_pxp_Y_imports_footprint_FR[], 2, FALSE) -> 2.2831375e+10 | D12: =VLOOKUP(A12, output_exiobase_v3.10.2_EXIO_IOT_2022_pxp_Z_imports_footprint_FR[], 2, FALSE) -> 1.4273838e+09 | E12: =VLOOKUP(A12, output_exiobase_v3.10.2_EXIO_IOT_2022_pxp_Y_production_footprint_FR[], 2, FALSE) -> 2.1817328e+10 | F12: =VLOOKUP(A12, output_exiobase_v3.10.2_EXIO_IOT_2022_pxp_Z_production_footprint_FR[], 2, FALSE) -> 3.5264137e+09 | G12: =(C12+D12)/B12 -> 0.48906322 | H12: =(E12+F12)/B12 -> 0.51093678
A13: Food products nec | B13: =SUM(C13:F13) -> 4.7526483e+10 | C13: =VLOOKUP(A13, output_exiobase_v3.10.2_EXIO_IOT_2022_pxp_Y_imports_footprint_FR[], 2, FALSE) -> 1.1604446e+10 | D13: =VLOOKUP(A13, output_exiobase_v3.10.2_EXIO_IOT_2022_pxp_Z_imports_footprint_FR[], 2, FALSE) -> 5.081569e+09 | E13: =VLOOKUP(A13, output_exiobase_v3.10.2_EXIO_IOT_2022_pxp_Y_production_footprint_FR[], 2, FALSE) -> 1.9283648e+10 | F13: =VLOOKUP(A13, output_exiobase_v3.10.2_EXIO_IOT_2022_pxp_Z_production_footprint_FR[], 2, FALSE) -> 1.1556821e+10 | G13: =(C13+D13)/B13 -> 0.35108877 | H13: =(E13+F13)/B13 -> 0.64891123
A14: Dairy products | B14: =SUM(C14:F14) -> 4.5827253e+10 | C14: =VLOOKUP(A14, output_exiobase_v3.10.2_EXIO_IOT_2022_pxp_Y_imports_footprint_FR[], 2, FALSE) -> 2.3205938e+09 | D14: =VLOOKUP(A14, output_exiobase_v3.10.2_EXIO_IOT_2022_pxp_Z_imports_footprint_FR[], 2, FALSE) -> 3.6486678e+09 | E14: =VLOOKUP(A14, output_exiobase_v3.10.2_EXIO_IOT_2022_pxp_Y_production_footprint_FR[], 2, FALSE) -> 1.9771099e+10 | F14: =VLOOKUP(A14, output_exiobase_v3.10.2_EXIO_IOT_2022_pxp_Z_production_footprint_FR[], 2, FALSE) -> 2.0086893e+10 | G14: =(C14+D14)/B14 -> 0.13025572 | H14: =(E14+F14)/B14 -> 0.86974428
A15: Basic iron and steel and of ferro-alloys and first products thereof | B15: =SUM(C15:F15) -> 4.1083825e+10 | C15: =VLOOKUP(A15, output_exiobase_v3.10.2_EXIO_IOT_2022_pxp_Y_imports_footprint_FR[], 2, FALSE) -> 12092.279 | D15: =VLOOKUP(A15, output_exiobase_v3.10.2_EXIO_IOT_2022_pxp_Z_imports_footprint_FR[], 2, FALSE) -> 1.3665794e+10 | E15: =VLOOKUP(A15, output_exiobase_v3.10.2_EXIO_IOT_2022_pxp_Y_production_footprint_FR[], 2, FALSE) -> 9.9997229e+08 | F15: =VLOOKUP(A15, output_exiobase_v3.10.2_EXIO_IOT_2022_pxp_Z_production_footprint_FR[], 2, FALSE) -> 2.6418046e+10 | G15: =(C15+D15)/B15 -> 0.33263228 | H15: =(E15+F15)/B15 -> 0.66736772
A16: Air transport services (62) | B16: =SUM(C16:F16) -> 4.0971156e+10 | C16: =VLOOKUP(A16, output_exiobase_v3.10.2_EXIO_IOT_2022_pxp_Y_imports_footprint_FR[], 2, FALSE) -> 1.0591607e+10 | D16: =VLOOKUP(A16, output_exiobase_v3.10.2_EXIO_IOT_2022_pxp_Z_imports_footprint_FR[], 2, FALSE) -> 5.1304293e+09 | E16: =VLOOKUP(A16, output_exiobase_v3.10.2_EXIO_IOT_2022_pxp_Y_production_footprint_FR[], 2, FALSE) -> 1.8203824e+10 | F16: =VLOOKUP(A16, output_exiobase_v3.10.2_EXIO_IOT_2022_pxp_Z_production_footprint_FR[], 2, FALSE) -> 7.0452956e+09 | G16: =(C16+D16)/B16 -> 0.38373425 | H16: =(E16+F16)/B16 -> 0.61626575
A17: Cattle | B17: =SUM(C17:F17) -> 3.4712063e+10 | C17: =VLOOKUP(A17, output_exiobase_v3.10.2_EXIO_IOT_2022_pxp_Y_imports_footprint_FR[], 2, FALSE) -> 17016517 | D17: =VLOOKUP(A17, output_exiobase_v3.10.2_EXIO_IOT_2022_pxp_Z_imports_footprint_FR[], 2, FALSE) -> 2.5169976e+08 | E17: =VLOOKUP(A17, output_exiobase_v3.10.2_EXIO_IOT_2022_pxp_Y_production_footprint_FR[], 2, FALSE) -> 2.0296053e+09 | F17: =VLOOKUP(A17, output_exiobase_v3.10.2_EXIO_IOT_2022_pxp_Z_production_footprint_FR[], 2, FALSE) -> 3.2413741e+10 | G17: =(C17+D17)/B17 -> 0.0077412937 | H17: =(E17+F17)/B17 -> 0.99225871
A18: Rubber and plastic products (25) | B18: =SUM(C18:F18) -> 3.1464768e+10 | C18: =VLOOKUP(A18, output_exiobase_v3.10.2_EXIO_IOT_2022_pxp_Y_imports_footprint_FR[], 2, FALSE) -> 4.1052244e+09 | D18: =VLOOKUP(A18, output_exiobase_v3.10.2_EXIO_IOT_2022_pxp_Z_imports_footprint_FR[], 2, FALSE) -> 1.3838407e+10 | E18: =VLOOKUP(A18, output_exiobase_v3.10.2_EXIO_IOT_2022_pxp_Y_production_footprint_FR[], 2, FALSE) -> 2.187241e+09 | F18: =VLOOKUP(A18, output_exiobase_v3.10.2_EXIO_IOT_2022_pxp_Z_production_footprint_FR[], 2, FALSE) -> 1.1333895e+10 | G18: =(C18+D18)/B18 -> 0.57027695 | H18: =(E18+F18)/B18 -> 0.42972305
A19: Cement, lime and plaster | B19: =SUM(C19:F19) -> 3.0645115e+10 | C19: =VLOOKUP(A19, output_exiobase_v3.10.2_EXIO_IOT_2022_pxp_Y_imports_footprint_FR[], 2, FALSE) -> 33249008 | D19: =VLOOKUP(A19, output_exiobase_v3.10.2_EXIO_IOT_2022_pxp_Z_imports_footprint_FR[], 2, FALSE) -> 7.1586437e+09 | E19: =VLOOKUP(A19, output_exiobase_v3.10.2_EXIO_IOT_2022_pxp_Y_production_footprint_FR[], 2, FALSE) -> 74485318 | F19: =VLOOKUP(A19, output_exiobase_v3.10.2_EXIO_IOT_2022_pxp_Z_production_footprint_FR[], 2, FALSE) -> 2.3378737e+10 | G19: =(C19+D19)/B19 -> 0.23468317 | H19: =(E19+F19)/B19 -> 0.76531683
A20: Products of meat cattle | B20: =SUM(C20:F20) -> 2.9453475e+10 | C20: =VLOOKUP(A20, output_exiobase_v3.10.2_EXIO_IOT_2022_pxp_Y_imports_footprint_FR[], 2, FALSE) -> 1.3582334e+09 | D20: =VLOOKUP(A20, output_exiobase_v3.10.2_EXIO_IOT_2022_pxp_Z_imports_footprint_FR[], 2, FALSE) -> 9.8348648e+08 | E20: =VLOOKUP(A20, output_exiobase_v3.10.2_EXIO_IOT_2022_pxp_Y_production_footprint_FR[], 2, FALSE) -> 2.0340542e+10 | F20: =VLOOKUP(A20, output_exiobase_v3.10.2_EXIO_IOT_2022_pxp_Z_production_footprint_FR[], 2, FALSE) -> 6.7712132e+09 | G20: =(C20+D20)/B20 -> 0.079505724 | H20: =(E20+F20)/B20 -> 0.92049428
A21: Wholesale trade and commission trade services, except of motor vehicles and motorcycles (51) | B21: =SUM(C21:F21) -> 2.9102463e+10 | C21: =VLOOKUP(A21, output_exiobase_v3.10.2_EXIO_IOT_2022_pxp_Y_imports_footprint_FR[], 2, FALSE) -> 0.00086695095 | D21: =VLOOKUP(A21, output_exiobase_v3.10.2_EXIO_IOT_2022_pxp_Z_imports_footprint_FR[], 2, FALSE) -> 1.9971439e+09 | E21: =VLOOKUP(A21, output_exiobase_v3.10.2_EXIO_IOT_2022_pxp_Y_production_footprint_FR[], 2, FALSE) -> 3.0872286e+08 | F21: =VLOOKUP(A21, output_exiobase_v3.10.2_EXIO_IOT_2022_pxp_Z_production_footprint_FR[], 2, FALSE) -> 2.6796596e+10 | G21: =(C21+D21)/B21 -> 0.068624568 | H21: =(E21+F21)/B21 -> 0.93137543
... A209: Extra-territorial organizations and bodies | B209: =SUM(C209:F209) -> 0 | C209: =VLOOKUP(A209, output_exiobase_v3.10.2_EXIO_IOT_2022_pxp_Y_imports_footprint_FR[], 2, FALSE) -> 0 | D209: =VLOOKUP(A209, output_exiobase_v3.10.2_EXIO_IOT_2022_pxp_Z_imports_footprint_FR[], 2, FALSE) -> 0 | E209: =VLOOKUP(A209, output_exiobase_v3.10.2_EXIO_IOT_2022_pxp_Y_production_footprint_FR[], 2, FALSE) -> 0 | F209: =VLOOKUP(A209, output_exiobase_v3.10.2_EXIO_IOT_2022_pxp_Z_production_footprint_FR[], 2, FALSE) -> 0 | G209: =(C209+D209)/B209 -> #DIV/0! | H209: =(E209+F209)/B209 -> #DIV/0!

Sheet 1.1 Y_EU27_imports_2019
A1: Sheet description: | B1: Imported data from the Prodcom Python notebook: Imported final demand footprint in the European Union (EU27 2020) per product (2019)
A2: Indicator | B2: GHG characterized with IPCC 2021 - climate change: total (excl. biogenic CO2) (GWP100, kg CO2-Eq) - see EXIOBASE calculation notebook in the SI.
A4: sector | B4: climate change: total (excl. biogenic CO2)
A5: Additives/Blending Components | B5: 80188159
A6: Air transport services (62) | B6: 6.2242203e+10
A7: Aluminium and aluminium products | B7: 8.652105e+08
A8: Aluminium ores and concentrates | B8: 6432793.7
A9: Animal products nec | B9: 3.9562515e+08
A10: Anthracite | B10: 1.0802862e+08
A11: Ash for treatment, Re-processing of ash into clinker | B11: 0
A12: Aviation Gasoline | B12: 24389.428
A13: BKB/Peat Briquettes | B13: 13291608
A14: Basic iron and steel and of ferro-alloys and first products thereof | B14: 5.9658575e+09
A15: Beverages | B15: 3.2538692e+09
A16: Biodiesels | B16: 1.4630363e+08
... A204: products of Vegetable oils and fats | B204: 1.7699017e+09

Sheet 1.2 Z_EU27_imports_2019
A1: Sheet description: | B1: Imported data from the Prodcom Python notebook: Imported intermediate demand footprint in the European Union (EU27 2020) per product (2019)
A2: Indicator | B2: GHG characterized with IPCC 2021 - climate change: total (excl. biogenic CO2) (GWP100, kg CO2-Eq) - see EXIOBASE calculation notebook in the SI.
A4: sector | B4: climate change: total (excl. biogenic CO2)
A5: Additives/Blending Components | B5: 3.105162e+08
A6: Air transport services (62) | B6: 2.3255212e+10
A7: Aluminium and aluminium products | B7: 2.8690429e+10
A8: Aluminium ores and concentrates | B8: 9520573.5
A9: Animal products nec | B9: 5.7455357e+08
A10: Anthracite | B10: 2.6913697e+09
A11: Ash for treatment, Re-processing of ash into clinker | B11: 0
A12: Aviation Gasoline | B12: 4152249.1
A13: BKB/Peat Briquettes | B13: 18871711
A14: Basic iron and steel and of ferro-alloys and first products thereof | B14: 1.0059157e+11
A15: Beverages | B15: 2.8861975e+09
A16: Biodiesels | B16: 5.9262988e+08
... A204: products of Vegetable oils and fats | B204: 1.0485023e+10

Sheet 2.1 Y_EU27_production_2019
A1: Sheet description: | B1: Imported data from the Prodcom Python notebook: Production footprint in the European Union (EU27 2020) per product, for final demand (EU27 and exports) (2019)
A2: Indicator | B2: GHG characterized with IPCC 2021 - climate change: total (excl. biogenic CO2) (GWP100, kg CO2-Eq) - see EXIOBASE calculation notebook in the SI.
A4: sector | B4: climate change: total (excl. biogenic CO2)
A5: Additives/Blending Components | B5: 1.7697046e+08
A6: Air transport services (62) | B6: 8.7382105e+10
A7: Aluminium and aluminium products | B7: 3.3054694e+09
A8: Aluminium ores and concentrates | B8: 1384348.8
A9: Animal products nec | B9: 3.0724858e+09
A10: Anthracite | B10: 12678936
A11: Ash for treatment, Re-processing of ash into clinker | B11: 0
A12: Aviation Gasoline | B12: 72881.588
A13: BKB/Peat Briquettes | B13: 5.7717455e+08
A14: Basic iron and steel and of ferro-alloys and first products thereof | B14: 6.5808864e+09
A15: Beverages | B15: 3.0879893e+10
A16: Biodiesels | B16: 4.1650465e+09
... A204: products of Vegetable oils and fats | B204: 2.6480454e+09

Sheet 2.2 Z_EU27_production_2019
A1: Sheet description: | B1: Imported data from the Prodcom Python notebook: Production footprint in the European Union (EU27 2020) per product, for intermediate demand (EU27 and exports) (2019)
A2: Indicator | B2: GHG characterized with IPCC 2021 - climate change: total (excl. biogenic CO2) (GWP100, kg CO2-Eq) - see EXIOBASE calculation notebook in the SI.
A4: sector | B4: climate change: total (excl. biogenic CO2)
A5: Additives/Blending Components | B5: 2.6481104e+09
A6: Air transport services (62) | B6: 6.1547151e+10
A7: Aluminium and aluminium products | B7: 5.3250376e+10
A8: Aluminium ores and concentrates | B8: 1.5576483e+08
A9: Animal products nec | B9: 1.3509347e+09
A10: Anthracite | B10: 2.1559924e+08
A11: Ash for treatment, Re-processing of ash into clinker | B11: 0
A12: Aviation Gasoline | B12: 5.0397037e+08
A13: BKB/Peat Briquettes | B13: 1.6334302e+09
A14: Basic iron and steel and of ferro-alloys and first products thereof | B14: 2.0735608e+11
A15: Beverages | B15: 3.4201637e+10
A16: Biodiesels | B16: 9.6501673e+09
... A204: products of Vegetable oils and fats | B204: 1.004314e+10

Sheet Summary_EU27_2019
A1: Sheet description: | B1: Combines and summarizes the data of the four footprint sheets for the European Union (EU27 2020) and year 2019
A2: Indicator | B2: GHG characterized with IPCC 2021 - climate change: total (excl. biogenic CO2) (GWP100, kg CO2-Eq) - see EXIOBASE calculation notebook in the SI.
D4: % Plastics, basic | E4: % Chemicals nec
A5: D_cba | B5: consumption-based accounts | C5: 4450000000000 | D5: =VLOOKUP("Plastics, basic", $A$10:$B$209, 2, FALSE)/$C5 -> 0.035551117 | E5: =VLOOKUP("Chemicals nec", $A$10:$B$209, 2, FALSE)/$C5 -> 0.050434259
A6: D_pba | B6: production-based accounts | C6: 3560000000000 | D6: =VLOOKUP("Plastics, basic", $A$10:$B$209, 2, FALSE)/$C6 -> 0.044438896 | E6: =VLOOKUP("Chemicals nec", $A$10:$B$209, 2, FALSE)/$C6 -> 0.063042824
A7: F_Y | B7: factor production final demand | C7: 660000000000 | D7: =VLOOKUP("Plastics, basic", $A$10:$B$209, 2, FALSE)/$C7 -> 0.23970071 | E7: =VLOOKUP("Chemicals nec", $A$10:$B$209, 2, FALSE)/$C7 -> 0.34004917
A9: Product | B9: Total (kg CO2 eq.) | C9: 1.1 Y_imports | D9: 1.2 Z_imports | E9: 2.1 Y_production | F9: 2.2 Z_production | G9: Imports | H9: Production
A10: Construction work (45) | B10: =SUM(C10:F10) -> 6.5253849e+11 | C10: =VLOOKUP(A10, output_exiobase_v3.10.2_EXIO_IOT_2019_pxp_Y_imports_footprint_EU27[], 2, FALSE) -> 1.0351269e+10 | D10: =VLOOKUP(A10, output_exiobase_v3.10.2_EXIO_IOT_2019_pxp_Z_imports_footprint_EU27[], 2, FALSE) -> 8.0781799e+09 | E10: =VLOOKUP(A10, output_exiobase_v3.10.2_EXIO_IOT_2019_pxp_Y_production_footprint_EU27[], 2, FALSE) -> 4.1948265e+11 | F10: =VLOOKUP(A10, output_exiobase_v3.10.2_EXIO_IOT_2019_pxp_Z_production_footprint_EU27[], 2, FALSE) -> 2.1462639e+11 | G10: =(C10+D10)/B10 -> 0.028242701 | H10: =(E10+F10)/B10 -> 0.9717573
A11: Sea and coastal water transportation services | B11: =SUM(C11:F11) -> 4.5624858e+11 | C11: =VLOOKUP(A11, output_exiobase_v3.10.2_EXIO_IOT_2019_pxp_Y_imports_footprint_EU27[], 2, FALSE) -> 4.9157294e+10 | D11: =VLOOKUP(A11, output_exiobase_v3.10.2_EXIO_IOT_2019_pxp_Z_imports_footprint_EU27[], 2, FALSE) -> 1.0020841e+11 | E11: =VLOOKUP(A11, output_exiobase_v3.10.2_EXIO_IOT_2019_pxp_Y_production_footprint_EU27[], 2, FALSE) -> 1.096639e+11 | F11: =VLOOKUP(A11, output_exiobase_v3.10.2_EXIO_IOT_2019_pxp_Z_production_footprint_EU27[], 2, FALSE) -> 1.9721897e+11 | G11: =(C11+D11)/B11 -> 0.32737791 | H11: =(E11+F11)/B11 -> 0.67262209
A12: Electricity by coal | B12: =SUM(C12:F12) -> 4.2159993e+11 | C12: =VLOOKUP(A12, output_exiobase_v3.10.2_EXIO_IOT_2019_pxp_Y_imports_footprint_EU27[], 2, FALSE) -> 6.3163219e+09 | D12: =VLOOKUP(A12, output_exiobase_v3.10.2_EXIO_IOT_2019_pxp_Z_imports_footprint_EU27[], 2, FALSE) -> 1.6609265e+10 | E12: =VLOOKUP(A12, output_exiobase_v3.10.2_EXIO_IOT_2019_pxp_Y_production_footprint_EU27[], 2, FALSE) -> 1.1122475e+11 | F12: =VLOOKUP(A12, output_exiobase_v3.10.2_EXIO_IOT_2019_pxp_Z_production_footprint_EU27[], 2, FALSE) -> 2.8744959e+11 | G12: =(C12+D12)/B12 -> 0.054377588 | H12: =(E12+F12)/B12 -> 0.94562241
A13: Basic iron and steel and of ferro-alloys and first products thereof | B13: =SUM(C13:F13) -> 3.204944e+11 | C13: =VLOOKUP(A13, output_exiobase_v3.10.2_EXIO_IOT_2019_pxp_Y_imports_footprint_EU27[], 2, FALSE) -> 5.9658575e+09 | D13: =VLOOKUP(A13, output_exiobase_v3.10.2_EXIO_IOT_2019_pxp_Z_imports_footprint_EU27[], 2, FALSE) -> 1.0059157e+11 | E13: =VLOOKUP(A13, output_exiobase_v3.10.2_EXIO_IOT_2019_pxp_Y_production_footprint_EU27[], 2, FALSE) -> 6.5808864e+09 | F13: =VLOOKUP(A13, output_exiobase_v3.10.2_EXIO_IOT_2019_pxp_Z_production_footprint_EU27[], 2, FALSE) -> 2.0735608e+11 | G13: =(C13+D13)/B13 -> 0.33247829 | H13: =(E13+F13)/B13 -> 0.66752171
A14: Other business services (74) | B14: =SUM(C14:F14) -> 3.2041903e+11 | C14: =VLOOKUP(A14, output_exiobase_v3.10.2_EXIO_IOT_2019_pxp_Y_imports_footprint_EU27[], 2, FALSE) -> 4.7504984e+09 | D14: =VLOOKUP(A14, output_exiobase_v3.10.2_EXIO_IOT_2019_pxp_Z_imports_footprint_EU27[], 2, FALSE) -> 1.9382261e+10 | E14: =VLOOKUP(A14, output_exiobase_v3.10.2_EXIO_IOT_2019_pxp_Y_production_footprint_EU27[], 2, FALSE) -> 3.5626183e+10 | F14: =VLOOKUP(A14, output_exiobase_v3.10.2_EXIO_IOT_2019_pxp_Z_production_footprint_EU27[], 2, FALSE) -> 2.6066009e+11 | G14: =(C14+D14)/B14 -> 0.075316247 | H14: =(E14+F14)/B14 -> 0.92468375
A15: Motor vehicles, trailers and semi-trailers (34) | B15: =SUM(C15:F15) -> 3.0119666e+11 | C15: =VLOOKUP(A15, output_exiobase_v3.10.2_EXIO_IOT_2019_pxp_Y_imports_footprint_EU27[], 2, FALSE) -> 4.3134222e+10 | D15: =VLOOKUP(A15, output_exiobase_v3.10.2_EXIO_IOT_2019_pxp_Z_imports_footprint_EU27[], 2, FALSE) -> 2.6223163e+10 | E15: =VLOOKUP(A15, output_exiobase_v3.10.2_EXIO_IOT_2019_pxp_Y_production_footprint_EU27[], 2, FALSE) -> 1.3658152e+11 | F15: =VLOOKUP(A15, output_exiobase_v3.10.2_EXIO_IOT_2019_pxp_Z_production_footprint_EU27[], 2, FALSE) -> 9.5257747e+10 | G15: =(C15+D15)/B15 -> 0.23027276 | H15: =(E15+F15)/B15 -> 0.76972724
A16: Food products nec | B16: =SUM(C16:F16) -> 2.8701751e+11 | C16: =VLOOKUP(A16, output_exiobase_v3.10.2_EXIO_IOT_2019_pxp_Y_imports_footprint_EU27[], 2, FALSE) -> 2.5530917e+10 | D16: =VLOOKUP(A16, output_exiobase_v3.10.2_EXIO_IOT_2019_pxp_Z_imports_footprint_EU27[], 2, FALSE) -> 5.9778102e+09 | E16: =VLOOKUP(A16, output_exiobase_v3.10.2_EXIO_IOT_2019_pxp_Y_production_footprint_EU27[], 2, FALSE) -> 1.7157459e+11 | F16: =VLOOKUP(A16, output_exiobase_v3.10.2_EXIO_IOT_2019_pxp_Z_production_footprint_EU27[], 2, FALSE) -> 8.393419e+10 | G16: =(C16+D16)/B16 -> 0.10977981 | H16: =(E16+F16)/B16 -> 0.89022019
A17: Wholesale trade and commission trade services, except of motor vehicles and motorcycles (51) | B17: =SUM(C17:F17) -> 2.8054437e+11 | C17: =VLOOKUP(A17, output_exiobase_v3.10.2_EXIO_IOT_2019_pxp_Y_imports_footprint_EU27[], 2, FALSE) -> 47380415 | D17: =VLOOKUP(A17, output_exiobase_v3.10.2_EXIO_IOT_2019_pxp_Z_imports_footprint_EU27[], 2, FALSE) -> 7.7843678e+09 | E17: =VLOOKUP(A17, output_exiobase_v3.10.2_EXIO_IOT_2019_pxp_Y_production_footprint_EU27[], 2, FALSE) -> 1.1591886e+11 | F17: =VLOOKUP(A17, output_exiobase_v3.10.2_EXIO_IOT_2019_pxp_Z_production_footprint_EU27[], 2, FALSE) -> 1.5679376e+11 | G17: =(C17+D17)/B17 -> 0.027916255 | H17: =(E17+F17)/B17 -> 0.97208374
A18: Fabricated metal products, except machinery and equipment (28) | B18: =SUM(C18:F18) -> 2.550504e+11 | C18: =VLOOKUP(A18, output_exiobase_v3.10.2_EXIO_IOT_2019_pxp_Y_imports_footprint_EU27[], 2, FALSE) -> 2.1911487e+10 | D18: =VLOOKUP(A18, output_exiobase_v3.10.2_EXIO_IOT_2019_pxp_Z_imports_footprint_EU27[], 2, FALSE) -> 4.6871051e+10 | E18: =VLOOKUP(A18, output_exiobase_v3.10.2_EXIO_IOT_2019_pxp_Y_production_footprint_EU27[], 2, FALSE) -> 3.7170123e+10 | F18: =VLOOKUP(A18, output_exiobase_v3.10.2_EXIO_IOT_2019_pxp_Z_production_footprint_EU27[], 2, FALSE) -> 1.4909774e+11 | G18: =(C18+D18)/B18 -> 0.26968213 | H18: =(E18+F18)/B18 -> 0.73031787
A19: Crude petroleum and services related to crude oil extraction, excluding surveying | B19: =SUM(C19:F19) -> 2.4556196e+11 | C19: =VLOOKUP(A19, output_exiobase_v3.10.2_EXIO_IOT_2019_pxp_Y_imports_footprint_EU27[], 2, FALSE) -> 8.0377874e+08 | D19: =VLOOKUP(A19, output_exiobase_v3.10.2_EXIO_IOT_2019_pxp_Z_imports_footprint_EU27[], 2, FALSE) -> 2.1842247e+11 | E19: =VLOOKUP(A19, output_exiobase_v3.10.2_EXIO_IOT_2019_pxp_Y_production_footprint_EU27[], 2, FALSE) -> 3.6817096e+09 | F19: =VLOOKUP(A19, output_exiobase_v3.10.2_EXIO_IOT_2019_pxp_Z_production_footprint_EU27[], 2, FALSE) -> 2.2653997e+10 | G19: =(C19+D19)/B19 -> 0.89275331 | H19: =(E19+F19)/B19 -> 0.10724669
A20: Air transport services (62) | B20: =SUM(C20:F20) -> 2.3442667e+11 | C20: =VLOOKUP(A20, output_exiobase_v3.10.2_EXIO_IOT_2019_pxp_Y_imports_footprint_EU27[], 2, FALSE) -> 6.2242203e+10 | D20: =VLOOKUP(A20, output_exiobase_v3.10.2_EXIO_IOT_2019_pxp_Z_imports_footprint_EU27[], 2, FALSE) -> 2.3255212e+10 | E20: =VLOOKUP(A20, output_exiobase_v3.10.2_EXIO_IOT_2019_pxp_Y_production_footprint_EU27[], 2, FALSE) -> 8.7382105e+10 | F20: =VLOOKUP(A20, output_exiobase_v3.10.2_EXIO_IOT_2019_pxp_Z_production_footprint_EU27[], 2, FALSE) -> 6.1547151e+10 | G20: =(C20+D20)/B20 -> 0.36470857 | H20: =(E20+F20)/B20 -> 0.63529143
A21: Chemicals nec | B21: =SUM(C21:F21) -> 2.2443245e+11 | C21: =VLOOKUP(A21, output_exiobase_v3.10.2_EXIO_IOT_2019_pxp_Y_imports_footprint_EU27[], 2, FALSE) -> 3.8138546e+10 | D21: =VLOOKUP(A21, output_exiobase_v3.10.2_EXIO_IOT_2019_pxp_Z_imports_footprint_EU27[], 2, FALSE) -> 7.7987966e+10 | E21: =VLOOKUP(A21, output_exiobase_v3.10.2_EXIO_IOT_2019_pxp_Y_production_footprint_EU27[], 2, FALSE) -> 3.5832447e+10 | F21: =VLOOKUP(A21, output_exiobase_v3.10.2_EXIO_IOT_2019_pxp_Z_production_footprint_EU27[], 2, FALSE) -> 7.2473493e+10 | G21: =(C21+D21)/B21 -> 0.517423 | H21: =(E21+F21)/B21 -> 0.482577
... A114: Meat products nec | B114: =SUM(C114:F114) -> 1.085589e+10 | C114: =VLOOKUP(A114, output_exiobase_v3.10.2_EXIO_IOT_2019_pxp_Y_imports_footprint_EU27[], 2, FALSE) -> 3.8415297e+09 | D114: =VLOOKUP(A114, output_exiobase_v3.10.2_EXIO_IOT_2019_pxp_Z_imports_footprint_EU27[], 2, FALSE) -> 4.1533478e+08 | E114: =VLOOKUP(A114, output_exiobase_v3.10.2_EXIO_IOT_2019_pxp_Y_production_footprint_EU27[], 2, FALSE) -> 3.8924399e+09 | F114: =VLOOKUP(A114, output_exiobase_v3.10.2_EXIO_IOT_2019_pxp_Z_production_footprint_EU27[], 2, FALSE) -> 2.7065854e+09 | G114: =(C114+D114)/B114 -> 0.39212488 | H114: =(E114+F114)/B114 -> 0.60787512
A115: Secondary raw materials | B115: =SUM(C115:F115) -> 1.0826188e+10 | C115: =VLOOKUP(A115, output_exiobase_v3.10.2_EXIO_IOT_2019_pxp_Y_imports_footprint_EU27[], 2, FALSE) -> 0 | D115: =VLOOKUP(A115, output_exiobase_v3.10.2_EXIO_IOT_2019_pxp_Z_imports_footprint_EU27[], 2, FALSE) -> 0 | E115: =VLOOKUP(A115, output_exiobase_v3.10.2_EXIO_IOT_2019_pxp_Y_production_footprint_EU27[], 2, FALSE) -> 3.0474787e+08 | F115: =VLOOKUP(A115, output_exiobase_v3.10.2_EXIO_IOT_2019_pxp_Z_production_footprint_EU27[], 2, FALSE) -> 1.0521441e+10
A116: Electricity by biomass and waste | B116: =SUM(C116:F116) -> 1.0192371e+10 | C116: =VLOOKUP(A116, output_exiobase_v3.10.2_EXIO_IOT_2019_pxp_Y_imports_footprint_EU27[], 2, FALSE) -> 23283424 | D116: =VLOOKUP(A116, output_exiobase_v3.10.2_EXIO_IOT_2019_pxp_Z_imports_footprint_EU27[], 2, FALSE) -> 33142433 | E116: =VLOOKUP(A116, output_exiobase_v3.10.2_EXIO_IOT_2019_pxp_Y_production_footprint_EU27[], 2, FALSE) -> 1.8137644e+09 | F116: =VLOOKUP(A116, output_exiobase_v3.10.2_EXIO_IOT_2019_pxp_Z_production_footprint_EU27[], 2, FALSE) -> 8.3221808e+09 | G116: =(C116+D116)/B116 -> 0.0055360874 | H116: =(E116+F116)/B116 -> 0.99446391
A117: Retail trade services of motor fuel | B117: =SUM(C117:F117) -> 9.7943049e+09 | C117: =VLOOKUP(A117, output_exiobase_v3.10.2_EXIO_IOT_2019_pxp_Y_imports_footprint_EU27[], 2, FALSE) -> 21201090 | D117: =VLOOKUP(A117, output_exiobase_v3.10.2_EXIO_IOT_2019_pxp_Z_imports_footprint_EU27[], 2, FALSE) -> 3.7904014e+08 | E117: =VLOOKUP(A117, output_exiobase_v3.10.2_EXIO_IOT_2019_pxp_Y_production_footprint_EU27[], 2, FALSE) -> 1.908153e+09 | F117: =VLOOKUP(A117, output_exiobase_v3.10.2_EXIO_IOT_2019_pxp_Z_production_footprint_EU27[], 2, FALSE) -> 7.4859107e+09 | G117: =(C117+D117)/B117 -> 0.04086469 | H117: =(E117+F117)/B117 -> 0.95913531
A118: Inland water transportation services | B118: =SUM(C118:F118) -> 9.4912069e+09 | C118: =VLOOKUP(A118, output_exiobase_v3.10.2_EXIO_IOT_2019_pxp_Y_imports_footprint_EU27[], 2, FALSE) -> 1.4047961e+08 | D118: =VLOOKUP(A118, output_exiobase_v3.10.2_EXIO_IOT_2019_pxp_Z_imports_footprint_EU27[], 2, FALSE) -> 6.8456088e+08 | E118: =VLOOKUP(A118, output_exiobase_v3.10.2_EXIO_IOT_2019_pxp_Y_production_footprint_EU27[], 2, FALSE) -> 3.6504201e+09 | F118: =VLOOKUP(A118, output_exiobase_v3.10.2_EXIO_IOT_2019_pxp_Z_production_footprint_EU27[], 2, FALSE) -> 5.0157462e+09 | G118: =(C118+D118)/B118 -> 0.086926826 | H118: =(E118+F118)/B118 -> 0.91307317
A119: Natural Gas Liquids | B119: =SUM(C119:F119) -> 9.2670385e+09 | C119: =VLOOKUP(A119, output_exiobase_v3.10.2_EXIO_IOT_2019_pxp_Y_imports_footprint_EU27[], 2, FALSE) -> 4.6880199e+08 | D119: =VLOOKUP(A119, output_exiobase_v3.10.2_EXIO_IOT_2019_pxp_Z_imports_footprint_EU27[], 2, FALSE) -> 8.4611124e+09 | E119: =VLOOKUP(A119, output_exiobase_v3.10.2_EXIO_IOT_2019_pxp_Y_production_footprint_EU27[], 2, FALSE) -> 10446290 | F119: =VLOOKUP(A119, output_exiobase_v3.10.2_EXIO_IOT_2019_pxp_Z_production_footprint_EU27[], 2, FALSE) -> 3.2667783e+08 | G119: =(C119+D119)/B119 -> 0.96362116 | H119: =(E119+F119)/B119 -> 0.036378841
A120: Food waste for treatment: composting and land application | B120: =SUM(C120:F120) -> 9.0540084e+09 | C120: =VLOOKUP(A120, output_exiobase_v3.10.2_EXIO_IOT_2019_pxp_Y_imports_footprint_EU27[], 2, FALSE) -> 2108683.7 | D120: =VLOOKUP(A120, output_exiobase_v3.10.2_EXIO_IOT_2019_pxp_Z_imports_footprint_EU27[], 2, FALSE) -> 1.2565851e+08 | E120: =VLOOKUP(A120, output_exiobase_v3.10.2_EXIO_IOT_2019_pxp_Y_production_footprint_EU27[], 2, FALSE) -> 2.4031325e+09 | F120: =VLOOKUP(A120, output_exiobase_v3.10.2_EXIO_IOT_2019_pxp_Z_production_footprint_EU27[], 2, FALSE) -> 6.5231087e+09 | G120: =(C120+D120)/B120 -> 0.014111672 | H120: =(E120+F120)/B120 -> 0.98588833
A121: Sugar cane, sugar beet | B121: =SUM(C121:F121) -> 8.8702535e+09 | C121: =VLOOKUP(A121, output_exiobase_v3.10.2_EXIO_IOT_2019_pxp_Y_imports_footprint_EU27[], 2, FALSE) -> 76255.565 | D121: =VLOOKUP(A121, output_exiobase_v3.10.2_EXIO_IOT_2019_pxp_Z_imports_footprint_EU27[], 2, FALSE) -> 1067906.4 | E121: =VLOOKUP(A121, output_exiobase_v3.10.2_EXIO_IOT_2019_pxp_Y_production_footprint_EU27[], 2, FALSE) -> 1.7158277e+09 | F121: =VLOOKUP(A121, output_exiobase_v3.10.2_EXIO_IOT_2019_pxp_Z_production_footprint_EU27[], 2, FALSE) -> 7.1532817e+09 | G121: =(C121+D121)/B121 -> 0.00012898865 | H121: =(E121+F121)/B121 -> 0.99987101
A122: Intert/metal waste for treatment: incineration | B122: =SUM(C122:F122) -> 8.8632915e+09 | C122: =VLOOKUP(A122, output_exiobase_v3.10.2_EXIO_IOT_2019_pxp_Y_imports_footprint_EU27[], 2, FALSE) -> 545439.26 | D122: =VLOOKUP(A122, output_exiobase_v3.10.2_EXIO_IOT_2019_pxp_Z_imports_footprint_EU27[], 2, FALSE) -> 1.1380706e+08 | E122: =VLOOKUP(A122, output_exiobase_v3.10.2_EXIO_IOT_2019_pxp_Y_production_footprint_EU27[], 2, FALSE) -> 1.8115244e+09 | F122: =VLOOKUP(A122, output_exiobase_v3.10.2_EXIO_IOT_2019_pxp_Z_production_footprint_EU27[], 2, FALSE) -> 6.9374146e+09 | G122: =(C122+D122)/B122 -> 0.012901809 | H122: =(E122+F122)/B122 -> 0.98709819
A123: N-fertiliser | B123: =SUM(C123:F123) -> 8.020689e+09 | C123: =VLOOKUP(A123, output_exiobase_v3.10.2_EXIO_IOT_2019_pxp_Y_imports_footprint_EU27[], 2, FALSE) -> 1.3320222e+08 | D123: =VLOOKUP(A123, output_exiobase_v3.10.2_EXIO_IOT_2019_pxp_Z_imports_footprint_EU27[], 2, FALSE) -> 5.0418365e+08 | E123: =VLOOKUP(A123, output_exiobase_v3.10.2_EXIO_IOT_2019_pxp_Y_production_footprint_EU27[], 2, FALSE) -> 3.6901009e+09 | F123: =VLOOKUP(A123, output_exiobase_v3.10.2_EXIO_IOT_2019_pxp_Z_production_footprint_EU27[], 2, FALSE) -> 3.6932023e+09 | G123: =(C123+D123)/B123 -> 0.079467721 | H123: =(E123+F123)/B123 -> 0.92053228
A124: Stone | B124: =SUM(C124:F124) -> 7.5506863e+09 | C124: =VLOOKUP(A124, output_exiobase_v3.10.2_EXIO_IOT_2019_pxp_Y_imports_footprint_EU27[], 2, FALSE) -> 15897521 | D124: =VLOOKUP(A124, output_exiobase_v3.10.2_EXIO_IOT_2019_pxp_Z_imports_footprint_EU27[], 2, FALSE) -> 48490149 | E124: =VLOOKUP(A124, output_exiobase_v3.10.2_EXIO_IOT_2019_pxp_Y_production_footprint_EU27[], 2, FALSE) -> 6.2477761e+08 | F124: =VLOOKUP(A124, output_exiobase_v3.10.2_EXIO_IOT_2019_pxp_Z_production_footprint_EU27[], 2, FALSE) -> 6.8615211e+09 | G124: =(C124+D124)/B124 -> 0.008527393 | H124: =(E124+F124)/B124 -> 0.99147261
A125: Tobacco products (16) | B125: =SUM(C125:F125) -> 7.2614385e+09 | C125: =VLOOKUP(A125, output_exiobase_v3.10.2_EXIO_IOT_2019_pxp_Y_imports_footprint_EU27[], 2, FALSE) -> 3.5909317e+08 | D125: =VLOOKUP(A125, output_exiobase_v3.10.2_EXIO_IOT_2019_pxp_Z_imports_footprint_EU27[], 2, FALSE) -> 1.565503e+08 | E125: =VLOOKUP(A125, output_exiobase_v3.10.2_EXIO_IOT_2019_pxp_Y_production_footprint_EU27[], 2, FALSE) -> 5.5110566e+09 | F125: =VLOOKUP(A125, output_exiobase_v3.10.2_EXIO_IOT_2019_pxp_Z_production_footprint_EU27[], 2, FALSE) -> 1.2347385e+09 | G125: =(C125+D125)/B125 -> 0.071011201 | H125: =(E125+F125)/B125 -> 0.9289888
A126: Inert/metal/hazardous waste for treatment: landfill | B126: =SUM(C126:F126) -> 7.0626427e+09 | C126: =VLOOKUP(A126, output_exiobase_v3.10.2_EXIO_IOT_2019_pxp_Y_imports_footprint_EU27[], 2, FALSE) -> 748694.26 | D126: =VLOOKUP(A126, output_exiobase_v3.10.2_EXIO_IOT_2019_pxp_Z_imports_footprint_EU27[], 2, FALSE) -> 33739576 | E126: =VLOOKUP(A126, output_exiobase_v3.10.2_EXIO_IOT_2019_pxp_Y_production_footprint_EU27[], 2, FALSE) -> 2.1762978e+09 | F126: =VLOOKUP(A126, output_exiobase_v3.10.2_EXIO_IOT_2019_pxp_Z_production_footprint_EU27[], 2, FALSE) -> 4.8518566e+09 | G126: =(C126+D126)/B126 -> 0.0048831962 | H126: =(E126+F126)/B126 -> 0.9951168
A127: Kerosene | B127: =SUM(C127:F127) -> 6.4921619e+09 | C127: =VLOOKUP(A127, output_exiobase_v3.10.2_EXIO_IOT_2019_pxp_Y_imports_footprint_EU27[], 2, FALSE) -> 1.3539002e+08 | D127: =VLOOKUP(A127, output_exiobase_v3.10.2_EXIO_IOT_2019_pxp_Z_imports_footprint_EU27[], 2, FALSE) -> 1.2475762e+08 | E127: =VLOOKUP(A127, output_exiobase_v3.10.2_EXIO_IOT_2019_pxp_Y_production_footprint_EU27[], 2, FALSE) -> 1.0114368e+08 | F127: =VLOOKUP(A127, output_exiobase_v3.10.2_EXIO_IOT_2019_pxp_Z_production_footprint_EU27[], 2, FALSE) -> 6.1308705e+09 | G127: =(C127+D127)/B127 -> 0.040071035 | H127: =(E127+F127)/B127 -> 0.95992897
... A154: Electricity by solar photovoltaic | B154: =SUM(C154:F154) -> 1.5570837e+09 | C154: =VLOOKUP(A154, output_exiobase_v3.10.2_EXIO_IOT_2019_pxp_Y_imports_footprint_EU27[], 2, FALSE) -> 15669838 | D154: =VLOOKUP(A154, output_exiobase_v3.10.2_EXIO_IOT_2019_pxp_Z_imports_footprint_EU27[], 2, FALSE) -> 35747040 | E154: =VLOOKUP(A154, output_exiobase_v3.10.2_EXIO_IOT_2019_pxp_Y_production_footprint_EU27[], 2, FALSE) -> 2.48931e+08 | F154: =VLOOKUP(A154, output_exiobase_v3.10.2_EXIO_IOT_2019_pxp_Z_production_footprint_EU27[], 2, FALSE) -> 1.2567358e+09 | G154: =(C154+D154)/B154 -> 0.033021268 | H154: =(E154+F154)/B154 -> 0.96697873
A155: Nickel ores and concentrates | B155: =SUM(C155:F155) -> 1.5082529e+09 | C155: =VLOOKUP(A155, output_exiobase_v3.10.2_EXIO_IOT_2019_pxp_Y_imports_footprint_EU27[], 2, FALSE) -> 2115564.9 | D155: =VLOOKUP(A155, output_exiobase_v3.10.2_EXIO_IOT_2019_pxp_Z_imports_footprint_EU27[], 2, FALSE) -> 713600.35 | E155: =VLOOKUP(A155, output_exiobase_v3.10.2_EXIO_IOT_2019_pxp_Y_production_footprint_EU27[], 2, FALSE) -> 7.4880635e+08 | F155: =VLOOKUP(A155, output_exiobase_v3.10.2_EXIO_IOT_2019_pxp_Z_production_footprint_EU27[], 2, FALSE) -> 7.5661736e+08
A156: White Spirit & SBP | B156: =SUM(C156:F156) -> 1.4810146e+09 | C156: =VLOOKUP(A156, output_exiobase_v3.10.2_EXIO_IOT_2019_pxp_Y_imports_footprint_EU27[], 2, FALSE) -> 6995981.5 | D156: =VLOOKUP(A156, output_exiobase_v3.10.2_EXIO_IOT_2019_pxp_Z_imports_footprint_EU27[], 2, FALSE) -> 85798324 | E156: =VLOOKUP(A156, output_exiobase_v3.10.2_EXIO_IOT_2019_pxp_Y_production_footprint_EU27[], 2, FALSE) -> 1.6500646e+08 | F156: =VLOOKUP(A156, output_exiobase_v3.10.2_EXIO_IOT_2019_pxp_Z_production_footprint_EU27[], 2, FALSE) -> 1.2232139e+09 | G156: =(C156+D156)/B156 -> 0.062655901 | H156: =(E156+F156)/B156 -> 0.9373441
A157: Blast Furnace Gas | B157: =SUM(C157:F157) -> 1.4409073e+09 | C157: =VLOOKUP(A157, output_exiobase_v3.10.2_EXIO_IOT_2019_pxp_Y_imports_footprint_EU27[], 2, FALSE) -> 120958.47 | D157: =VLOOKUP(A157, output_exiobase_v3.10.2_EXIO_IOT_2019_pxp_Z_imports_footprint_EU27[], 2, FALSE) -> 5025483.2 | E157: =VLOOKUP(A157, output_exiobase_v3.10.2_EXIO_IOT_2019_pxp_Y_production_footprint_EU27[], 2, FALSE) -> 43037350 | F157: =VLOOKUP(A157, output_exiobase_v3.10.2_EXIO_IOT_2019_pxp_Z_production_footprint_EU27[], 2, FALSE) -> 1.3927236e+09 | G157: =(C157+D157)/B157 -> 0.0035716673 | H157: =(E157+F157)/B157 -> 0.99642833
A158: Coal Tar | B158: =SUM(C158:F158) -> 1.4375542e+09 | C158: =VLOOKUP(A158, output_exiobase_v3.10.2_EXIO_IOT_2019_pxp_Y_imports_footprint_EU27[], 2, FALSE) -> 96840505 | D158: =VLOOKUP(A158, output_exiobase_v3.10.2_EXIO_IOT_2019_pxp_Z_imports_footprint_EU27[], 2, FALSE) -> 2.207717e+08 | E158: =VLOOKUP(A158, output_exiobase_v3.10.2_EXIO_IOT_2019_pxp_Y_production_footprint_EU27[], 2, FALSE) -> 1.5694688e+08 | F158: =VLOOKUP(A158, output_exiobase_v3.10.2_EXIO_IOT_2019_pxp_Z_production_footprint_EU27[], 2, FALSE) -> 9.6299517e+08 | G158: =(C158+D158)/B158 -> 0.22093928 | H158: =(E158+F158)/B158 -> 0.77906072
A159: Lead, zinc and tin ores and concentrates | B159: =SUM(C159:F159) -> 1.434191e+09 | C159: =VLOOKUP(A159, output_exiobase_v3.10.2_EXIO_IOT_2019_pxp_Y_imports_footprint_EU27[], 2, FALSE) -> 15051644 | D159: =VLOOKUP(A159, output_exiobase_v3.10.2_EXIO_IOT_2019_pxp_Z_imports_footprint_EU27[], 2, FALSE) -> 55367065 | E159: =VLOOKUP(A159, output_exiobase_v3.10.2_EXIO_IOT_2019_pxp_Y_production_footprint_EU27[], 2, FALSE) -> 1.7307359e+08 | F159: =VLOOKUP(A159, output_exiobase_v3.10.2_EXIO_IOT_2019_pxp_Z_production_footprint_EU27[], 2, FALSE) -> 1.1906987e+09 | G159: =(C159+D159)/B159 -> 0.049099952 | H159: =(E159+F159)/B159 -> 0.95090005
A160: Biogas | B160: =SUM(C160:F160) -> 1.4265354e+09 | C160: =VLOOKUP(A160, output_exiobase_v3.10.2_EXIO_IOT_2019_pxp_Y_imports_footprint_EU27[], 2, FALSE) -> 400.45737 | D160: =VLOOKUP(A160, output_exiobase_v3.10.2_EXIO_IOT_2019_pxp_Z_imports_footprint_EU27[], 2, FALSE) -> 284154.4 | E160: =VLOOKUP(A160, output_exiobase_v3.10.2_EXIO_IOT_2019_pxp_Y_production_footprint_EU27[], 2, FALSE) -> 14839407 | F160: =VLOOKUP(A160, output_exiobase_v3.10.2_EXIO_IOT_2019_pxp_Z_production_footprint_EU27[], 2, FALSE) -> 1.4114114e+09 | G160: =(C160+D160)/B160 -> 0.0001994727 | H160: =(E160+F160)/B160 -> 0.99980053
...

Sheet 1.1 Y_EU27_imports_2022
A1: Sheet description: | B1: Imported data from the Prodcom Python notebook: Imported final demand footprint in the European Union (EU27 2020) per product (2022)
A2: Indicator | B2: GHG characterized with IPCC 2021 - climate change: total (excl. biogenic CO2) (GWP100, kg CO2-Eq) - see EXIOBASE calculation notebook in the SI.
A4: sector | B4: climate change: total (excl. biogenic CO2)
A5: Additives/Blending Components | B5: 40561503
A6: Air transport services (62) | B6: 3.9594416e+10
A7: Aluminium and aluminium products | B7: 1.4366271e+09
A8: Aluminium ores and concentrates | B8: 489081.02
A9: Animal products nec | B9: 1.3755998e+09
A10: Anthracite | B10: 4.0151574e+08
A11: Ash for treatment, Re-processing of ash into clinker | B11: 0
A12: Aviation Gasoline | B12: 16671.667
A13: BKB/Peat Briquettes | B13: 11678835
A14: Basic iron and steel and of ferro-alloys and first products thereof | B14: 6.9301933e+09
A15: Beverages | B15: 3.1275079e+09
