Workbook

Sheet README
B2: README sheet
B5: General information
B7: Main paper title | C7: Residual biomass to bio-based chemicals and plastics: ex-ante screening methodology for prioritizing high-impact substitutions
B8: Authors | C8: Nicolas LIENART, Thibaut LECOMPTE, Lorie HAMELIN
B9: Contact (Nicolas Lienart) | C9: nicolas.lienart@insa-toulouse.fr
B10: Contact (Thibaut Lecompte) | C10: thibaut.lecompte@univ-ubs.fr
B11: Contact (Lorie Hamelin) | C11: lorie.hamelin@insa-toulouse.fr
B12: Description | C12: This file is used to perform screening on the top most produced and imported products obtained from PRODCOM data processing using the related Python notebook: "Python_notebooks/Extract PRODCOM data.ipynb". LCI datasets are associated to the selected hotspots. The final output is a CSV file that can be processed by the environmental hotspot calculation Python notebook: "Python_notebooks/Calculate hotspot products footprints and contributions.ipynb". Local production, imports and exports quantities in physical unit (i.e., kilogram mostly) of basic organic chemicals and plastics in France and in the EU27 for the years 2019 and 2022. Filtering of the top products to remove inorganics. Disaggregating of some products into their major components: polyamides (PA-6 and PA-6,6) and isocyanates (MDI and TDI). Match top products (N=57, including disaggregated products) to representative Ecoinvent activity, HS22 code and carbon content. Estimated Ecoinvent geography representativity of the top products for the EU27. Estimated generic end-of-life fate shares of the top products.
B13: Note | C13: This file is part of a set of supplementary materials. Please refer to the main manuscript and the accompanying document to find other materials and for a description of their usage.
B14: Git repository (Forge INRAE) | C14: https://forge.inrae.fr/nicolas.lienart/screen-lca-paper-supplementary-code
B15: Git repository (GitHub) | C15: https://github.com/nicolnt/screen-lca-paper-supplementary-code
B18: Updates
B20: Date | C20: Note
B21: 46146 | C21: Ready for submission
B22: 46242 | C22: Rethought the structure of the input data and added several series to compare across regions (EU27 and FR) and years (2019, 2022). Still need to bring missing sheets from the previous version of this Excel file (i.e., Calculations, Hotspots, Export)
B23: 46245 | C23: Updated the structure. Added HS22 codes. Added multiple Ecoinvent versions and regions and filled in the values obtained via BACI
B24: 46247 | C24: Improved some descriptions. Renamed some column titles and sheet name in export sheet.
B25: 46248 | C25: Update Hotspot product export sheet description
B26: 46251 | C26: Add sensitivity analysis
B27: 46253 | C27: Rename Calculations sheet and add End-of-life fates sheet
B28: 46255 | C28: Cleanings
B29: 46257 | C29: Update descriptions
B32: Sheet structure
B34: Sheet name | C34: Description
B35: README | C35: This sheet. Contains meta information about this Excel file and its structure.
B36: Filtered PRODCOM data | C36: ='Filtered PRODCOM data'!$B$1 -> PRODCOM data: local production, import, export. Regions: France (FR) and the EU (EU27_2020). Years: 2019 and 2022. Further filtering of out of scope products.
B37: Correlation EU27 2019-2022 | C37: ='Correlation EU27 2019-2022'!$B$1 -> Correlation coefficient of the PRODCOM products' mass to total mass.
B38: Split Polyamides & Isocyanates | C38: ='Split Polyamides & Isocyanates'!$B$1 -> Data and necessary calculation to split polyamides and isocyanates PRODCOM products into separate products for matching with Ecoinvent datasets.
B39: End-of-life fates | C39: ='End-of-life fates'!$B$1 -> End-of-life fate shares of plastic waste.
B40: Hotspot products export | C40: ='Hotspot products export'!$B$1 -> Extraction of the top PRODCOM products (available quantity), with disaggregation of polyamides and isocyanates. Additional data for footprint calculation. For export to CSV.
B41: Sensitivity analysis | C41: ='Sensitivity analysis'!$B$1 -> Available quantity correlation between 2019 and 2022 series, for sensitivity analysis.
B42: References | C42: =References!$B$1 -> Bibliography: list of references used thoughout the workbook
B45: Cell color nomenclature
B47: Style name | C47: Description | D47: Color | E47: Example 1 | F47: Example 2 | G47: Example 3
B48: Data Assumption | C48: Assumed data (no specific reference) | D48: pink background | E48: 15 | F48: 0.041154 | G48: 5.5855e-05
B49: Data Reference | C49: Data with reference (input) | D49: grey background | E49: 15 | F49: 0.041154 | G49: 5.5855e-05
B50: Formula | C50: Cell performing calculations using other cells | D50: blue | E50: 15 | F50: 0.041154 | G50: 5.5855e-05
B51: Data Linked Cell | C51: Cell refering to another, without transformation | D51: brown, italics | E51: 15 | F51: 0.041154 | G51: 5.5855e-05
B52: Text Reference | C52: Reference text | D52: small, grey, italic | E52: Bohers, 2024 - Com. Pers. | F52: (Muñoz and Weidema, 2024, p. 4) | G52: [2]
B53: Text Unit | C53: Unit | D53: small, centered | E53: kt.km | F53: MJ LHV/kg DM | G53: °C

Sheet Filtered PRODCOM data
A1: Sheet description: | B1: PRODCOM data: local production, import, export. Regions: France (FR) and the EU (EU27_2020). Years: 2019 and 2022. Further filtering of out of scope products.
A2: Note: | B2: PRODCOM data obtained from "Python_notebooks/Extract PRODCOM data.ipynb". The "In scope" column is filtered to only show rows with no identified issues. The identification process was performed iteratively and manually over the top products in terms of availability (i.e., local production + imports in the EU27). Therefore, only the top 50 products (after filtering) should be considered analyzed by the authors.
A4: freq | B4: product | C4: product label | D4: PRODQNT - EU27_2020 - 2019 - amount | E4: PRODQNT - EU27_2020 - 2019 - unit | F4: EXPQNT - EU27_2020 - 2019 - amount | G4: EXPQNT - EU27_2020 - 2019 - unit | H4: IMPQNT - EU27_2020 - 2019 - amount | I4: IMPQNT - EU27_2020 - 2019 - unit | J4: PRODQNT - EU27_2020 - 2022 - amount | K4: PRODQNT - EU27_2020 - 2022 - unit | L4: EXPQNT - EU27_2020 - 2022 - amount | M4: EXPQNT - EU27_2020 - 2022 - unit | N4: IMPQNT - EU27_2020 - 2022 - amount | O4: IMPQNT - EU27_2020 - 2022 - unit | P4: PRODQNT - FR - 2019 - amount | Q4: PRODQNT - FR - 2019 - unit | R4: EXPQNT - FR - 2019 - amount | S4: EXPQNT - FR - 2019 - unit | T4: IMPQNT - FR - 2019 - amount | U4: IMPQNT - FR - 2019 - unit | V4: PRODQNT - FR - 2022 - amount | W4: PRODQNT - FR - 2022 - unit | X4: EXPQNT - FR - 2022 - amount | Y4: EXPQNT - FR - 2022 - unit | Z4: IMPQNT - FR - 2022 - amount | AA4: IMPQNT - FR - 2022 - unit | AB4: PRODQNT + IMPQNT - EU27 - 2019 | AC4: PRODQNT + IMPQNT - EU27 - 2019 - secrets | AD4: PRODQNT + IMPQNT - EU27 - 2022 | AE4: PRODQNT + IMPQNT - EU27 - 2022 - secrets | AF4: PRODQNT + IMPQNT - FR - 2019 | AG4: PRODQNT + IMPQNT - FR - 2019 - secrets | AH4: PRODQNT + IMPQNT - FR - 2022 | AI4: PRODQNT + IMPQNT - FR - 2022 - secrets | AJ4: Local production share of available quantity (PRODQNT + IMPQNT) - EU27 - 2022 | AK4: In scope
A5: A | B5: 20147390 | C5: Other oils and oil products, n.e.c. | D5: 2320000000 | E5: KG | F5: 11340024043 | G5: KG | H5: 7099883514 | I5: KG | J5: 4229969352 | K5: KG | L5: 17420292158 | M5: KG | N5: 8235095443 | O5: KG | P5: : | Q5: KG | R5: 843035400 | S5: KG | T5: 325014900 | U5: KG | V5: : | W5: KG | X5: 1488203802 | Y5: KG | Z5: 342542510 | AA5: KG | AB5: =_xlfn.LET(_xlpm.production_amount, VALUE(prodcom_data[[#This Row],[PRODQNT - EU27_2020 - 2019 - amount]]), IF(ISNUMBER(_xlpm.production_amount), _xlpm.production_amount, 0))+_xlfn.LET(_xlpm.import_amount, VALUE(prodcom_data[[#This Row],[IMPQNT - EU27_2020 - 2019 - amount]]), IF(ISNUMBER(_xlpm.import_amount), _xlpm.import_amount, 0)) -> 9419883514 | AC5: =IF(NOT(AND(ISNUMBER(VALUE(prodcom_data[[#This Row],[PRODQNT - EU27_2020 - 2019 - amount]])), ISNUMBER(VALUE(prodcom_data[[#This Row],[IMPQNT - EU27_2020 - 2019 - amount]])))), "secrets", "") | AD5: =_xlfn.LET(_xlpm.production_amount, VALUE(prodcom_data[[#This Row],[PRODQNT - EU27_2020 - 2022 - amount]]), IF(ISNUMBER(_xlpm.production_amount), _xlpm.production_amount, 0))+_xlfn.LET(_xlpm.import_amount, VALUE(prodcom_data[[#This Row],[IMPQNT - EU27_2020 - 2022 - amount]]), IF(ISNUMBER(_xlpm.import_amount), _xlpm.import_amount, 0)) -> 12465064795 | AE5: =IF(NOT(AND(ISNUMBER(VALUE(prodcom_data[[#This Row],[PRODQNT - EU27_2020 - 2022 - amount]])), ISNUMBER(VALUE(prodcom_data[[#This Row],[IMPQNT - EU27_2020 - 2022 - amount]])))), "secrets", "") | AF5: =_xlfn.LET(_xlpm.production_amount, VALUE(prodcom_data[[#This Row],[PRODQNT - FR - 2019 - amount]]), IF(ISNUMBER(_xlpm.production_amount), _xlpm.production_amount, 0))+_xlfn.LET(_xlpm.import_amount, VALUE(prodcom_data[[#This Row],[IMPQNT - FR - 2019 - amount]]), IF(ISNUMBER(_xlpm.import_amount), _xlpm.import_amount, 0)) -> 325014900 | AG5: =IF(NOT(AND(ISNUMBER(VALUE(prodcom_data[[#This Row],[PRODQNT - FR - 2019 - amount]])), ISNUMBER(VALUE(prodcom_data[[#This Row],[IMPQNT - FR - 2019 - amount]])))), "secrets", "") -> secrets | AH5: =_xlfn.LET(_xlpm.production_amount, VALUE(prodcom_data[[#This Row],[PRODQNT - FR - 2022 - amount]]), IF(ISNUMBER(_xlpm.production_amount), _xlpm.production_amount, 0))+_xlfn.LET(_xlpm.import_amount, VALUE(prodcom_data[[#This Row],[IMPQNT - FR - 2022 - amount]]), IF(ISNUMBER(_xlpm.import_amount), _xlpm.import_amount, 0)) -> 342542510 | AI5: =IF(NOT(AND(ISNUMBER(VALUE(prodcom_data[[#This Row],[PRODQNT - FR - 2022 - amount]])), ISNUMBER(VALUE(prodcom_data[[#This Row],[IMPQNT - FR - 2022 - amount]])))), "secrets", "") -> secrets | AJ5: =_xlfn.LET(_xlpm.production_amount, IF(ISNUMBER(VALUE(prodcom_data[[#This Row],[PRODQNT - EU27_2020 - 2022 - amount]])),VALUE(prodcom_data[[#This Row],[PRODQNT - EU27_2020 - 2022 - amount]]), 0), _xlpm.import_amount, IF(ISNUMBER(VALUE(prodcom_data[[#This Row],[IMPQNT - EU27_2020 - 2022 - amount]])), VALUE(prodcom_data[[#This Row],[IMPQNT - EU27_2020 - 2022 - amount]]), 0), _xlpm.production_amount/(_xlpm.production_amount+_xlpm.import_amount)) -> 0.33934596 | AK5: Too broad
A6: A | B6: 20165130 | C6: Polypropylene, in primary forms | D6: 9673911407 | E6: KG | F6: 1031526235 | G6: KG | H6: 1366859420 | I6: KG | J6: 9555914244 | K6: KG | L6: 840201926 | M6: KG | N6: 1503902249 | O6: KG | P6: 1328181138 | Q6: KG | R6: 528842900 | S6: KG | T6: 450055900 | U6: KG | V6: 1002690213 | W6: KG | X6: 453736761 | Y6: KG | Z6: 360204335 | AA6: KG | AB6: =_xlfn.LET(_xlpm.production_amount, VALUE(prodcom_data[[#This Row],[PRODQNT - EU27_2020 - 2019 - amount]]), IF(ISNUMBER(_xlpm.production_amount), _xlpm.production_amount, 0))+_xlfn.LET(_xlpm.import_amount, VALUE(prodcom_data[[#This Row],[IMPQNT - EU27_2020 - 2019 - amount]]), IF(ISNUMBER(_xlpm.import_amount), _xlpm.import_amount, 0)) -> 11040770827 | AC6: =IF(NOT(AND(ISNUMBER(VALUE(prodcom_data[[#This Row],[PRODQNT - EU27_2020 - 2019 - amount]])), ISNUMBER(VALUE(prodcom_data[[#This Row],[IMPQNT - EU27_2020 - 2019 - amount]])))), "secrets", "") | AD6: =_xlfn.LET(_xlpm.production_amount, VALUE(prodcom_data[[#This Row],[PRODQNT - EU27_2020 - 2022 - amount]]), IF(ISNUMBER(_xlpm.production_amount), _xlpm.production_amount, 0))+_xlfn.LET(_xlpm.import_amount, VALUE(prodcom_data[[#This Row],[IMPQNT - EU27_2020 - 2022 - amount]]), IF(ISNUMBER(_xlpm.import_amount), _xlpm.import_amount, 0)) -> 11059816493 | AE6: =IF(NOT(AND(ISNUMBER(VALUE(prodcom_data[[#This Row],[PRODQNT - EU27_2020 - 2022 - amount]])), ISNUMBER(VALUE(prodcom_data[[#This Row],[IMPQNT - EU27_2020 - 2022 - amount]])))), "secrets", "") | AF6: =_xlfn.LET(_xlpm.production_amount, VALUE(prodcom_data[[#This Row],[PRODQNT - FR - 2019 - amount]]), IF(ISNUMBER(_xlpm.production_amount), _xlpm.production_amount, 0))+_xlfn.LET(_xlpm.import_amount, VALUE(prodcom_data[[#This Row],[IMPQNT - FR - 2019 - amount]]), IF(ISNUMBER(_xlpm.import_amount), _xlpm.import_amount, 0)) -> 1778237038 | AG6: =IF(NOT(AND(ISNUMBER(VALUE(prodcom_data[[#This Row],[PRODQNT - FR - 2019 - amount]])), ISNUMBER(VALUE(prodcom_data[[#This Row],[IMPQNT - FR - 2019 - amount]])))), "secrets", "") | AH6: =_xlfn.LET(_xlpm.production_amount, VALUE(prodcom_data[[#This Row],[PRODQNT - FR - 2022 - amount]]), IF(ISNUMBER(_xlpm.production_amount), _xlpm.production_amount, 0))+_xlfn.LET(_xlpm.import_amount, VALUE(prodcom_data[[#This Row],[IMPQNT - FR - 2022 - amount]]), IF(ISNUMBER(_xlpm.import_amount), _xlpm.import_amount, 0)) -> 1362894548 | AI6: =IF(NOT(AND(ISNUMBER(VALUE(prodcom_data[[#This Row],[PRODQNT - FR - 2022 - amount]])), ISNUMBER(VALUE(prodcom_data[[#This Row],[IMPQNT - FR - 2022 - amount]])))), "secrets", "") | AJ6: =_xlfn.LET(_xlpm.production_amount, IF(ISNUMBER(VALUE(prodcom_data[[#This Row],[PRODQNT - EU27_2020 - 2022 - amount]])),VALUE(prodcom_data[[#This Row],[PRODQNT - EU27_2020 - 2022 - amount]]), 0), _xlpm.import_amount, IF(ISNUMBER(VALUE(prodcom_data[[#This Row],[IMPQNT - EU27_2020 - 2022 - amount]])), VALUE(prodcom_data[[#This Row],[IMPQNT - EU27_2020 - 2022 - amount]]), 0), _xlpm.production_amount/(_xlpm.production_amount+_xlpm.import_amount)) -> 0.86402105
A7: A | B7: 20141130 | C7: Ethylene | D7: 9817689027 | E7: KG | F7: 280758738 | G7: KG | H7: 1418579590 | I7: KG | J7: 9087159767 | K7: KG | L7: 130155532 | M7: KG | N7: 1250333999 | O7: KG | P7: 1454878883 | Q7: KG | R7: 198372600 | S7: KG | T7: 71123000 | U7: KG | V7: : | W7: KG | X7: 101283487 | Y7: KG | Z7: 171202101 | AA7: KG | AB7: =_xlfn.LET(_xlpm.production_amount, VALUE(prodcom_data[[#This Row],[PRODQNT - EU27_2020 - 2019 - amount]]), IF(ISNUMBER(_xlpm.production_amount), _xlpm.production_amount, 0))+_xlfn.LET(_xlpm.import_amount, VALUE(prodcom_data[[#This Row],[IMPQNT - EU27_2020 - 2019 - amount]]), IF(ISNUMBER(_xlpm.import_amount), _xlpm.import_amount, 0)) -> 11236268617 | AC7: =IF(NOT(AND(ISNUMBER(VALUE(prodcom_data[[#This Row],[PRODQNT - EU27_2020 - 2019 - amount]])), ISNUMBER(VALUE(prodcom_data[[#This Row],[IMPQNT - EU27_2020 - 2019 - amount]])))), "secrets", "") | AD7: =_xlfn.LET(_xlpm.production_amount, VALUE(prodcom_data[[#This Row],[PRODQNT - EU27_2020 - 2022 - amount]]), IF(ISNUMBER(_xlpm.production_amount), _xlpm.production_amount, 0))+_xlfn.LET(_xlpm.import_amount, VALUE(prodcom_data[[#This Row],[IMPQNT - EU27_2020 - 2022 - amount]]), IF(ISNUMBER(_xlpm.import_amount), _xlpm.import_amount, 0)) -> 10337493766 | AE7: =IF(NOT(AND(ISNUMBER(VALUE(prodcom_data[[#This Row],[PRODQNT - EU27_2020 - 2022 - amount]])), ISNUMBER(VALUE(prodcom_data[[#This Row],[IMPQNT - EU27_2020 - 2022 - amount]])))), "secrets", "") | AF7: =_xlfn.LET(_xlpm.production_amount, VALUE(prodcom_data[[#This Row],[PRODQNT - FR - 2019 - amount]]), IF(ISNUMBER(_xlpm.production_amount), _xlpm.production_amount, 0))+_xlfn.LET(_xlpm.import_amount, VALUE(prodcom_data[[#This Row],[IMPQNT - FR - 2019 - amount]]), IF(ISNUMBER(_xlpm.import_amount), _xlpm.import_amount, 0)) -> 1526001883 | AG7: =IF(NOT(AND(ISNUMBER(VALUE(prodcom_data[[#This Row],[PRODQNT - FR - 2019 - amount]])), ISNUMBER(VALUE(prodcom_data[[#This Row],[IMPQNT - FR - 2019 - amount]])))), "secrets", "") | AH7: =_xlfn.LET(_xlpm.production_amount, VALUE(prodcom_data[[#This Row],[PRODQNT - FR - 2022 - amount]]), IF(ISNUMBER(_xlpm.production_amount), _xlpm.production_amount, 0))+_xlfn.LET(_xlpm.import_amount, VALUE(prodcom_data[[#This Row],[IMPQNT - FR - 2022 - amount]]), IF(ISNUMBER(_xlpm.import_amount), _xlpm.import_amount, 0)) -> 171202101 | AI7: =IF(NOT(AND(ISNUMBER(VALUE(prodcom_data[[#This Row],[PRODQNT - FR - 2022 - amount]])), ISNUMBER(VALUE(prodcom_data[[#This Row],[IMPQNT - FR - 2022 - amount]])))), "secrets", "") -> secrets | AJ7: =_xlfn.LET(_xlpm.production_amount, IF(ISNUMBER(VALUE(prodcom_data[[#This Row],[PRODQNT - EU27_2020 - 2022 - amount]])),VALUE(prodcom_data[[#This Row],[PRODQNT - EU27_2020 - 2022 - amount]]), 0), _xlpm.import_amount, IF(ISNUMBER(VALUE(prodcom_data[[#This Row],[IMPQNT - EU27_2020 - 2022 - amount]])), VALUE(prodcom_data[[#This Row],[IMPQNT - EU27_2020 - 2022 - amount]]), 0), _xlpm.production_amount/(_xlpm.production_amount+_xlpm.import_amount)) -> 0.87904863
A8: A | B8: 20141140 | C8: Propene (propylene) | D8: 9792446126 | E8: KG | F8: 124453445 | G8: KG | H8: 845569901 | I8: KG | J8: 8574019066 | K8: KG | L8: 199594233 | M8: KG | N8: 507722136 | O8: KG | P8: 1055275803 | Q8: KG | R8: 120498700 | S8: KG | T8: 376161400 | U8: KG | V8: : | W8: KG | X8: 91064341 | Y8: KG | Z8: 361054455 | AA8: KG | AB8: =_xlfn.LET(_xlpm.production_amount, VALUE(prodcom_data[[#This Row],[PRODQNT - EU27_2020 - 2019 - amount]]), IF(ISNUMBER(_xlpm.production_amount), _xlpm.production_amount, 0))+_xlfn.LET(_xlpm.import_amount, VALUE(prodcom_data[[#This Row],[IMPQNT - EU27_2020 - 2019 - amount]]), IF(ISNUMBER(_xlpm.import_amount), _xlpm.import_amount, 0)) -> 10638016027 | AC8: =IF(NOT(AND(ISNUMBER(VALUE(prodcom_data[[#This Row],[PRODQNT - EU27_2020 - 2019 - amount]])), ISNUMBER(VALUE(prodcom_data[[#This Row],[IMPQNT - EU27_2020 - 2019 - amount]])))), "secrets", "") | AD8: =_xlfn.LET(_xlpm.production_amount, VALUE(prodcom_data[[#This Row],[PRODQNT - EU27_2020 - 2022 - amount]]), IF(ISNUMBER(_xlpm.production_amount), _xlpm.production_amount, 0))+_xlfn.LET(_xlpm.import_amount, VALUE(prodcom_data[[#This Row],[IMPQNT - EU27_2020 - 2022 - amount]]), IF(ISNUMBER(_xlpm.import_amount), _xlpm.import_amount, 0)) -> 9081741202 | AE8: =IF(NOT(AND(ISNUMBER(VALUE(prodcom_data[[#This Row],[PRODQNT - EU27_2020 - 2022 - amount]])), ISNUMBER(VALUE(prodcom_data[[#This Row],[IMPQNT - EU27_2020 - 2022 - amount]])))), "secrets", "") | AF8: =_xlfn.LET(_xlpm.production_amount, VALUE(prodcom_data[[#This Row],[PRODQNT - FR - 2019 - amount]]), IF(ISNUMBER(_xlpm.production_amount), _xlpm.production_amount, 0))+_xlfn.LET(_xlpm.import_amount, VALUE(prodcom_data[[#This Row],[IMPQNT - FR - 2019 - amount]]), IF(ISNUMBER(_xlpm.import_amount), _xlpm.import_amount, 0)) -> 1431437203 | AG8: =IF(NOT(AND(ISNUMBER(VALUE(prodcom_data[[#This Row],[PRODQNT - FR - 2019 - amount]])), ISNUMBER(VALUE(prodcom_data[[#This Row],[IMPQNT - FR - 2019 - amount]])))), "secrets", "") | AH8: =_xlfn.LET(_xlpm.production_amount, VALUE(prodcom_data[[#This Row],[PRODQNT - FR - 2022 - amount]]), IF(ISNUMBER(_xlpm.production_amount), _xlpm.production_amount, 0))+_xlfn.LET(_xlpm.import_amount, VALUE(prodcom_data[[#This Row],[IMPQNT - FR - 2022 - amount]]), IF(ISNUMBER(_xlpm.import_amount), _xlpm.import_amount, 0)) -> 361054455 | AI8: =IF(NOT(AND(ISNUMBER(VALUE(prodcom_data[[#This Row],[PRODQNT - FR - 2022 - amount]])), ISNUMBER(VALUE(prodcom_data[[#This Row],[IMPQNT - FR - 2022 - amount]])))), "secrets", "") -> secrets | AJ8: =_xlfn.LET(_xlpm.production_amount, IF(ISNUMBER(VALUE(prodcom_data[[#This Row],[PRODQNT - EU27_2020 - 2022 - amount]])),VALUE(prodcom_data[[#This Row],[PRODQNT - EU27_2020 - 2022 - amount]]), 0), _xlpm.import_amount, IF(ISNUMBER(VALUE(prodcom_data[[#This Row],[IMPQNT - EU27_2020 - 2022 - amount]])), VALUE(prodcom_data[[#This Row],[IMPQNT - EU27_2020 - 2022 - amount]]), 0), _xlpm.production_amount/(_xlpm.production_amount+_xlpm.import_amount)) -> 0.94409419
A9: A | B9: 20161050 | C9: Polyethylene having a specific gravity of >= 0,94, in primary forms | D9: 5550745548 | E9: KG | F9: 1237023590 | G9: KG | H9: 1953474415 | I9: KG | J9: 5978698843 | K9: KG | L9: 990970125 | M9: KG | N9: 1650180628 | O9: KG | P9: : | Q9: KG | R9: 343468500 | S9: KG | T9: 518059400 | U9: KG | V9: : | W9: KG | X9: 323981555 | Y9: KG | Z9: 455203986 | AA9: KG | AB9: =_xlfn.LET(_xlpm.production_amount, VALUE(prodcom_data[[#This Row],[PRODQNT - EU27_2020 - 2019 - amount]]), IF(ISNUMBER(_xlpm.production_amount), _xlpm.production_amount, 0))+_xlfn.LET(_xlpm.import_amount, VALUE(prodcom_data[[#This Row],[IMPQNT - EU27_2020 - 2019 - amount]]), IF(ISNUMBER(_xlpm.import_amount), _xlpm.import_amount, 0)) -> 7504219963 | AC9: =IF(NOT(AND(ISNUMBER(VALUE(prodcom_data[[#This Row],[PRODQNT - EU27_2020 - 2019 - amount]])), ISNUMBER(VALUE(prodcom_data[[#This Row],[IMPQNT - EU27_2020 - 2019 - amount]])))), "secrets", "") | AD9: =_xlfn.LET(_xlpm.production_amount, VALUE(prodcom_data[[#This Row],[PRODQNT - EU27_2020 - 2022 - amount]]), IF(ISNUMBER(_xlpm.production_amount), _xlpm.production_amount, 0))+_xlfn.LET(_xlpm.import_amount, VALUE(prodcom_data[[#This Row],[IMPQNT - EU27_2020 - 2022 - amount]]), IF(ISNUMBER(_xlpm.import_amount), _xlpm.import_amount, 0)) -> 7628879471 | AE9: =IF(NOT(AND(ISNUMBER(VALUE(prodcom_data[[#This Row],[PRODQNT - EU27_2020 - 2022 - amount]])), ISNUMBER(VALUE(prodcom_data[[#This Row],[IMPQNT - EU27_2020 - 2022 - amount]])))), "secrets", "") | AF9: =_xlfn.LET(_xlpm.production_amount, VALUE(prodcom_data[[#This Row],[PRODQNT - FR - 2019 - amount]]), IF(ISNUMBER(_xlpm.production_amount), _xlpm.production_amount, 0))+_xlfn.LET(_xlpm.import_amount, VALUE(prodcom_data[[#This Row],[IMPQNT - FR - 2019 - amount]]), IF(ISNUMBER(_xlpm.import_amount), _xlpm.import_amount, 0)) -> 518059400 | AG9: =IF(NOT(AND(ISNUMBER(VALUE(prodcom_data[[#This Row],[PRODQNT - FR - 2019 - amount]])), ISNUMBER(VALUE(prodcom_data[[#This Row],[IMPQNT - FR - 2019 - amount]])))), "secrets", "") -> secrets | AH9: =_xlfn.LET(_xlpm.production_amount, VALUE(prodcom_data[[#This Row],[PRODQNT - FR - 2022 - amount]]), IF(ISNUMBER(_xlpm.production_amount), _xlpm.production_amount, 0))+_xlfn.LET(_xlpm.import_amount, VALUE(prodcom_data[[#This Row],[IMPQNT - FR - 2022 - amount]]), IF(ISNUMBER(_xlpm.import_amount), _xlpm.import_amount, 0)) -> 455203986 | AI9: =IF(NOT(AND(ISNUMBER(VALUE(prodcom_data[[#This Row],[PRODQNT - FR - 2022 - amount]])), ISNUMBER(VALUE(prodcom_data[[#This Row],[IMPQNT - FR - 2022 - amount]])))), "secrets", "") -> secrets | AJ9: =_xlfn.LET(_xlpm.production_amount, IF(ISNUMBER(VALUE(prodcom_data[[#This Row],[PRODQNT - EU27_2020 - 2022 - amount]])),VALUE(prodcom_data[[#This Row],[PRODQNT - EU27_2020 - 2022 - amount]]), 0), _xlpm.import_amount, IF(ISNUMBER(VALUE(prodcom_data[[#This Row],[IMPQNT - EU27_2020 - 2022 - amount]])), VALUE(prodcom_data[[#This Row],[IMPQNT - EU27_2020 - 2022 - amount]]), 0), _xlpm.production_amount/(_xlpm.production_amount+_xlpm.import_amount)) -> 0.78369292
A10: A | B10: 20142210 | C10: Methanol (methyl alcohol) | D10: 1200000000 | E10: KG | F10: 465543413 | G10: KG | H10: 6504716635 | I10: KG | J10: 980000000 | K10: KG | L10: 360831488 | M10: KG | N10: 5924732058 | O10: KG | P10: : | Q10: KG | R10: 3032600 | S10: KG | T10: 621287900 | U10: KG | V10: 2033506 | W10: KG | X10: 2559616 | Y10: KG | Z10: 576113848 | AA10: KG | AB10: =_xlfn.LET(_xlpm.production_amount, VALUE(prodcom_data[[#This Row],[PRODQNT - EU27_2020 - 2019 - amount]]), IF(ISNUMBER(_xlpm.production_amount), _xlpm.production_amount, 0))+_xlfn.LET(_xlpm.import_amount, VALUE(prodcom_data[[#This Row],[IMPQNT - EU27_2020 - 2019 - amount]]), IF(ISNUMBER(_xlpm.import_amount), _xlpm.import_amount, 0)) -> 7704716635 | AC10: =IF(NOT(AND(ISNUMBER(VALUE(prodcom_data[[#This Row],[PRODQNT - EU27_2020 - 2019 - amount]])), ISNUMBER(VALUE(prodcom_data[[#This Row],[IMPQNT - EU27_2020 - 2019 - amount]])))), "secrets", "") | AD10: =_xlfn.LET(_xlpm.production_amount, VALUE(prodcom_data[[#This Row],[PRODQNT - EU27_2020 - 2022 - amount]]), IF(ISNUMBER(_xlpm.production_amount), _xlpm.production_amount, 0))+_xlfn.LET(_xlpm.import_amount, VALUE(prodcom_data[[#This Row],[IMPQNT - EU27_2020 - 2022 - amount]]), IF(ISNUMBER(_xlpm.import_amount), _xlpm.import_amount, 0)) -> 6904732058 | AE10: =IF(NOT(AND(ISNUMBER(VALUE(prodcom_data[[#This Row],[PRODQNT - EU27_2020 - 2022 - amount]])), ISNUMBER(VALUE(prodcom_data[[#This Row],[IMPQNT - EU27_2020 - 2022 - amount]])))), "secrets", "") | AF10: =_xlfn.LET(_xlpm.production_amount, VALUE(prodcom_data[[#This Row],[PRODQNT - FR - 2019 - amount]]), IF(ISNUMBER(_xlpm.production_amount), _xlpm.production_amount, 0))+_xlfn.LET(_xlpm.import_amount, VALUE(prodcom_data[[#This Row],[IMPQNT - FR - 2019 - amount]]), IF(ISNUMBER(_xlpm.import_amount), _xlpm.import_amount, 0)) -> 621287900 | AG10: =IF(NOT(AND(ISNUMBER(VALUE(prodcom_data[[#This Row],[PRODQNT - FR - 2019 - amount]])), ISNUMBER(VALUE(prodcom_data[[#This Row],[IMPQNT - FR - 2019 - amount]])))), "secrets", "") -> secrets | AH10: =_xlfn.LET(_xlpm.production_amount, VALUE(prodcom_data[[#This Row],[PRODQNT - FR - 2022 - amount]]), IF(ISNUMBER(_xlpm.production_amount), _xlpm.production_amount, 0))+_xlfn.LET(_xlpm.import_amount, VALUE(prodcom_data[[#This Row],[IMPQNT - FR - 2022 - amount]]), IF(ISNUMBER(_xlpm.import_amount), _xlpm.import_amount, 0)) -> 578147354 | AI10: =IF(NOT(AND(ISNUMBER(VALUE(prodcom_data[[#This Row],[PRODQNT - FR - 2022 - amount]])), ISNUMBER(VALUE(prodcom_data[[#This Row],[IMPQNT - FR - 2022 - amount]])))), "secrets", "") | AJ10: =_xlfn.LET(_xlpm.production_amount, IF(ISNUMBER(VALUE(prodcom_data[[#This Row],[PRODQNT - EU27_2020 - 2022 - amount]])),VALUE(prodcom_data[[#This Row],[PRODQNT - EU27_2020 - 2022 - amount]]), 0), _xlpm.import_amount, IF(ISNUMBER(VALUE(prodcom_data[[#This Row],[IMPQNT - EU27_2020 - 2022 - amount]])), VALUE(prodcom_data[[#This Row],[IMPQNT - EU27_2020 - 2022 - amount]]), 0), _xlpm.production_amount/(_xlpm.production_amount+_xlpm.import_amount)) -> 0.14193165
A11: A | B11: 20141223 | C11: Benzene | D11: 5406482633 | E11: KG | F11: 113144308 | G11: KG | H11: 1030258210 | I11: KG | J11: 5504236965 | K11: KG | L11: 319663008 | M11: KG | N11: 730239102 | O11: KG | P11: 453962000 | Q11: KG | R11: 106748700 | S11: KG | T11: 271292700 | U11: KG | V11: : | W11: KG | X11: 81604347 | Y11: KG | Z11: 185801174 | AA11: KG | AB11: =_xlfn.LET(_xlpm.production_amount, VALUE(prodcom_data[[#This Row],[PRODQNT - EU27_2020 - 2019 - amount]]), IF(ISNUMBER(_xlpm.production_amount), _xlpm.production_amount, 0))+_xlfn.LET(_xlpm.import_amount, VALUE(prodcom_data[[#This Row],[IMPQNT - EU27_2020 - 2019 - amount]]), IF(ISNUMBER(_xlpm.import_amount), _xlpm.import_amount, 0)) -> 6436740843 | AC11: =IF(NOT(AND(ISNUMBER(VALUE(prodcom_data[[#This Row],[PRODQNT - EU27_2020 - 2019 - amount]])), ISNUMBER(VALUE(prodcom_data[[#This Row],[IMPQNT - EU27_2020 - 2019 - amount]])))), "secrets", "") | AD11: =_xlfn.LET(_xlpm.production_amount, VALUE(prodcom_data[[#This Row],[PRODQNT - EU27_2020 - 2022 - amount]]), IF(ISNUMBER(_xlpm.production_amount), _xlpm.production_amount, 0))+_xlfn.LET(_xlpm.import_amount, VALUE(prodcom_data[[#This Row],[IMPQNT - EU27_2020 - 2022 - amount]]), IF(ISNUMBER(_xlpm.import_amount), _xlpm.import_amount, 0)) -> 6234476067 | AE11: =IF(NOT(AND(ISNUMBER(VALUE(prodcom_data[[#This Row],[PRODQNT - EU27_2020 - 2022 - amount]])), ISNUMBER(VALUE(prodcom_data[[#This Row],[IMPQNT - EU27_2020 - 2022 - amount]])))), "secrets", "") | AF11: =_xlfn.LET(_xlpm.production_amount, VALUE(prodcom_data[[#This Row],[PRODQNT - FR - 2019 - amount]]), IF(ISNUMBER(_xlpm.production_amount), _xlpm.production_amount, 0))+_xlfn.LET(_xlpm.import_amount, VALUE(prodcom_data[[#This Row],[IMPQNT - FR - 2019 - amount]]), IF(ISNUMBER(_xlpm.import_amount), _xlpm.import_amount, 0)) -> 725254700 | AG11: =IF(NOT(AND(ISNUMBER(VALUE(prodcom_data[[#This Row],[PRODQNT - FR - 2019 - amount]])), ISNUMBER(VALUE(prodcom_data[[#This Row],[IMPQNT - FR - 2019 - amount]])))), "secrets", "") | AH11: =_xlfn.LET(_xlpm.production_amount, VALUE(prodcom_data[[#This Row],[PRODQNT - FR - 2022 - amount]]), IF(ISNUMBER(_xlpm.production_amount), _xlpm.production_amount, 0))+_xlfn.LET(_xlpm.import_amount, VALUE(prodcom_data[[#This Row],[IMPQNT - FR - 2022 - amount]]), IF(ISNUMBER(_xlpm.import_amount), _xlpm.import_amount, 0)) -> 185801174 | AI11: =IF(NOT(AND(ISNUMBER(VALUE(prodcom_data[[#This Row],[PRODQNT - FR - 2022 - amount]])), ISNUMBER(VALUE(prodcom_data[[#This Row],[IMPQNT - FR - 2022 - amount]])))), "secrets", "") -> secrets | AJ11: =_xlfn.LET(_xlpm.production_amount, IF(ISNUMBER(VALUE(prodcom_data[[#This Row],[PRODQNT - EU27_2020 - 2022 - amount]])),VALUE(prodcom_data[[#This Row],[PRODQNT - EU27_2020 - 2022 - amount]]), 0), _xlpm.import_amount, IF(ISNUMBER(VALUE(prodcom_data[[#This Row],[IMPQNT - EU27_2020 - 2022 - amount]])), VALUE(prodcom_data[[#This Row],[IMPQNT - EU27_2020 - 2022 - amount]]), 0), _xlpm.production_amount/(_xlpm.production_amount+_xlpm.import_amount)) -> 0.88287081
A12: A | B12: 20147340 | C12: Naphthalene and other aromatic hydrocarbon mixtures (excluding benzene, toluene, xylene) | D12: 3857631585 | E12: KG | F12: 1609435284 | G12: KG | H12: 2479688162 | I12: KG | J12: 4200000000 | K12: KG | L12: 817079827 | M12: KG | N12: 1785891804 | O12: KG | P12: 718962185 | Q12: KG | R12: 332620600 | S12: KG | T12: 92493100 | U12: KG | V12: 213667462 | W12: KG | X12: 371161494 | Y12: KG | Z12: 67629059 | AA12: KG | AB12: =_xlfn.LET(_xlpm.production_amount, VALUE(prodcom_data[[#This Row],[PRODQNT - EU27_2020 - 2019 - amount]]), IF(ISNUMBER(_xlpm.production_amount), _xlpm.production_amount, 0))+_xlfn.LET(_xlpm.import_amount, VALUE(prodcom_data[[#This Row],[IMPQNT - EU27_2020 - 2019 - amount]]), IF(ISNUMBER(_xlpm.import_amount), _xlpm.import_amount, 0)) -> 6337319747 | AC12: =IF(NOT(AND(ISNUMBER(VALUE(prodcom_data[[#This Row],[PRODQNT - EU27_2020 - 2019 - amount]])), ISNUMBER(VALUE(prodcom_data[[#This Row],[IMPQNT - EU27_2020 - 2019 - amount]])))), "secrets", "") | AD12: =_xlfn.LET(_xlpm.production_amount, VALUE(prodcom_data[[#This Row],[PRODQNT - EU27_2020 - 2022 - amount]]), IF(ISNUMBER(_xlpm.production_amount), _xlpm.production_amount, 0))+_xlfn.LET(_xlpm.import_amount, VALUE(prodcom_data[[#This Row],[IMPQNT - EU27_2020 - 2022 - amount]]), IF(ISNUMBER(_xlpm.import_amount), _xlpm.import_amount, 0)) -> 5985891804 | AE12: =IF(NOT(AND(ISNUMBER(VALUE(prodcom_data[[#This Row],[PRODQNT - EU27_2020 - 2022 - amount]])), ISNUMBER(VALUE(prodcom_data[[#This Row],[IMPQNT - EU27_2020 - 2022 - amount]])))), "secrets", "") | AF12: =_xlfn.LET(_xlpm.production_amount, VALUE(prodcom_data[[#This Row],[PRODQNT - FR - 2019 - amount]]), IF(ISNUMBER(_xlpm.production_amount), _xlpm.production_amount, 0))+_xlfn.LET(_xlpm.import_amount, VALUE(prodcom_data[[#This Row],[IMPQNT - FR - 2019 - amount]]), IF(ISNUMBER(_xlpm.import_amount), _xlpm.import_amount, 0)) -> 811455285 | AG12: =IF(NOT(AND(ISNUMBER(VALUE(prodcom_data[[#This Row],[PRODQNT - FR - 2019 - amount]])), ISNUMBER(VALUE(prodcom_data[[#This Row],[IMPQNT - FR - 2019 - amount]])))), "secrets", "") | AH12: =_xlfn.LET(_xlpm.production_amount, VALUE(prodcom_data[[#This Row],[PRODQNT - FR - 2022 - amount]]), IF(ISNUMBER(_xlpm.production_amount), _xlpm.production_amount, 0))+_xlfn.LET(_xlpm.import_amount, VALUE(prodcom_data[[#This Row],[IMPQNT - FR - 2022 - amount]]), IF(ISNUMBER(_xlpm.import_amount), _xlpm.import_amount, 0)) -> 281296521 | AI12: =IF(NOT(AND(ISNUMBER(VALUE(prodcom_data[[#This Row],[PRODQNT - FR - 2022 - amount]])), ISNUMBER(VALUE(prodcom_data[[#This Row],[IMPQNT - FR - 2022 - amount]])))), "secrets", "") | AJ12: =_xlfn.LET(_xlpm.production_amount, IF(ISNUMBER(VALUE(prodcom_data[[#This Row],[PRODQNT - EU27_2020 - 2022 - amount]])),VALUE(prodcom_data[[#This Row],[PRODQNT - EU27_2020 - 2022 - amount]]), 0), _xlpm.import_amount, IF(ISNUMBER(VALUE(prodcom_data[[#This Row],[IMPQNT - EU27_2020 - 2022 - amount]])), VALUE(prodcom_data[[#This Row],[IMPQNT - EU27_2020 - 2022 - amount]]), 0), _xlpm.production_amount/(_xlpm.production_amount+_xlpm.import_amount)) -> 0.70164984 | AK12: Too broad
A13: A | B13: 20147400 | C13: Undenatured ethyl alcohol of an alcoholic strength by volume >= 80 % (important: excluding alcohol duty) | D13: 3849209351.0 | E13: KG | F13: 579008236.22 | G13: KG | H13: 766310790.61 | I13: KG | J13: 3950000000.0 | K13: KG | L13: 352347383.34000003 | M13: KG | N13: 1202299307.03 | O13: KG | P13: 1134544968.0900002 | Q13: KG | R13: 606179743.49 | S13: KG | T13: 354912762.19 | U13: KG | V13: 1169549630.3 | W13: KG | X13: 399937967.68 | Y13: KG | Z13: 638756277.5 | AA13: KG | AB13: =_xlfn.LET(_xlpm.production_amount, VALUE(prodcom_data[[#This Row],[PRODQNT - EU27_2020 - 2019 - amount]]), IF(ISNUMBER(_xlpm.production_amount), _xlpm.production_amount, 0))+_xlfn.LET(_xlpm.import_amount, VALUE(prodcom_data[[#This Row],[IMPQNT - EU27_2020 - 2019 - amount]]), IF(ISNUMBER(_xlpm.import_amount), _xlpm.import_amount, 0)) -> 4.6155201e+09 | AC13: =IF(NOT(AND(ISNUMBER(VALUE(prodcom_data[[#This Row],[PRODQNT - EU27_2020 - 2019 - amount]])), ISNUMBER(VALUE(prodcom_data[[#This Row],[IMPQNT - EU27_2020 - 2019 - amount]])))), "secrets", "") | AD13: =_xlfn.LET(_xlpm.production_amount, VALUE(prodcom_data[[#This Row],[PRODQNT - EU27_2020 - 2022 - amount]]), IF(ISNUMBER(_xlpm.production_amount), _xlpm.production_amount, 0))+_xlfn.LET(_xlpm.import_amount, VALUE(prodcom_data[[#This Row],[IMPQNT - EU27_2020 - 2022 - amount]]), IF(ISNUMBER(_xlpm.import_amount), _xlpm.import_amount, 0)) -> 5.1522993e+09 | AE13: =IF(NOT(AND(ISNUMBER(VALUE(prodcom_data[[#This Row],[PRODQNT - EU27_2020 - 2022 - amount]])), ISNUMBER(VALUE(prodcom_data[[#This Row],[IMPQNT - EU27_2020 - 2022 - amount]])))), "secrets", "") | AF13: =_xlfn.LET(_xlpm.production_amount, VALUE(prodcom_data[[#This Row],[PRODQNT - FR - 2019 - amount]]), IF(ISNUMBER(_xlpm.production_amount), _xlpm.production_amount, 0))+_xlfn.LET(_xlpm.import_amount, VALUE(prodcom_data[[#This Row],[IMPQNT - FR - 2019 - amount]]), IF(ISNUMBER(_xlpm.import_amount), _xlpm.import_amount, 0)) -> 1.4894577e+09 | AG13: =IF(NOT(AND(ISNUMBER(VALUE(prodcom_data[[#This Row],[PRODQNT - FR - 2019 - amount]])), ISNUMBER(VALUE(prodcom_data[[#This Row],[IMPQNT - FR - 2019 - amount]])))), "secrets", "") | AH13: =_xlfn.LET(_xlpm.production_amount, VALUE(prodcom_data[[#This Row],[PRODQNT - FR - 2022 - amount]]), IF(ISNUMBER(_xlpm.production_amount), _xlpm.production_amount, 0))+_xlfn.LET(_xlpm.import_amount, VALUE(prodcom_data[[#This Row],[IMPQNT - FR - 2022 - amount]]), IF(ISNUMBER(_xlpm.import_amount), _xlpm.import_amount, 0)) -> 1.8083059e+09 | AI13: =IF(NOT(AND(ISNUMBER(VALUE(prodcom_data[[#This Row],[PRODQNT - FR - 2022 - amount]])), ISNUMBER(VALUE(prodcom_data[[#This Row],[IMPQNT - FR - 2022 - amount]])))), "secrets", "") | AJ13: =_xlfn.LET(_xlpm.production_amount, IF(ISNUMBER(VALUE(prodcom_data[[#This Row],[PRODQNT - EU27_2020 - 2022 - amount]])),VALUE(prodcom_data[[#This Row],[PRODQNT - EU27_2020 - 2022 - amount]]), 0), _xlpm.import_amount, IF(ISNUMBER(VALUE(prodcom_data[[#This Row],[IMPQNT - EU27_2020 - 2022 - amount]])), VALUE(prodcom_data[[#This Row],[IMPQNT - EU27_2020 - 2022 - amount]]), 0), _xlpm.production_amount/(_xlpm.production_amount+_xlpm.import_amount)) -> 0.76664801 | AK13: Bio-based
A14: A | B14: 20163010 | C14: Polyvinyl chloride, not mixed with any other substances, in primary forms | D14: 4953910010 | E14: KG | F14: 1425967650 | G14: KG | H14: 504513532 | I14: KG | J14: 4470793569 | K14: KG | L14: 1060607262 | M14: KG | N14: 537253899 | O14: KG | P14: 1145155600 | Q14: KG | R14: 839037800 | S14: KG | T14: 189717600 | U14: KG | V14: 945577326 | W14: KG | X14: 673218633 | Y14: KG | Z14: 192712821 | AA14: KG | AB14: =_xlfn.LET(_xlpm.production_amount, VALUE(prodcom_data[[#This Row],[PRODQNT - EU27_2020 - 2019 - amount]]), IF(ISNUMBER(_xlpm.production_amount), _xlpm.production_amount, 0))+_xlfn.LET(_xlpm.import_amount, VALUE(prodcom_data[[#This Row],[IMPQNT - EU27_2020 - 2019 - amount]]), IF(ISNUMBER(_xlpm.import_amount), _xlpm.import_amount, 0)) -> 5458423542 | AC14: =IF(NOT(AND(ISNUMBER(VALUE(prodcom_data[[#This Row],[PRODQNT - EU27_2020 - 2019 - amount]])), ISNUMBER(VALUE(prodcom_data[[#This Row],[IMPQNT - EU27_2020 - 2019 - amount]])))), "secrets", "") | AD14: =_xlfn.LET(_xlpm.production_amount, VALUE(prodcom_data[[#This Row],[PRODQNT - EU27_2020 - 2022 - amount]]), IF(ISNUMBER(_xlpm.production_amount), _xlpm.production_amount, 0))+_xlfn.LET(_xlpm.import_amount, VALUE(prodcom_data[[#This Row],[IMPQNT - EU27_2020 - 2022 - amount]]), IF(ISNUMBER(_xlpm.import_amount), _xlpm.import_amount, 0)) -> 5008047468 | AE14: =IF(NOT(AND(ISNUMBER(VALUE(prodcom_data[[#This Row],[PRODQNT - EU27_2020 - 2022 - amount]])), ISNUMBER(VALUE(prodcom_data[[#This Row],[IMPQNT - EU27_2020 - 2022 - amount]])))), "secrets", "") | AF14: =_xlfn.LET(_xlpm.production_amount, VALUE(prodcom_data[[#This Row],[PRODQNT - FR - 2019 - amount]]), IF(ISNUMBER(_xlpm.production_amount), _xlpm.production_amount, 0))+_xlfn.LET(_xlpm.import_amount, VALUE(prodcom_data[[#This Row],[IMPQNT - FR - 2019 - amount]]), IF(ISNUMBER(_xlpm.import_amount), _xlpm.import_amount, 0)) -> 1334873200 | AG14: =IF(NOT(AND(ISNUMBER(VALUE(prodcom_data[[#This Row],[PRODQNT - FR - 2019 - amount]])), ISNUMBER(VALUE(prodcom_data[[#This Row],[IMPQNT - FR - 2019 - amount]])))), "secrets", "") | AH14: =_xlfn.LET(_xlpm.production_amount, VALUE(prodcom_data[[#This Row],[PRODQNT - FR - 2022 - amount]]), IF(ISNUMBER(_xlpm.production_amount), _xlpm.production_amount, 0))+_xlfn.LET(_xlpm.import_amount, VALUE(prodcom_data[[#This Row],[IMPQNT - FR - 2022 - amount]]), IF(ISNUMBER(_xlpm.import_amount), _xlpm.import_amount, 0)) -> 1138290147 | AI14: =IF(NOT(AND(ISNUMBER(VALUE(prodcom_data[[#This Row],[PRODQNT - FR - 2022 - amount]])), ISNUMBER(VALUE(prodcom_data[[#This Row],[IMPQNT - FR - 2022 - amount]])))), "secrets", "") | AJ14: =_xlfn.LET(_xlpm.production_amount, IF(ISNUMBER(VALUE(prodcom_data[[#This Row],[PRODQNT - EU27_2020 - 2022 - amount]])),VALUE(prodcom_data[[#This Row],[PRODQNT - EU27_2020 - 2022 - amount]]), 0), _xlpm.import_amount, IF(ISNUMBER(VALUE(prodcom_data[[#This Row],[IMPQNT - EU27_2020 - 2022 - amount]])), VALUE(prodcom_data[[#This Row],[IMPQNT - EU27_2020 - 2022 - amount]]), 0), _xlpm.production_amount/(_xlpm.production_amount+_xlpm.import_amount)) -> 0.89272188
A15: A | B15: 20161039 | C15: Polyethylene having a specific gravity < 0,94, in primary forms (excluding linear) | D15: 3804711583 | E15: KG | F15: 935132814 | G15: KG | H15: 846552896 | I15: KG | J15: 3561952039 | K15: KG | L15: 870209572 | M15: KG | N15: 912261837 | O15: KG | P15: 465074009 | Q15: KG | R15: 336705400 | S15: KG | T15: 397749900 | U15: KG | V15: : | W15: KG | X15: 198057025 | Y15: KG | Z15: 380096125 | AA15: KG | AB15: =_xlfn.LET(_xlpm.production_amount, VALUE(prodcom_data[[#This Row],[PRODQNT - EU27_2020 - 2019 - amount]]), IF(ISNUMBER(_xlpm.production_amount), _xlpm.production_amount, 0))+_xlfn.LET(_xlpm.import_amount, VALUE(prodcom_data[[#This Row],[IMPQNT - EU27_2020 - 2019 - amount]]), IF(ISNUMBER(_xlpm.import_amount), _xlpm.import_amount, 0)) -> 4651264479 | AC15: =IF(NOT(AND(ISNUMBER(VALUE(prodcom_data[[#This Row],[PRODQNT - EU27_2020 - 2019 - amount]])), ISNUMBER(VALUE(prodcom_data[[#This Row],[IMPQNT - EU27_2020 - 2019 - amount]])))), "secrets", "") | AD15: =_xlfn.LET(_xlpm.production_amount, VALUE(prodcom_data[[#This Row],[PRODQNT - EU27_2020 - 2022 - amount]]), IF(ISNUMBER(_xlpm.production_amount), _xlpm.production_amount, 0))+_xlfn.LET(_xlpm.import_amount, VALUE(prodcom_data[[#This Row],[IMPQNT - EU27_2020 - 2022 - amount]]), IF(ISNUMBER(_xlpm.import_amount), _xlpm.import_amount, 0)) -> 4474213876 | AE15: =IF(NOT(AND(ISNUMBER(VALUE(prodcom_data[[#This Row],[PRODQNT - EU27_2020 - 2022 - amount]])), ISNUMBER(VALUE(prodcom_data[[#This Row],[IMPQNT - EU27_2020 - 2022 - amount]])))), "secrets", "") | AF15: =_xlfn.LET(_xlpm.production_amount, VALUE(prodcom_data[[#This Row],[PRODQNT - FR - 2019 - amount]]), IF(ISNUMBER(_xlpm.production_amount), _xlpm.production_amount, 0))+_xlfn.LET(_xlpm.import_amount, VALUE(prodcom_data[[#This Row],[IMPQNT - FR - 2019 - amount]]), IF(ISNUMBER(_xlpm.import_amount), _xlpm.import_amount, 0)) -> 862823909 | AG15: =IF(NOT(AND(ISNUMBER(VALUE(prodcom_data[[#This Row],[PRODQNT - FR - 2019 - amount]])), ISNUMBER(VALUE(prodcom_data[[#This Row],[IMPQNT - FR - 2019 - amount]])))), "secrets", "") | AH15: =_xlfn.LET(_xlpm.production_amount, VALUE(prodcom_data[[#This Row],[PRODQNT - FR - 2022 - amount]]), IF(ISNUMBER(_xlpm.production_amount), _xlpm.production_amount, 0))+_xlfn.LET(_xlpm.import_amount, VALUE(prodcom_data[[#This Row],[IMPQNT - FR - 2022 - amount]]), IF(ISNUMBER(_xlpm.import_amount), _xlpm.import_amount, 0)) -> 380096125 | AI15: =IF(NOT(AND(ISNUMBER(VALUE(prodcom_data[[#This Row],[PRODQNT - FR - 2022 - amount]])), ISNUMBER(VALUE(prodcom_data[[#This Row],[IMPQNT - FR - 2022 - amount]])))), "secrets", "") -> secrets | AJ15: =_xlfn.LET(_xlpm.production_amount, IF(ISNUMBER(VALUE(prodcom_data[[#This Row],[PRODQNT - EU27_2020 - 2022 - amount]])),VALUE(prodcom_data[[#This Row],[PRODQNT - EU27_2020 - 2022 - amount]]), 0), _xlpm.import_amount, IF(ISNUMBER(VALUE(prodcom_data[[#This Row],[IMPQNT - EU27_2020 - 2022 - amount]])), VALUE(prodcom_data[[#This Row],[IMPQNT - EU27_2020 - 2022 - amount]]), 0), _xlpm.production_amount/(_xlpm.production_amount+_xlpm.import_amount)) -> 0.79610679
A16: A | B16: 20165390 | C16: Acrylic polymers, in primary forms (excluding polymethyl methacrylate) | D16: 3338385824 | E16: KG | F16: 1068009737 | G16: KG | H16: 426646178 | I16: KG | J16: 4000794976 | K16: KG | L16: 945648319 | M16: KG | N16: 471446900 | O16: KG | P16: 665115053 | Q16: KG | R16: 693817200 | S16: KG | T16: 259707700 | U16: KG | V16: 783387358 | W16: KG | X16: 678085987 | Y16: KG | Z16: 286964711 | AA16: KG | AB16: =_xlfn.LET(_xlpm.production_amount, VALUE(prodcom_data[[#This Row],[PRODQNT - EU27_2020 - 2019 - amount]]), IF(ISNUMBER(_xlpm.production_amount), _xlpm.production_amount, 0))+_xlfn.LET(_xlpm.import_amount, VALUE(prodcom_data[[#This Row],[IMPQNT - EU27_2020 - 2019 - amount]]), IF(ISNUMBER(_xlpm.import_amount), _xlpm.import_amount, 0)) -> 3765032002 | AC16: =IF(NOT(AND(ISNUMBER(VALUE(prodcom_data[[#This Row],[PRODQNT - EU27_2020 - 2019 - amount]])), ISNUMBER(VALUE(prodcom_data[[#This Row],[IMPQNT - EU27_2020 - 2019 - amount]])))), "secrets", "") | AD16: =_xlfn.LET(_xlpm.production_amount, VALUE(prodcom_data[[#This Row],[PRODQNT - EU27_2020 - 2022 - amount]]), IF(ISNUMBER(_xlpm.production_amount), _xlpm.production_amount, 0))+_xlfn.LET(_xlpm.import_amount, VALUE(prodcom_data[[#This Row],[IMPQNT - EU27_2020 - 2022 - amount]]), IF(ISNUMBER(_xlpm.import_amount), _xlpm.import_amount, 0)) -> 4472241876 | AE16: =IF(NOT(AND(ISNUMBER(VALUE(prodcom_data[[#This Row],[PRODQNT - EU27_2020 - 2022 - amount]])), ISNUMBER(VALUE(prodcom_data[[#This Row],[IMPQNT - EU27_2020 - 2022 - amount]])))), "secrets", "") | AF16: =_xlfn.LET(_xlpm.production_amount, VALUE(prodcom_data[[#This Row],[PRODQNT - FR - 2019 - amount]]), IF(ISNUMBER(_xlpm.production_amount), _xlpm.production_amount, 0))+_xlfn.LET(_xlpm.import_amount, VALUE(prodcom_data[[#This Row],[IMPQNT - FR - 2019 - amount]]), IF(ISNUMBER(_xlpm.import_amount), _xlpm.import_amount, 0)) -> 924822753 | AG16: =IF(NOT(AND(ISNUMBER(VALUE(prodcom_data[[#This Row],[PRODQNT - FR - 2019 - amount]])), ISNUMBER(VALUE(prodcom_data[[#This Row],[IMPQNT - FR - 2019 - amount]])))), "secrets", "") | AH16: =_xlfn.LET(_xlpm.production_amount, VALUE(prodcom_data[[#This Row],[PRODQNT - FR - 2022 - amount]]), IF(ISNUMBER(_xlpm.production_amount), _xlpm.production_amount, 0))+_xlfn.LET(_xlpm.import_amount, VALUE(prodcom_data[[#This Row],[IMPQNT - FR - 2022 - amount]]), IF(ISNUMBER(_xlpm.import_amount), _xlpm.import_amount, 0)) -> 1070352069 | AI16: =IF(NOT(AND(ISNUMBER(VALUE(prodcom_data[[#This Row],[PRODQNT - FR - 2022 - amount]])), ISNUMBER(VALUE(prodcom_data[[#This Row],[IMPQNT - FR - 2022 - amount]])))), "secrets", "") | AJ16: =_xlfn.LET(_xlpm.production_amount, IF(ISNUMBER(VALUE(prodcom_data[[#This Row],[PRODQNT - EU27_2020 - 2022 - amount]])),VALUE(prodcom_data[[#This Row],[PRODQNT - EU27_2020 - 2022 - amount]]), 0), _xlpm.import_amount, IF(ISNUMBER(VALUE(prodcom_data[[#This Row],[IMPQNT - EU27_2020 - 2022 - amount]])), VALUE(prodcom_data[[#This Row],[IMPQNT - EU27_2020 - 2022 - amount]]), 0), _xlpm.production_amount/(_xlpm.production_amount+_xlpm.import_amount)) -> 0.89458377 | AK16: Too broad
A17: A | B17: 20161035 | C17: Linear polyethylene having a specific gravity < 0,94, in primary forms | D17: 1839610198 | E17: KG | F17: 318193075 | G17: KG | H17: 791305255 | I17: KG | J17: 3486497998 | K17: KG | L17: 199640883 | M17: KG | N17: 752212055 | O17: KG | P17: 777417367 | Q17: KG | R17: 199769400 | S17: KG | T17: 182774100 | U17: KG | V17: 791249287 | W17: KG | X17: 146735786 | Y17: KG | Z17: 173773205 | AA17: KG | AB17: =_xlfn.LET(_xlpm.production_amount, VALUE(prodcom_data[[#This Row],[PRODQNT - EU27_2020 - 2019 - amount]]), IF(ISNUMBER(_xlpm.production_amount), _xlpm.production_amount, 0))+_xlfn.LET(_xlpm.import_amount, VALUE(prodcom_data[[#This Row],[IMPQNT - EU27_2020 - 2019 - amount]]), IF(ISNUMBER(_xlpm.import_amount), _xlpm.import_amount, 0)) -> 2630915453 | AC17: =IF(NOT(AND(ISNUMBER(VALUE(prodcom_data[[#This Row],[PRODQNT - EU27_2020 - 2019 - amount]])), ISNUMBER(VALUE(prodcom_data[[#This Row],[IMPQNT - EU27_2020 - 2019 - amount]])))), "secrets", "") | AD17: =_xlfn.LET(_xlpm.production_amount, VALUE(prodcom_data[[#This Row],[PRODQNT - EU27_2020 - 2022 - amount]]), IF(ISNUMBER(_xlpm.production_amount), _xlpm.production_amount, 0))+_xlfn.LET(_xlpm.import_amount, VALUE(prodcom_data[[#This Row],[IMPQNT - EU27_2020 - 2022 - amount]]), IF(ISNUMBER(_xlpm.import_amount), _xlpm.import_amount, 0)) -> 4238710053 | AE17: =IF(NOT(AND(ISNUMBER(VALUE(prodcom_data[[#This Row],[PRODQNT - EU27_2020 - 2022 - amount]])), ISNUMBER(VALUE(prodcom_data[[#This Row],[IMPQNT - EU27_2020 - 2022 - amount]])))), "secrets", "") | AF17: =_xlfn.LET(_xlpm.production_amount, VALUE(prodcom_data[[#This Row],[PRODQNT - FR - 2019 - amount]]), IF(ISNUMBER(_xlpm.production_amount), _xlpm.production_amount, 0))+_xlfn.LET(_xlpm.import_amount, VALUE(prodcom_data[[#This Row],[IMPQNT - FR - 2019 - amount]]), IF(ISNUMBER(_xlpm.import_amount), _xlpm.import_amount, 0)) -> 960191467 | AG17: =IF(NOT(AND(ISNUMBER(VALUE(prodcom_data[[#This Row],[PRODQNT - FR - 2019 - amount]])), ISNUMBER(VALUE(prodcom_data[[#This Row],[IMPQNT - FR - 2019 - amount]])))), "secrets", "") | AH17: =_xlfn.LET(_xlpm.production_amount, VALUE(prodcom_data[[#This Row],[PRODQNT - FR - 2022 - amount]]), IF(ISNUMBER(_xlpm.production_amount), _xlpm.production_amount, 0))+_xlfn.LET(_xlpm.import_amount, VALUE(prodcom_data[[#This Row],[IMPQNT - FR - 2022 - amount]]), IF(ISNUMBER(_xlpm.import_amount), _xlpm.import_amount, 0)) -> 965022492 | AI17: =IF(NOT(AND(ISNUMBER(VALUE(prodcom_data[[#This Row],[PRODQNT - FR - 2022 - amount]])), ISNUMBER(VALUE(prodcom_data[[#This Row],[IMPQNT - FR - 2022 - amount]])))), "secrets", "") | AJ17: =_xlfn.LET(_xlpm.production_amount, IF(ISNUMBER(VALUE(prodcom_data[[#This Row],[PRODQNT - EU27_2020 - 2022 - amount]])),VALUE(prodcom_data[[#This Row],[PRODQNT - EU27_2020 - 2022 - amount]]), 0), _xlpm.import_amount, IF(ISNUMBER(VALUE(prodcom_data[[#This Row],[IMPQNT - EU27_2020 - 2022 - amount]])), VALUE(prodcom_data[[#This Row],[IMPQNT - EU27_2020 - 2022 - amount]]), 0), _xlpm.production_amount/(_xlpm.production_amount+_xlpm.import_amount)) -> 0.82253751
A18: A | B18: 20141250 | C18: Styrene | D18: 2880904684 | E18: KG | F18: 592906998 | G18: KG | H18: 780445063 | I18: KG | J18: 3000000000 | K18: KG | L18: 319176496 | M18: KG | N18: 627976392 | O18: KG | P18: N/A | Q18: N/A | R18: 245663900 | S18: KG | T18: 314982100 | U18: KG | V18: N/A | W18: N/A | X18: 167106617 | Y18: KG | Z18: 242749901 | AA18: KG | AB18: =_xlfn.LET(_xlpm.production_amount, VALUE(prodcom_data[[#This Row],[PRODQNT - EU27_2020 - 2019 - amount]]), IF(ISNUMBER(_xlpm.production_amount), _xlpm.production_amount, 0))+_xlfn.LET(_xlpm.import_amount, VALUE(prodcom_data[[#This Row],[IMPQNT - EU27_2020 - 2019 - amount]]), IF(ISNUMBER(_xlpm.import_amount), _xlpm.import_amount, 0)) -> 3661349747 | AC18: =IF(NOT(AND(ISNUMBER(VALUE(prodcom_data[[#This Row],[PRODQNT - EU27_2020 - 2019 - amount]])), ISNUMBER(VALUE(prodcom_data[[#This Row],[IMPQNT - EU27_2020 - 2019 - amount]])))), "secrets", "") | AD18: =_xlfn.LET(_xlpm.production_amount, VALUE(prodcom_data[[#This Row],[PRODQNT - EU27_2020 - 2022 - amount]]), IF(ISNUMBER(_xlpm.production_amount), _xlpm.production_amount, 0))+_xlfn.LET(_xlpm.import_amount, VALUE(prodcom_data[[#This Row],[IMPQNT - EU27_2020 - 2022 - amount]]), IF(ISNUMBER(_xlpm.import_amount), _xlpm.import_amount, 0)) -> 3627976392 | AE18: =IF(NOT(AND(ISNUMBER(VALUE(prodcom_data[[#This Row],[PRODQNT - EU27_2020 - 2022 - amount]])), ISNUMBER(VALUE(prodcom_data[[#This Row],[IMPQNT - EU27_2020 - 2022 - amount]])))), "secrets", "") | AF18: =_xlfn.LET(_xlpm.production_amount, VALUE(prodcom_data[[#This Row],[PRODQNT - FR - 2019 - amount]]), IF(ISNUMBER(_xlpm.production_amount), _xlpm.production_amount, 0))+_xlfn.LET(_xlpm.import_amount, VALUE(prodcom_data[[#This Row],[IMPQNT - FR - 2019 - amount]]), IF(ISNUMBER(_xlpm.import_amount), _xlpm.import_amount, 0)) -> 314982100 | AG18: =IF(NOT(AND(ISNUMBER(VALUE(prodcom_data[[#This Row],[PRODQNT - FR - 2019 - amount]])), ISNUMBER(VALUE(prodcom_data[[#This Row],[IMPQNT - FR - 2019 - amount]])))), "secrets", "") -> secrets | AH18: =_xlfn.LET(_xlpm.production_amount, VALUE(prodcom_data[[#This Row],[PRODQNT - FR - 2022 - amount]]), IF(ISNUMBER(_xlpm.production_amount), _xlpm.production_amount, 0))+_xlfn.LET(_xlpm.import_amount, VALUE(prodcom_data[[#This Row],[IMPQNT - FR - 2022 - amount]]), IF(ISNUMBER(_xlpm.import_amount), _xlpm.import_amount, 0)) -> 242749901 | AI18: =IF(NOT(AND(ISNUMBER(VALUE(prodcom_data[[#This Row],[PRODQNT - FR - 2022 - amount]])), ISNUMBER(VALUE(prodcom_data[[#This Row],[IMPQNT - FR - 2022 - amount]])))), "secrets", "") -> secrets | AJ18: =_xlfn.LET(_xlpm.production_amount, IF(ISNUMBER(VALUE(prodcom_data[[#This Row],[PRODQNT - EU27_2020 - 2022 - amount]])),VALUE(prodcom_data[[#This Row],[PRODQNT - EU27_2020 - 2022 - amount]]), 0), _xlpm.import_amount, IF(ISNUMBER(VALUE(prodcom_data[[#This Row],[IMPQNT - EU27_2020 - 2022 - amount]])), VALUE(prodcom_data[[#This Row],[IMPQNT - EU27_2020 - 2022 - amount]]), 0), _xlpm.production_amount/(_xlpm.production_amount+_xlpm.import_amount)) -> 0.82690726
A19: A | B19: 20143430 | C19: Phthalic anhydride; terephthalic acid and its salts | D19: 3205054549 | E19: KG | F19: 1043592979 | G19: KG | H19: 786875190 | I19: KG | J19: 2800000000 | K19: KG | L19: 567296099 | M19: KG | N19: 691283735 | O19: KG | P19: 0 | Q19: KG | R19: 12200 | S19: KG | T19: 76134800 | U19: KG | V19: : | W19: KG | X19: 37355 | Y19: KG | Z19: 75268175 | AA19: KG | AB19: =_xlfn.LET(_xlpm.production_amount, VALUE(prodcom_data[[#This Row],[PRODQNT - EU27_2020 - 2019 - amount]]), IF(ISNUMBER(_xlpm.production_amount), _xlpm.production_amount, 0))+_xlfn.LET(_xlpm.import_amount, VALUE(prodcom_data[[#This Row],[IMPQNT - EU27_2020 - 2019 - amount]]), IF(ISNUMBER(_xlpm.import_amount), _xlpm.import_amount, 0)) -> 3991929739 | AC19: =IF(NOT(AND(ISNUMBER(VALUE(prodcom_data[[#This Row],[PRODQNT - EU27_2020 - 2019 - amount]])), ISNUMBER(VALUE(prodcom_data[[#This Row],[IMPQNT - EU27_2020 - 2019 - amount]])))), "secrets", "") | AD19: =_xlfn.LET(_xlpm.production_amount, VALUE(prodcom_data[[#This Row],[PRODQNT - EU27_2020 - 2022 - amount]]), IF(ISNUMBER(_xlpm.production_amount), _xlpm.production_amount, 0))+_xlfn.LET(_xlpm.import_amount, VALUE(prodcom_data[[#This Row],[IMPQNT - EU27_2020 - 2022 - amount]]), IF(ISNUMBER(_xlpm.import_amount), _xlpm.import_amount, 0)) -> 3491283735 | AE19: =IF(NOT(AND(ISNUMBER(VALUE(prodcom_data[[#This Row],[PRODQNT - EU27_2020 - 2022 - amount]])), ISNUMBER(VALUE(prodcom_data[[#This Row],[IMPQNT - EU27_2020 - 2022 - amount]])))), "secrets", "") | AF19: =_xlfn.LET(_xlpm.production_amount, VALUE(prodcom_data[[#This Row],[PRODQNT - FR - 2019 - amount]]), IF(ISNUMBER(_xlpm.production_amount), _xlpm.production_amount, 0))+_xlfn.LET(_xlpm.import_amount, VALUE(prodcom_data[[#This Row],[IMPQNT - FR - 2019 - amount]]), IF(ISNUMBER(_xlpm.import_amount), _xlpm.import_amount, 0)) -> 76134800 | AG19: =IF(NOT(AND(ISNUMBER(VALUE(prodcom_data[[#This Row],[PRODQNT - FR - 2019 - amount]])), ISNUMBER(VALUE(prodcom_data[[#This Row],[IMPQNT - FR - 2019 - amount]])))), "secrets", "") | AH19: =_xlfn.LET(_xlpm.production_amount, VALUE(prodcom_data[[#This Row],[PRODQNT - FR - 2022 - amount]]), IF(ISNUMBER(_xlpm.production_amount), _xlpm.production_amount, 0))+_xlfn.LET(_xlpm.import_amount, VALUE(prodcom_data[[#This Row],[IMPQNT - FR - 2022 - amount]]), IF(ISNUMBER(_xlpm.import_amount), _xlpm.import_amount, 0)) -> 75268175 | AI19: =IF(NOT(AND(ISNUMBER(VALUE(prodcom_data[[#This Row],[PRODQNT - FR - 2022 - amount]])), ISNUMBER(VALUE(prodcom_data[[#This Row],[IMPQNT - FR - 2022 - amount]])))), "secrets", "") -> secrets | AJ19: =_xlfn.LET(_xlpm.production_amount, IF(ISNUMBER(VALUE(prodcom_data[[#This Row],[PRODQNT - EU27_2020 - 2022 - amount]])),VALUE(prodcom_data[[#This Row],[PRODQNT - EU27_2020 - 2022 - amount]]), 0), _xlpm.import_amount, IF(ISNUMBER(VALUE(prodcom_data[[#This Row],[IMPQNT - EU27_2020 - 2022 - amount]])), VALUE(prodcom_data[[#This Row],[IMPQNT - EU27_2020 - 2022 - amount]]), 0), _xlpm.production_amount/(_xlpm.production_amount+_xlpm.import_amount)) -> 0.80199726
A20: A | B20: 20164062 | C20: Polyethylene terephthalate in primary forms having a viscosity number of >= 78 ml/g | D20: 2517574915 | E20: KG | F20: 267056705 | G20: KG | H20: 1091012060 | I20: KG | J20: 2200000000 | K20: KG | L20: 251477812 | M20: KG | N20: 1149184970 | O20: KG | P20: : | Q20: KG | R20: 31968300 | S20: KG | T20: 494229500 | U20: KG | V20: : | W20: KG | X20: 45776343 | Y20: KG | Z20: 399790693 | AA20: KG | AB20: =_xlfn.LET(_xlpm.production_amount, VALUE(prodcom_data[[#This Row],[PRODQNT - EU27_2020 - 2019 - amount]]), IF(ISNUMBER(_xlpm.production_amount), _xlpm.production_amount, 0))+_xlfn.LET(_xlpm.import_amount, VALUE(prodcom_data[[#This Row],[IMPQNT - EU27_2020 - 2019 - amount]]), IF(ISNUMBER(_xlpm.import_amount), _xlpm.import_amount, 0)) -> 3608586975 | AC20: =IF(NOT(AND(ISNUMBER(VALUE(prodcom_data[[#This Row],[PRODQNT - EU27_2020 - 2019 - amount]])), ISNUMBER(VALUE(prodcom_data[[#This Row],[IMPQNT - EU27_2020 - 2019 - amount]])))), "secrets", "") | AD20: =_xlfn.LET(_xlpm.production_amount, VALUE(prodcom_data[[#This Row],[PRODQNT - EU27_2020 - 2022 - amount]]), IF(ISNUMBER(_xlpm.production_amount), _xlpm.production_amount, 0))+_xlfn.LET(_xlpm.import_amount, VALUE(prodcom_data[[#This Row],[IMPQNT - EU27_2020 - 2022 - amount]]), IF(ISNUMBER(_xlpm.import_amount), _xlpm.import_amount, 0)) -> 3349184970 | AE20: =IF(NOT(AND(ISNUMBER(VALUE(prodcom_data[[#This Row],[PRODQNT - EU27_2020 - 2022 - amount]])), ISNUMBER(VALUE(prodcom_data[[#This Row],[IMPQNT - EU27_2020 - 2022 - amount]])))), "secrets", "") | AF20: =_xlfn.LET(_xlpm.production_amount, VALUE(prodcom_data[[#This Row],[PRODQNT - FR - 2019 - amount]]), IF(ISNUMBER(_xlpm.production_amount), _xlpm.production_amount, 0))+_xlfn.LET(_xlpm.import_amount, VALUE(prodcom_data[[#This Row],[IMPQNT - FR - 2019 - amount]]), IF(ISNUMBER(_xlpm.import_amount), _xlpm.import_amount, 0)) -> 494229500 | AG20: =IF(NOT(AND(ISNUMBER(VALUE(prodcom_data[[#This Row],[PRODQNT - FR - 2019 - amount]])), ISNUMBER(VALUE(prodcom_data[[#This Row],[IMPQNT - FR - 2019 - amount]])))), "secrets", "") -> secrets | AH20: =_xlfn.LET(_xlpm.production_amount, VALUE(prodcom_data[[#This Row],[PRODQNT - FR - 2022 - amount]]), IF(ISNUMBER(_xlpm.production_amount), _xlpm.production_amount, 0))+_xlfn.LET(_xlpm.import_amount, VALUE(prodcom_data[[#This Row],[IMPQNT - FR - 2022 - amount]]), IF(ISNUMBER(_xlpm.import_amount), _xlpm.import_amount, 0)) -> 399790693 | AI20: =IF(NOT(AND(ISNUMBER(VALUE(prodcom_data[[#This Row],[PRODQNT - FR - 2022 - amount]])), ISNUMBER(VALUE(prodcom_data[[#This Row],[IMPQNT - FR - 2022 - amount]])))), "secrets", "") -> secrets | AJ20: =_xlfn.LET(_xlpm.production_amount, IF(ISNUMBER(VALUE(prodcom_data[[#This Row],[PRODQNT - EU27_2020 - 2022 - amount]])),VALUE(prodcom_data[[#This Row],[PRODQNT - EU27_2020 - 2022 - amount]]), 0), _xlpm.import_amount, IF(ISNUMBER(VALUE(prodcom_data[[#This Row],[IMPQNT - EU27_2020 - 2022 - amount]])), VALUE(prodcom_data[[#This Row],[IMPQNT - EU27_2020 - 2022 - amount]]), 0), _xlpm.production_amount/(_xlpm.production_amount+_xlpm.import_amount)) -> 0.65687623
A21: A | B21: 20165550 | C21: Urea resins and thiourea resins, in primary forms | D21: 3271365258 | E21: KG | F21: 146978442 | G21: KG | H21: 102920747 | I21: KG | J21: 2827179444 | K21: KG | L21: 181699159 | M21: KG | N21: 142591005 | O21: KG | P21: : | Q21: KG | R21: 223800 | S21: KG | T21: 331218500 | U21: KG | V21: : | W21: KG | X21: 1293874 | Y21: KG | Z21: 207263216 | AA21: KG | AB21: =_xlfn.LET(_xlpm.production_amount, VALUE(prodcom_data[[#This Row],[PRODQNT - EU27_2020 - 2019 - amount]]), IF(ISNUMBER(_xlpm.production_amount), _xlpm.production_amount, 0))+_xlfn.LET(_xlpm.import_amount, VALUE(prodcom_data[[#This Row],[IMPQNT - EU27_2020 - 2019 - amount]]), IF(ISNUMBER(_xlpm.import_amount), _xlpm.import_amount, 0)) -> 3374286005 | AC21: =IF(NOT(AND(ISNUMBER(VALUE(prodcom_data[[#This Row],[PRODQNT - EU27_2020 - 2019 - amount]])), ISNUMBER(VALUE(prodcom_data[[#This Row],[IMPQNT - EU27_2020 - 2019 - amount]])))), "secrets", "") | AD21: =_xlfn.LET(_xlpm.production_amount, VALUE(prodcom_data[[#This Row],[PRODQNT - EU27_2020 - 2022 - amount]]), IF(ISNUMBER(_xlpm.production_amount), _xlpm.production_amount, 0))+_xlfn.LET(_xlpm.import_amount, VALUE(prodcom_data[[#This Row],[IMPQNT - EU27_2020 - 2022 - amount]]), IF(ISNUMBER(_xlpm.import_amount), _xlpm.import_amount, 0)) -> 2969770449 | AE21: =IF(NOT(AND(ISNUMBER(VALUE(prodcom_data[[#This Row],[PRODQNT - EU27_2020 - 2022 - amount]])), ISNUMBER(VALUE(prodcom_data[[#This Row],[IMPQNT - EU27_2020 - 2022 - amount]])))), "secrets", "") | AF21: =_xlfn.LET(_xlpm.production_amount, VALUE(prodcom_data[[#This Row],[PRODQNT - FR - 2019 - amount]]), IF(ISNUMBER(_xlpm.production_amount), _xlpm.production_amount, 0))+_xlfn.LET(_xlpm.import_amount, VALUE(prodcom_data[[#This Row],[IMPQNT - FR - 2019 - amount]]), IF(ISNUMBER(_xlpm.import_amount), _xlpm.import_amount, 0)) -> 331218500 | AG21: =IF(NOT(AND(ISNUMBER(VALUE(prodcom_data[[#This Row],[PRODQNT - FR - 2019 - amount]])), ISNUMBER(VALUE(prodcom_data[[#This Row],[IMPQNT - FR - 2019 - amount]])))), "secrets", "") -> secrets | AH21: =_xlfn.LET(_xlpm.production_amount, VALUE(prodcom_data[[#This Row],[PRODQNT - FR - 2022 - amount]]), IF(ISNUMBER(_xlpm.production_amount), _xlpm.production_amount, 0))+_xlfn.LET(_xlpm.import_amount, VALUE(prodcom_data[[#This Row],[IMPQNT - FR - 2022 - amount]]), IF(ISNUMBER(_xlpm.import_amount), _xlpm.import_amount, 0)) -> 207263216 | AI21: =IF(NOT(AND(ISNUMBER(VALUE(prodcom_data[[#This Row],[PRODQNT - FR - 2022 - amount]])), ISNUMBER(VALUE(prodcom_data[[#This Row],[IMPQNT - FR - 2022 - amount]])))), "secrets", "") -> secrets | AJ21: =_xlfn.LET(_xlpm.production_amount, IF(ISNUMBER(VALUE(prodcom_data[[#This Row],[PRODQNT - EU27_2020 - 2022 - amount]])),VALUE(prodcom_data[[#This Row],[PRODQNT - EU27_2020 - 2022 - amount]]), 0), _xlpm.import_amount, IF(ISNUMBER(VALUE(prodcom_data[[#This Row],[IMPQNT - EU27_2020 - 2022 - amount]])), VALUE(prodcom_data[[#This Row],[IMPQNT - EU27_2020 - 2022 - amount]]), 0), _xlpm.production_amount/(_xlpm.production_amount+_xlpm.import_amount)) -> 0.95198585 | AK21: Inorganic
