Workbook
Name _20260204___reorganized_annual_series: 'PRODCOM screening and matching'!$A$4:$M$239

Sheet README
B2: README sheet
B5: General information
B7: Main paper title | C7: Residual biomass to bio-based chemicals and plastics: ex-ante screening methodology for prioritizing high-impact substitutions
B8: Authors | C8: Nicolas LIENART, Thibaut LECOMPTE, Lorie HAMELIN
B9: Contact (Nicolas Lienart) | C9: nicolas.lienart@insa-toulouse.fr
B10: Contact (Thibaut Lecompte) | C10: thibaut.lecompte@univ-ubs.fr
B11: Contact (Lorie Hamelin) | C11: lorie.hamelin@insa-toulouse.fr
B12: Description | C12: This file is used to perform screening on the top most produced and imported products obtained from Prodcom data processing using the related Python notebook. LCI datasets are associated to the selected hotspots. The final output is a CSV file that can be processed by the environmental hotspot calculation Python notebook.
B13: Note | C13: This file is part of a set of supplementary materials. Please refer to the main manuscript and the accompanying document to find other materials and for a description of their usage.
B14: Git repository (Forge INRAE) | C14: https://forge.inrae.fr/nicolas.lienart/screen-lca-paper-supplementary-code
B15: Git repository (GitHub) | C15: https://github.com/nicolnt/screen-lca-paper-supplementary-code
B18: Updates
B20: Date | C20: Note
B21: 46146 | C21: Ready for submission
B24: Sheet structure
B26: Sheet name | C26: Description
B27: README | C27: This sheet. Contains meta information about this Excel file and its structure.
B28: PRODCOM screening and matching | C28: Imported data from the Prodcom Python notebook, calculations and screening.
B29: Calculations | C29: Contains data for for disaggregating isocyanates and polyamides, and some additional utils (atomic mass)
B30: Hotspots | C30: Extraction of Prodcom data, adjusted names, aggregated products and carbon content
B31: Export | C31: Export sheet to CSV for use in the hotspot calculation Python notebook.
B32: References | C32: Details of the bibliographic references used in this Excel file.
B35: Cell color nomenclature
B37: Style name | C37: Description | D37: Color | E37: Example 1 | F37: Example 2 | G37: Example 3
B38: Data Assumption | C38: Assumed data (no specific reference) | D38: pink background | E38: 15 | F38: 0.041154 | G38: 5.5855e-05
B39: Data Reference | C39: Data with reference (input) | D39: grey background | E39: 15 | F39: 0.041154 | G39: 5.5855e-05
B40: Formula | C40: Cell performing calculations using other cells | D40: blue | E40: 15 | F40: 0.041154 | G40: 5.5855e-05
B41: Data Linked Cell | C41: Cell refering to another, without transformation | D41: brown, italics | E41: 15 | F41: 0.041154 | G41: 5.5855e-05
B42: Text Reference | C42: Reference text | D42: small, grey, italic | E42: Bohers, 2024 - Com. Pers. | F42: (Muñoz and Weidema, 2024, p. 4) | G42: [2]
B43: Text Unit | C43: Unit | D43: small, centered | E43: kt.km | F43: MJ LHV/kg DM | G43: °C
B44: Text Formula | C44: Formula used in closeby cells (generally below), for history | D44: small, blue | E44: =90.9*37000000 | F44: =SUM(I14:I19)/J19
B45: No specific style | C45: Important cell, not being a note | D45: yellow background, no specific style (apply on top) | E45: 15 | F45: 0.041154 | G45: 5.5855e-05
B46: No specific style | C46: Emphasized cells (e.g., key intermediate or final results) | D46: bold, color depending on type | E46: 15 | F46: 0.041154 | G46: 5.5855e-05

Sheet PRODCOM screening and matching
C1: Imported file: | D1: output/reorganized annual_series.csv
M3: Formulas: | N3: =IF(ISNUMBER(E3), E3, 0)+IF(ISNUMBER(K3), K3, 0)
A4: freq | B4: reporter | C4: product | D4: product label | E4: PRODQNT value | F4: PRODQNT year | G4: PRODQNT unit | H4: EXPQNT value | I4: EXPQNT year | J4: EXPQNT unit | K4: IMPQNT value | L4: IMPQNT year | M4: IMPQNT unit | N4: PROD+IMP | O4: Conversion factor to kg | P4: PROD+IMP (kg) | Q4: In scope | R4: Ecoinvent 3.11 activity name proxy | S4: Note and references
A5: A | B5: EU27_2020 | C5: 20147390 | D5: Other oils and oil products, n.e.c. | E5: 6281510027 | F5: 2024 | G5: KG | H5: 21755270186 | I5: 2024 | J5: KG | K5: 6686056032 | L5: 2024 | M5: KG | N5: =IF(ISNUMBER(E5), E5, 0)+IF(ISNUMBER(K5), K5, 0) -> 12967566059 | O5: 1 | P5: =N5*O5 -> 12967566059 | Q5: Too broad
A6: A | B6: EU27_2020 | C6: 20165130 | D6: Polypropylene, in primary forms | E6: 9018125838 | F6: 2024 | G6: KG | H6: 804486358 | I6: 2024 | J6: KG | K6: 1420773663 | L6: 2024 | M6: KG | N6: =IF(ISNUMBER(E6), E6, 0)+IF(ISNUMBER(K6), K6, 0) -> 10438899501 | O6: 1 | P6: =N6*O6 -> 10438899501 | R6: market for polypropylene, granulate
A7: A | B7: EU27_2020 | C7: 20165150 | D7: Polymers of propylene or of other olefins, in primary forms (excluding polypropylene) | E7: 2056138729 | F7: 2024 | G7: KG | H7: 1087580681 | I7: 2024 | J7: KG | K7: 679794621 | L7: 2024 | M7: KG | N7: =IF(ISNUMBER(E7), E7, 0)+IF(ISNUMBER(K7), K7, 0) -> 2735933350 | O7: 1 | P7: =N7*O7 -> 2735933350 | Q7: Too broad | R7: market for polypropylene, granulate
A8: A | B8: EU27_2020 | C8: 20147340 | D8: Naphthalene and other aromatic hydrocarbon mixtures (excluding benzene, toluene, xylene) | E8: 4200000000 | F8: 2024 | G8: KG | H8: 1042009420 | I8: 2024 | J8: KG | K8: 1685389468 | L8: 2024 | M8: KG | N8: =IF(ISNUMBER(E8), E8, 0)+IF(ISNUMBER(K8), K8, 0) -> 5885389468 | O8: 1 | P8: =N8*O8 -> 5885389468 | Q8: Too broad
A9: A | B9: EU27_2020 | C9: 20141140 | D9: Propene (propylene) | E9: 9154997559 | F9: 2024 | G9: KG | H9: 151507551 | I9: 2024 | J9: KG | K9: 225368724 | L9: 2024 | M9: KG | N9: =IF(ISNUMBER(E9), E9, 0)+IF(ISNUMBER(K9), K9, 0) -> 9380366283 | O9: 1 | P9: =N9*O9 -> 9380366283 | R9: market for propylene
A10: A | B10: EU27_2020 | C10: 20141130 | D10: Ethylene | E10: 8082262489 | F10: 2024 | G10: KG | H10: 7255001 | I10: 2024 | J10: KG | K10: 1162202519 | L10: 2024 | M10: KG | N10: =IF(ISNUMBER(E10), E10, 0)+IF(ISNUMBER(K10), K10, 0) -> 9244465008 | O10: 1 | P10: =N10*O10 -> 9244465008 | R10: market for ethylene
A11: A | B11: EU27_2020 | C11: 20161090 | D11: Polymers of ethylene, in primary forms (excluding polyethylene, ethylene-vinyl acetate copolymers) | E11: 1054762109 | F11: 2024 | G11: KG | H11: 935329057 | I11: 2024 | J11: KG | K11: 1537639634 | L11: 2024 | M11: KG | N11: =IF(ISNUMBER(E11), E11, 0)+IF(ISNUMBER(K11), K11, 0) -> 2592401743 | O11: 1 | P11: =N11*O11 -> 2592401743 | Q11: Too broad | R11: market for polyethylene, low density, granulate
A12: A | B12: EU27_2020 | C12: 20161050 | D12: Polyethylene having a specific gravity of >= 0,94, in primary forms | E12: 5507260631 | F12: 2024 | G12: KG | H12: 951456319 | I12: 2024 | J12: KG | K12: 1702406546 | L12: 2024 | M12: KG | N12: =IF(ISNUMBER(E12), E12, 0)+IF(ISNUMBER(K12), K12, 0) -> 7209667177 | O12: 1 | P12: =N12*O12 -> 7209667177 | R12: market for polyethylene, high density, granulate
A13: A | B13: EU27_2020 | C13: 20165390 | D13: Acrylic polymers, in primary forms (excluding polymethyl methacrylate) | E13: 3784589489 | F13: 2024 | G13: KG | H13: 802904999 | I13: 2024 | J13: KG | K13: 443280701 | L13: 2024 | M13: KG | N13: =IF(ISNUMBER(E13), E13, 0)+IF(ISNUMBER(K13), K13, 0) -> 4227870190 | O13: 1 | P13: =N13*O13 -> 4227870190 | Q13: Too broad | R13: market for butyl acrylate
A14: A | B14: EU27_2020 | C14: 20165630 | D14: Amino resins, in primary forms (excluding urea and thiourea resins, melamine resins) | E14: 1521228629 | F14: 2024 | G14: KG | H14: 720236690 | I14: 2024 | J14: KG | K14: 214039250 | L14: 2024 | M14: KG | N14: =IF(ISNUMBER(E14), E14, 0)+IF(ISNUMBER(K14), K14, 0) -> 1735267879 | O14: 1 | P14: =N14*O14 -> 1735267879 | Q14: Too broad
A15: A | B15: EU27_2020 | C15: 20146310 | D15: Acyclic ethers and their halogenated, sulphonated, nitrated or nitrosated derivatives | E15: 1800000000 | F15: 2024 | G15: KG | H15: 503736982 | I15: 2024 | J15: KG | K15: 848579596 | L15: 2024 | M15: KG | N15: =IF(ISNUMBER(E15), E15, 0)+IF(ISNUMBER(K15), K15, 0) -> 2648579596 | O15: 1 | P15: =N15*O15 -> 2648579596 | Q15: Too broad
A16: A | B16: EU27_2020 | C16: 20164015 | D16: Polyethylene glycols and other polyether alcohols, in primary forms | E16: 1236618667 | F16: 2024 | G16: KG | H16: 496608245 | I16: 2024 | J16: KG | K16: 277527064 | L16: 2024 | M16: KG | N16: =IF(ISNUMBER(E16), E16, 0)+IF(ISNUMBER(K16), K16, 0) -> 1514145731 | O16: 1 | P16: =N16*O16 -> 1514145731 | Q16: Too broad | R16: market for polyether polyols, short chain
A17: A | B17: EU27_2020 | C17: 20142210 | D17: Methanol (methyl alcohol) | E17: 800000000 | F17: 2024 | G17: KG | H17: 427422136 | I17: 2024 | J17: KG | K17: 6323081145 | L17: 2024 | M17: KG | N17: =IF(ISNUMBER(E17), E17, 0)+IF(ISNUMBER(K17), K17, 0) -> 7123081145 | O17: 1 | P17: =N17*O17 -> 7123081145 | R17: market for methanol
A18: A | B18: EU27_2020 | C18: 20165670 | D18: Polyurethanes, in primary forms | E18: 2000000000 | F18: 2024 | G18: KG | H18: 399773869 | I18: 2024 | J18: KG | K18: 86849920 | L18: 2024 | M18: KG | N18: =IF(ISNUMBER(E18), E18, 0)+IF(ISNUMBER(K18), K18, 0) -> 2086849920 | O18: 1 | P18: =N18*O18 -> 2086849920 | Q18: Too broad | R18: market for polyurethane, rigid foam
A19: A | B19: EU27_2020 | C19: 20141223 | D19: Benzene | E19: 5459018446 | F19: 2024 | G19: KG | H19: 342450902 | I19: 2024 | J19: KG | K19: 531552505 | L19: 2024 | M19: KG | N19: =IF(ISNUMBER(E19), E19, 0)+IF(ISNUMBER(K19), K19, 0) -> 5990570951 | O19: 1 | P19: =N19*O19 -> 5990570951 | R19: market for benzene
A20: A | B20: EU27_2020 | C20: 20164090 | D20: Polyesters, in primary forms (excluding polyacetals, polyethers, epoxide resins, polycarbonates, alkyd resins, polyethylene terephthalate, other unsaturated polyesters) | E20: 1093364852 | F20: 2024 | G20: KG | H20: 346057837 | I20: 2024 | J20: KG | K20: 371444833 | L20: 2024 | M20: KG | N20: =IF(ISNUMBER(E20), E20, 0)+IF(ISNUMBER(K20), K20, 0) -> 1464809685 | O20: 1 | P20: =N20*O20 -> 1464809685 | Q20: Too broad | R20: market for polyester resin, unsaturated
A21: A | B21: EU27_2020 | C21: 20163010 | D21: Polyvinyl chloride, not mixed with any other substances, in primary forms | E21: 4431944772 | F21: 2024 | G21: KG | H21: 1200688249 | I21: 2024 | J21: KG | K21: 398464555 | L21: 2024 | M21: KG | N21: =IF(ISNUMBER(E21), E21, 0)+IF(ISNUMBER(K21), K21, 0) -> 4830409327 | O21: 1 | P21: =N21*O21 -> 4830409327 | R21: market for polyvinyl chloride, emulsion polymerised
A22: A | B22: EU27_2020 | C22: 20161039 | D22: Polyethylene having a specific gravity < 0,94, in primary forms (excluding linear) | E22: 3434283993 | F22: 2024 | G22: KG | H22: 938356558 | I22: 2024 | J22: KG | K22: 799356302 | L22: 2024 | M22: KG | N22: =IF(ISNUMBER(E22), E22, 0)+IF(ISNUMBER(K22), K22, 0) -> 4233640295 | O22: 1 | P22: =N22*O22 -> 4233640295 | R22: market for polyethylene, low density, granulate
A23: A | B23: EU27_2020 | C23: 20165940 | D23: Cellulose and its chemical derivatives, n.e.c., in primary forms | E23: 418243981 | F23: 2018 | G23: KG | H23: 294421605 | I23: 2018 | J23: KG | K23: 120427027 | L23: 2018 | M23: KG | N23: =IF(ISNUMBER(E23), E23, 0)+IF(ISNUMBER(K23), K23, 0) -> 538671008 | O23: 1 | P23: =N23*O23 -> 538671008 | Q23: Bio-based | R23: market for cellulose fibre
A24: A | B24: EU27_2020 | C24: 20147120 | D24: Activated natural mineral products; animal black | E24: 700000000 | F24: 2024 | G24: KG | H24: 292652074 | I24: 2024 | J24: KG | K24: 84363989 | L24: 2024 | M24: KG | N24: =IF(ISNUMBER(E24), E24, 0)+IF(ISNUMBER(K24), K24, 0) -> 784363989 | O24: 1 | P24: =N24*O24 -> 784363989 | Q24: Inorganic
A25: A | B25: EU27_2020 | C25: 20143420 | D25: Other esters of orthophthalic acid | E25: 526597998 | F25: 2024 | G25: KG | H25: 292253900 | I25: 2011 | J25: KG | K25: 34970700 | L25: 2011 | M25: KG | N25: =IF(ISNUMBER(E25), E25, 0)+IF(ISNUMBER(K25), K25, 0) -> 561568698 | O25: 1 | P25: =N25*O25 -> 561568698 | Q25: Too broad
A26: A | B26: EU27_2020 | C26: 20142265 | D26: Lauryl alcohol; cetyl alcohol; stearyl alcohol and other saturated monohydric alcohols (excluding methyl, propyl and isopropyl, n-butyl, other butanols, octyl) | E26: 400000000 | F26: 2024 | G26: KG | H26: 290427849 | I26: 2024 | J26: KG | K26: 67102694 | L26: 2024 | M26: KG | N26: =IF(ISNUMBER(E26), E26, 0)+IF(ISNUMBER(K26), K26, 0) -> 467102694 | O26: 1 | P26: =N26*O26 -> 467102694 | Q26: Too broad
A27: A | B27: EU27_2020 | C27: 20143430 | D27: Phthalic anhydride; terephthalic acid and its salts | E27: 3240000000 | F27: 2024 | G27: KG | H27: 216746591 | I27: 2024 | J27: KG | K27: 792953658 | L27: 2024 | M27: KG | N27: =IF(ISNUMBER(E27), E27, 0)+IF(ISNUMBER(K27), K27, 0) -> 4032953658 | O27: 1 | P27: =N27*O27 -> 4032953658 | R27: market for purified terephthalic acid | S27: Globally: >3.7 Mt phthalic anhydride production capacity in 1996 (Lorz et al., 2007) vs 81.6 Mt terephthalic acid in 2021 (Tomás et al., 2024). With no more recent trustworthy data, phthalic anhydride is assumed to be very small compared to terephthalic acid
A28: A | B28: EU27_2020 | C28: 20164062 | D28: Polyethylene terephthalate in primary forms having a viscosity number of >= 78 ml/g | E28: 2078527679 | F28: 2024 | G28: KG | H28: 281655452 | I28: 2024 | J28: KG | K28: 1230771387 | L28: 2024 | M28: KG | N28: =IF(ISNUMBER(E28), E28, 0)+IF(ISNUMBER(K28), K28, 0) -> 3309299066 | O28: 1 | P28: =N28*O28 -> 3309299066 | R28: market for polyethylene terephthalate, granulate, amorphous
A29: A | B29: EU27_2020 | C29: 20141250 | D29: Styrene | E29: 2340000000 | F29: 2024 | G29: KG | H29: 335102036 | I29: 2024 | J29: KG | K29: 652240374 | L29: 2024 | M29: KG | N29: =IF(ISNUMBER(E29), E29, 0)+IF(ISNUMBER(K29), K29, 0) -> 2992240374 | O29: 1 | P29: =N29*O29 -> 2992240374 | R29: market for styrene
A30: A | B30: EU27_2020 | C30: 20162090 | D30: Polymers of styrene, in primary forms (excluding polystyrene, styrene-acrylonitrile (SAN) copolymers, acrylonitrile-butadiene-styrene (ABS) copolymers) | E30: 657361341 | F30: 2024 | G30: KG | H30: 244324425 | I30: 2024 | J30: KG | K30: 74047298 | L30: 2024 | M30: KG | N30: =IF(ISNUMBER(E30), E30, 0)+IF(ISNUMBER(K30), K30, 0) -> 731408639 | O30: 1 | P30: =N30*O30 -> 731408639 | Q30: Too broad | R30: market for styrene
A31: A | B31: EU27_2020 | C31: 20161035 | D31: Linear polyethylene having a specific gravity < 0,94, in primary forms | E31: 2000580713 | F31: 2024 | G31: KG | H31: 173560950 | I31: 2024 | J31: KG | K31: 582711227 | L31: 2024 | M31: KG | N31: =IF(ISNUMBER(E31), E31, 0)+IF(ISNUMBER(K31), K31, 0) -> 2583291940 | O31: 1 | P31: =N31*O31 -> 2583291940 | R31: market for polyethylene, linear low density, granulate
A32: A | B32: EU27_2020 | C32: 20147400 | D32: Undenatured ethyl alcohol of an alcoholic strength by volume >= 80 % (important: excluding alcohol duty) | E32: 5000000000 | F32: 2024 | G32: L | H32: 291915847 | I32: 2024 | J32: L | K32: 1258625585 | L32: 2024 | M32: L | N32: =IF(ISNUMBER(E32), E32, 0)+IF(ISNUMBER(K32), K32, 0) -> 6258625585 | O32: 0.79 | P32: =N32*O32 -> 4.9443142e+09 | Q32: Bio-based | S32: Globally, 93 % of ethanol is produced by fermentation (Sheldon and Brady, 2022)
A33: A | B33: EU27_2020 | C33: 20165450 | D33: Polyamide -6, -11, -12, -6,6, -6,9, -6,10 or -6,12, in primary forms | E33: 2069358570 | F33: 2024 | G33: KG | H33: 357769008 | I33: 2024 | J33: KG | K33: 255501225 | L33: 2024 | M33: KG | N33: =IF(ISNUMBER(E33), E33, 0)+IF(ISNUMBER(K33), K33, 0) -> 2324859795 | O33: 1 | P33: =N33*O33 -> 2324859795 | S33: Split PA 6 and PA 66, with ratio built from 4 million tons for PA 6 and 3.4 million tons for PA 66 (Khedr, 2023)
A34: A | B34: EU27_2020 | C34: 20141160 | D34: Buta-1,3-diene and isoprene | E34: 2043943673 | F34: 2024 | G34: KG | H34: 85693377 | I34: 2024 | J34: KG | K34: 5603755 | L34: 2024 | M34: KG | N34: =IF(ISNUMBER(E34), E34, 0)+IF(ISNUMBER(K34), K34, 0) -> 2049547428 | O34: 1 | P34: =N34*O34 -> 2049547428 | R34: market for butadiene | S34: Globally: Isoprene production is supposed between 0.8 and 1.3 Mt (Kim et al., 2016; Aldridge et al., 2021) vs 10 Mt for butediene (Biddy et al., 2016)
A35: A | B35: EU27_2020 | C35: 20146339 | D35: Ether-alcohols and their halogenated, sulphonated, nitrated or nitrosated derivatives (excluding 2,2-Oxydiethanol) | E35: 440000000 | F35: 2024 | G35: KG | H35: 214951347 | I35: 2024 | J35: KG | K35: 97039544 | L35: 2024 | M35: KG | N35: =IF(ISNUMBER(E35), E35, 0)+IF(ISNUMBER(K35), K35, 0) -> 537039544 | O35: 1 | P35: =N35*O35 -> 537039544 | Q35: Too broad
A36: A | B36: EU27_2020 | C36: 20141165 | D36: Unsaturated acyclic hydrocarbons; buta-1.3-diene | E36: 2174651913 | F36: 2008 | G36: KG | H36: 209246900 | I36: 2008 | J36: KG | K36: 14293100 | L36: 2008 | M36: KG | N36: =IF(ISNUMBER(E36), E36, 0)+IF(ISNUMBER(K36), K36, 0) -> 2188945013 | O36: 1 | P36: =N36*O36 -> 2188945013 | Q36: Already covered
A37: A | B37: EU27_2020 | C37: 20141150 | D37: Butene (butylene) and isomers thereof | E37: 1800000000 | F37: 2024 | G37: KG | H37: 91343999 | I37: 2024 | J37: KG | K37: 76728 | L37: 2024 | M37: KG | N37: =IF(ISNUMBER(E37), E37, 0)+IF(ISNUMBER(K37), K37, 0) -> 1800076728 | O37: 1 | P37: =N37*O37 -> 1800076728 | R37: market for butene, mixed
A38: A | B38: EU27_2020 | C38: 20142263 | D38: Octanol (octyl alcohol) and isomers thereof | E38: 420000000 | F38: 2024 | G38: KG | H38: 188929951 | I38: 2024 | J38: KG | K38: 13982483 | L38: 2024 | M38: KG | N38: =IF(ISNUMBER(E38), E38, 0)+IF(ISNUMBER(K38), K38, 0) -> 433982483 | O38: 1 | P38: =N38*O38 -> 433982483 | Q38: Too broad
A39: A | B39: EU27_2020 | C39: 20165550 | D39: Urea resins and thiourea resins, in primary forms | E39: 2400000000 | F39: 2024 | G39: KG | H39: 185386522 | I39: 2024 | J39: KG | K39: 119966200 | L39: 2024 | M39: KG | N39: =IF(ISNUMBER(E39), E39, 0)+IF(ISNUMBER(K39), K39, 0) -> 2519966200 | O39: 1 | P39: =N39*O39 -> 2519966200 | Q39: Inorganic | R39: market for urea formaldehyde resin | S39: 53% of impact because of urea (Ecoinvent, 2024)
A40: A | B40: EU27_2020 | C40: 20165920 | D40: Petroleum resins, coumarone-indene resins, polyterpenes, polysulphides, polysulphones, etc., n.e.c., in primary forms | E40: 400000000 | F40: 2024 | G40: KG | H40: 184133999 | I40: 2024 | J40: KG | K40: 320187033 | L40: 2024 | M40: KG | N40: =IF(ISNUMBER(E40), E40, 0)+IF(ISNUMBER(K40), K40, 0) -> 720187033 | O40: 1 | P40: =N40*O40 -> 720187033 | Q40: Too broad
A41: A | B41: EU27_2020 | C41: 20143220 | D41: Mono-, di- or tri-chloroacetic acids; propionic, butanoic and pentanoic acids; their salts and esters | E41: 331121714 | F41: 2024 | G41: KG | H41: 182933222 | I41: 2024 | J41: KG | K41: 107058481 | L41: 2024 | M41: KG | N41: =IF(ISNUMBER(E41), E41, 0)+IF(ISNUMBER(K41), K41, 0) -> 438180195 | O41: 1 | P41: =N41*O41 -> 438180195 | Q41: Too broad
...

Sheet Calculations
B2: Polyamides
B4: Polyamide -6, -11, -12, -6,6, -6,9, -6,10 or -6,12, in primary forms | C4: ='PRODCOM screening and matching'!$P$33/1000000000 -> 2.3248598 | D4: Quantity (Mt)
B6: PA 6
B8: Caprolactam | C8: 1009 | D8: kg/t PA6 | E8: (Li, 2007, p. 136)
B9: Caprolactam | C9: =C8/1000 -> 1.009 | D9: kg/kg PA6
B10: Benzene | C10: 0.95 | D10: t/t Caprolactame | E10: (Hong and Xu, 2012, p. 105)
B11: Benzene | C11: =C10*C9 -> 0.95855 | D11: kg/kg PA6
B13: World Polyamide -6 production | C13: 4 | D13: Mt | E13: (Khedr, 2023)
B15: PA 66
B17: Adipic acid | C17: 646 | D17: kg/t PA66 | E17: (Li, 2007, p. 136)
B18: Hexamethylene diamine | C18: 513 | D18: kg/t PA66 | E18: (Li, 2007, p. 136)
B19: Adipic acid | C19: =C17/1000 -> 0.646 | D19: kg/kg PA66
B20: Hexamethylene diamine | C20: =C18/1000 -> 0.513 | D20: kg/kg PA66
B22: World Polyamide -6,6 production | C22: 3.4 | D22: Mt | E22: (Khedr, 2023)
B24: Isocyanates
B26: MDI production capacity | C26: 10 | D26: Mt | E26: (Richter et al., 2024)
B27: TDI production capacity | C27: 3 | D27: Mt | E27: (Richter et al., 2024)
B30: Isocyanates | C30: ='PRODCOM screening and matching'!$P$55/1000000000 -> 1.0275579 | D30: Quantity (Mt)
B32: Atomic mass
C34: Abridged standard atomic weight
B35: C | C35: 12.011 | D35: unified atomic mass | E35: (Prohaska et al., 2022, p. 582)
B36: O | C36: 15.999 | D36: unified atomic mass | E36: (Prohaska et al., 2022, p. 582)
B37: H | C37: 1.008 | D37: unified atomic mass | E37: (Prohaska et al., 2022, p. 581)

Sheet Hotspots
A1: Description | B1: The table below is an extraction of the table from the previous sheet, taking the top products in the list after screening and ecoinvent matching. Also polyamides and isocyanates were disaggregated below
D3: =INDEX('PRODCOM screening and matching'!$P$5:$P$1000, MATCH(A10, 'PRODCOM screening and matching'!$C$5:$C$1000, 0))/1000000000
A4: PRODCOM code | B4: Long name | C4: Figure name | D4: Quantity (Mt) | E4: Ecoinvent 3.11 activity name proxy | F4: Molecular formula (MF) | G4: Molecular weight (MW) | H4: Carbon atoms | I4: Carbon mass share | J4: MF and MW reference
A5: 20165130 | B5: Polypropylene, in primary forms | C5: Polypropylene | D5: =INDEX('PRODCOM screening and matching'!$P$5:$P$1000, MATCH(A5, 'PRODCOM screening and matching'!$C$5:$C$1000, 0))/1000000000 -> 10.4389 | E5: market for polypropylene, granulate | F5: (C3H6)x | G5: =3*Calculations!$C$35+6*Calculations!$C$37 -> 42.081 | H5: 3 | I5: =H5*Calculations!$C$35/G5 -> 0.85627718 | J5: Source : 26-03-2026 - https://pubchem.ncbi.nlm.nih.gov/compound/Polypropylene
A6: 20141140 | B6: Propene (propylene) | C6: Propylene | D6: =INDEX('PRODCOM screening and matching'!$P$5:$P$1000, MATCH(A6, 'PRODCOM screening and matching'!$C$5:$C$1000, 0))/1000000000 -> 9.3803663 | E6: market for propylene | F6: C3H6 | G6: 42.08 | H6: 3 | I6: =H6*Calculations!$C$35/G6 -> 0.85629753 | J6: Source : 26-03-2026 - https://pubchem.ncbi.nlm.nih.gov/compound/8252
A7: 20141130 | B7: Ethylene | C7: Ethylene | D7: =INDEX('PRODCOM screening and matching'!$P$5:$P$1000, MATCH(A7, 'PRODCOM screening and matching'!$C$5:$C$1000, 0))/1000000000 -> 9.244465 | E7: market for ethylene | F7: C2H4 | G7: 28.05 | H7: 2 | I7: =H7*Calculations!$C$35/G7 -> 0.85639929 | J7: Source : 26-03-2026 - https://pubchem.ncbi.nlm.nih.gov/compound/6325
A8: 20161050 | B8: Polyethylene having a specific gravity of >= 0,94, in primary forms | C8: Polyethylene | D8: =INDEX('PRODCOM screening and matching'!$P$5:$P$1000, MATCH(A8, 'PRODCOM screening and matching'!$C$5:$C$1000, 0))/1000000000 -> 7.2096672 | E8: market for polyethylene, high density, granulate | F8: (C2H4)n | G8: =2*Calculations!$C$35+4*Calculations!$C$37 -> 28.054 | H8: 2 | I8: =H8*Calculations!$C$35/G8 -> 0.85627718 | J8: Source : 26-03-2026 - https://pubchem.ncbi.nlm.nih.gov/compound/Polyethylene
A9: 20142210 | B9: Methanol (methyl alcohol) | C9: Methanol | D9: =INDEX('PRODCOM screening and matching'!$P$5:$P$1000, MATCH(A9, 'PRODCOM screening and matching'!$C$5:$C$1000, 0))/1000000000 -> 7.1230811 | E9: market for methanol | F9: CH4O | G9: 32.042 | H9: 1 | I9: =H9*Calculations!$C$35/G9 -> 0.37485176 | J9: Source : 26-03-2026 - https://pubchem.ncbi.nlm.nih.gov/compound/887
A10: 20141223 | B10: Benzene | C10: Benzene | D10: =INDEX('PRODCOM screening and matching'!$P$5:$P$1000, MATCH(A10, 'PRODCOM screening and matching'!$C$5:$C$1000, 0))/1000000000 -> 5.990571 | E10: market for benzene | F10: C6H6 | G10: 78.11 | H10: 6 | I10: =H10*Calculations!$C$35/G10 -> 0.92262194 | J10: Source : 26-03-2026 - https://pubchem.ncbi.nlm.nih.gov/compound/241
A11: 20163010 | B11: Polyvinyl chloride, not mixed with any other substances, in primary forms | C11: Polyvinyl chloride | D11: =INDEX('PRODCOM screening and matching'!$P$5:$P$1000, MATCH(A11, 'PRODCOM screening and matching'!$C$5:$C$1000, 0))/1000000000 -> 4.8304093 | E11: market for polyvinyl chloride, emulsion polymerised | F11: C2H3Cl | G11: 62.5 | H11: 2 | I11: =H11*Calculations!$C$35/G11 -> 0.384352 | J11: Source : 26-03-2026 - https://pubchem.ncbi.nlm.nih.gov/compound/6338
A12: 20161039 | B12: Polyethylene having a specific gravity < 0,94, in primary forms (excluding linear) | C12: Polyethylene | D12: =INDEX('PRODCOM screening and matching'!$P$5:$P$1000, MATCH(A12, 'PRODCOM screening and matching'!$C$5:$C$1000, 0))/1000000000 -> 4.2336403 | E12: market for polyethylene, low density, granulate | F12: (C2H4)n | G12: =2*Calculations!$C$35+4*Calculations!$C$37 -> 28.054 | H12: 2 | I12: =H12*Calculations!$C$35/G12 -> 0.85627718 | J12: Source : 26-03-2026 - https://pubchem.ncbi.nlm.nih.gov/compound/Polyethylene
A13: 20143430 | B13: Phthalic anhydride; terephthalic acid and its salts | C13: Terephthalic acid | D13: =INDEX('PRODCOM screening and matching'!$P$5:$P$1000, MATCH(A13, 'PRODCOM screening and matching'!$C$5:$C$1000, 0))/1000000000 -> 4.0329537 | E13: market for purified terephthalic acid | F13: C8H6O4 | G13: 166.13 | H13: 8 | I13: =H13*Calculations!$C$35/G13 -> 0.57839042 | J13: Source : 26-03-2026 - https://pubchem.ncbi.nlm.nih.gov/compound/7489
A14: 20164062 | B14: Polyethylene terephthalate in primary forms having a viscosity number of >= 78 ml/g | C14: Polyethylene terephthalate | D14: =INDEX('PRODCOM screening and matching'!$P$5:$P$1000, MATCH(A14, 'PRODCOM screening and matching'!$C$5:$C$1000, 0))/1000000000 -> 3.3092991 | E14: market for polyethylene terephthalate, granulate, amorphous | F14: C12H14O4 | G14: 222.24 | H14: 12 | I14: =H14*Calculations!$C$35/G14 -> 0.64854212 | J14: Source : 26-03-2026 - https://pubchem.ncbi.nlm.nih.gov/compound/18721140
A15: 20141250 | B15: Styrene | C15: Styrene | D15: =INDEX('PRODCOM screening and matching'!$P$5:$P$1000, MATCH(A15, 'PRODCOM screening and matching'!$C$5:$C$1000, 0))/1000000000 -> 2.9922404 | E15: market for styrene | F15: C8H8 | G15: 104.15 | H15: 8 | I15: =H15*Calculations!$C$35/G15 -> 0.92259241 | J15: Source : 26-03-2026 - https://pubchem.ncbi.nlm.nih.gov/compound/7501
A16: 20161035 | B16: Linear polyethylene having a specific gravity < 0,94, in primary forms | C16: Polyethylene | D16: =INDEX('PRODCOM screening and matching'!$P$5:$P$1000, MATCH(A16, 'PRODCOM screening and matching'!$C$5:$C$1000, 0))/1000000000 -> 2.5832919 | E16: market for polyethylene, linear low density, granulate | F16: (C2H4)n | G16: =2*Calculations!$C$35+4*Calculations!$C$37 -> 28.054 | H16: 2 | I16: =H16*Calculations!$C$35/G16 -> 0.85627718 | J16: Source : 26-03-2026 - https://pubchem.ncbi.nlm.nih.gov/compound/Polyethylene
A17: 20141160 | B17: Buta-1,3-diene and isoprene | C17: Butadiene | D17: =INDEX('PRODCOM screening and matching'!$P$5:$P$1000, MATCH(A17, 'PRODCOM screening and matching'!$C$5:$C$1000, 0))/1000000000 -> 2.0495474 | E17: market for butadiene | F17: C4H6 | G17: 54.09 | H17: 4 | I17: =H17*Calculations!$C$35/G17 -> 0.88822333 | J17: Source : 26-03-2026 - https://pubchem.ncbi.nlm.nih.gov/compound/7845
A18: 20141150 | B18: Butene (butylene) and isomers thereof | C18: Butylene | D18: =INDEX('PRODCOM screening and matching'!$P$5:$P$1000, MATCH(A18, 'PRODCOM screening and matching'!$C$5:$C$1000, 0))/1000000000 -> 1.8000767 | E18: market for butene, mixed | F18: C8H16 | G18: 112.21 | H18: 8 | I18: =H18*Calculations!$C$35/G18 -> 0.85632297 | J18: Source : 26-03-2026 - https://pubchem.ncbi.nlm.nih.gov/compound/6435908
A19: 20162039 | B19: Polystyrene, in primary forms (excluding expansible polystyrene) | C19: Polystyrene | D19: =INDEX('PRODCOM screening and matching'!$P$5:$P$1000, MATCH(A19, 'PRODCOM screening and matching'!$C$5:$C$1000, 0))/1000000000 -> 1.6494167 | E19: market for polystyrene, extruded | F19: (C8H8)x | G19: =8*Calculations!$C$35+8*Calculations!$C$37 -> 104.152 | H19: 8 | I19: =H19*Calculations!$C$35/G19 -> 0.9225747 | J19: Source : 26-03-2026 - https://pubchem.ncbi.nlm.nih.gov/compound/Polystyrene
A20: 20146375 | B20: Methyloxirane (propylene oxide) | C20: Propylene oxide | D20: =INDEX('PRODCOM screening and matching'!$P$5:$P$1000, MATCH(A20, 'PRODCOM screening and matching'!$C$5:$C$1000, 0))/1000000000 -> 1.5120548 | E20: market for propylene oxide, liquid | F20: C3H6O | G20: 58.08 | H20: 3 | I20: =H20*Calculations!$C$35/G20 -> 0.62040289 | J20: Source : 26-03-2026 - https://pubchem.ncbi.nlm.nih.gov/compound/6378
A21: 20142310 | B21: Ethylene glycol (ethanediol) | C21: Ethylene glycol | D21: =INDEX('PRODCOM screening and matching'!$P$5:$P$1000, MATCH(A21, 'PRODCOM screening and matching'!$C$5:$C$1000, 0))/1000000000 -> 1.4890492 | E21: market for ethylene glycol | F21: C2H6O2 | G21: 62.07 | H21: 2 | I21: =H21*Calculations!$C$35/G21 -> 0.38701466 | J21: Source : 26-03-2026 - https://pubchem.ncbi.nlm.nih.gov/compound/174
A22: 20162035 | B22: Expansible polystyrene, in primary forms | C22: Polystyrene | D22: =INDEX('PRODCOM screening and matching'!$P$5:$P$1000, MATCH(A22, 'PRODCOM screening and matching'!$C$5:$C$1000, 0))/1000000000 -> 1.4685235 | E22: market for polystyrene, expandable | F22: (C8H8)x | G22: =8*Calculations!$C$35+8*Calculations!$C$37 -> 104.152 | H22: 8 | I22: =H22*Calculations!$C$35/G22 -> 0.9225747 | J22: Source : 26-03-2026 - https://pubchem.ncbi.nlm.nih.gov/compound/Polystyrene
A23: 20165230 | B23: Polymers of vinyl acetate, in aqueous dispersion, in primary forms | C23: Polyvinyl acetate | D23: =INDEX('PRODCOM screening and matching'!$P$5:$P$1000, MATCH(A23, 'PRODCOM screening and matching'!$C$5:$C$1000, 0))/1000000000 -> 1.074468 | E23: market for vinyl acetate | F23: (C4H6O2)x | G23: =4*Calculations!$C$35+6*Calculations!$C$37+2*Calculations!$C$36 -> 86.09 | H23: 4 | I23: =H23*Calculations!$C$35/G23 -> 0.55806714 | J23: Source : 26-03-2026 - https://pubchem.ncbi.nlm.nih.gov/compound/Poly_vinyl-acetate
A24: 20146211 | B24: Acetone | C24: Acetone | D24: =INDEX('PRODCOM screening and matching'!$P$5:$P$1000, MATCH(A24, 'PRODCOM screening and matching'!$C$5:$C$1000, 0))/1000000000 -> 1.0377841 | E24: market for acetone, liquid | F24: C3H6O | G24: 58.08 | H24: 3 | I24: =H24*Calculations!$C$35/G24 -> 0.62040289 | J24: Source : 26-03-2026 - https://pubchem.ncbi.nlm.nih.gov/compound/180
A25: 20141353 | B25: 1,2-Dichloroethane (ethylene dichloride) | C25: Ethylene dichloride | D25: =INDEX('PRODCOM screening and matching'!$P$5:$P$1000, MATCH(A25, 'PRODCOM screening and matching'!$C$5:$C$1000, 0))/1000000000 -> 1.0187455 | E25: market for ethylene dichloride | F25: C2H4Cl2 | G25: 98.96 | H25: 2 | I25: =H25*Calculations!$C$35/G25 -> 0.24274454 | J25: Source : 26-03-2026 - https://pubchem.ncbi.nlm.nih.gov/compound/11
A26: 20141225 | B26: Toluene | C26: Toluene | D26: =INDEX('PRODCOM screening and matching'!$P$5:$P$1000, MATCH(A26, 'PRODCOM screening and matching'!$C$5:$C$1000, 0))/1000000000 -> 1.0064607 | E26: market for toluene, liquid | F26: C7H8 | G26: 92.14 | H26: 7 | I26: =H26*Calculations!$C$35/G26 -> 0.91249186 | J26: Source : 26-03-2026 - https://pubchem.ncbi.nlm.nih.gov/compound/1140
A27: 20144151 | B27: Aniline and its salts (excluding derivatives) | C27: Aniline | D27: =INDEX('PRODCOM screening and matching'!$P$5:$P$1000, MATCH(A27, 'PRODCOM screening and matching'!$C$5:$C$1000, 0))/1000000000 -> 0.9594972 | E27: market for aniline | F27: C6H7N | G27: 93.13 | H27: 6 | I27: =H27*Calculations!$C$35/G27 -> 0.77382154 | J27: Source : 26-03-2026 - https://pubchem.ncbi.nlm.nih.gov/compound/6115
A28: 20146111 | B28: Methanal (formaldehyde) | C28: Formaldehyde | D28: =INDEX('PRODCOM screening and matching'!$P$5:$P$1000, MATCH(A28, 'PRODCOM screening and matching'!$C$5:$C$1000, 0))/1000000000 -> 0.89854172 | E28: market for formaldehyde | F28: CH2O | G28: 30.026 | H28: 1 | I28: =H28*Calculations!$C$35/G28 -> 0.40001998 | J28: Source : 26-03-2026 - https://pubchem.ncbi.nlm.nih.gov/compound/712
A29: 20143271 | B29: Acetic acid | C29: Acetic acid | D29: =INDEX('PRODCOM screening and matching'!$P$5:$P$1000, MATCH(A29, 'PRODCOM screening and matching'!$C$5:$C$1000, 0))/1000000000 -> 0.88939678 | E29: market for acetic acid | F29: C2H4O2 | G29: 60.05 | H29: 2 | I29: =H29*Calculations!$C$35/G29 -> 0.40003331 | J29: Source : 26-03-2026 - https://pubchem.ncbi.nlm.nih.gov/compound/176
A30: 20162070 | B30: Acrylonitrile-butadiene-styrene (ABS) copolymers, in primary forms | C30: ABS | D30: =INDEX('PRODCOM screening and matching'!$P$5:$P$1000, MATCH(A30, 'PRODCOM screening and matching'!$C$5:$C$1000, 0))/1000000000 -> 0.81732564 | E30: market for acrylonitrile-butadiene-styrene copolymer | F30: C15H17N | G30: 211.3 | H30: 15 | I30: =H30*Calculations!$C$35/G30 -> 0.85265026 | J30: Source : 26-03-2026 - https://pubchem.ncbi.nlm.nih.gov/compound/24756
A31: 20141371 | B31: Vinyl chloride (chloroethylene) | C31: Vinyl chloride | D31: =INDEX('PRODCOM screening and matching'!$P$5:$P$1000, MATCH(A31, 'PRODCOM screening and matching'!$C$5:$C$1000, 0))/1000000000 -> 0.80778956 | E31: market for vinyl chloride | F31: C2H3Cl | G31: 62.5 | H31: 2 | I31: =H31*Calculations!$C$35/G31 -> 0.384352 | J31: Source : 26-03-2026 - https://pubchem.ncbi.nlm.nih.gov/compound/6338
A32: 20146373 | B32: Oxirane (ethylene oxide) | C32: Ethylene oxide | D32: =INDEX('PRODCOM screening and matching'!$P$5:$P$1000, MATCH(A32, 'PRODCOM screening and matching'!$C$5:$C$1000, 0))/1000000000 -> 0.80212793 | E32: market for ethylene oxide | F32: C2H4O | G32: 44.05 | H32: 2 | I32: =H32*Calculations!$C$35/G32 -> 0.54533485 | J32: Source : 26-03-2026 - https://pubchem.ncbi.nlm.nih.gov/compound/6354
A33: 20164064 | B33: Other polyethylene terephthalate in primary forms | C33: Polyethylene terephthalate | D33: =INDEX('PRODCOM screening and matching'!$P$5:$P$1000, MATCH(A33, 'PRODCOM screening and matching'!$C$5:$C$1000, 0))/1000000000 -> 0.78118323 | E33: market for polyethylene terephthalate, granulate, amorphous | F33: C12H14O4 | G33: 222.24 | H33: 12 | I33: =H33*Calculations!$C$35/G33 -> 0.64854212 | J33: Source : 26-03-2026 - https://pubchem.ncbi.nlm.nih.gov/compound/18721140
A34: 20163025 | B34: Plasticised polyvinyl chloride mixed with any other substance, in primary forms | C34: Polyvinyl chloride | D34: =INDEX('PRODCOM screening and matching'!$P$5:$P$1000, MATCH(A34, 'PRODCOM screening and matching'!$C$5:$C$1000, 0))/1000000000 -> 0.77995666 | E34: market for polyvinyl chloride, suspension polymerised | F34: C2H3Cl | G34: 62.5 | H34: 2 | I34: =H34*Calculations!$C$35/G34 -> 0.384352 | J34: Source : 26-03-2026 - https://pubchem.ncbi.nlm.nih.gov/compound/6338
A35: 20161070 | B35: Ethylene-vinyl acetate copolymers, in primary forms | C35: Ethylene-vinyl acetate | D35: =INDEX('PRODCOM screening and matching'!$P$5:$P$1000, MATCH(A35, 'PRODCOM screening and matching'!$C$5:$C$1000, 0))/1000000000 -> 0.67715198 | E35: market for ethylene vinyl acetate copolymer | F35: C6H10O2 | G35: 114.14 | H35: 6 | I35: =H35*Calculations!$C$35/G35 -> 0.63138251 | J35: Source : 26-03-2026 - https://pubchem.ncbi.nlm.nih.gov/compound/32742
... A50: 20146115 | B50: Butanal (butyraldehyde; normal isomer) | C50: Butanal | D50: =INDEX('PRODCOM screening and matching'!$P$5:$P$1000, MATCH(A50, 'PRODCOM screening and matching'!$C$5:$C$1000, 0))/1000000000 -> 0.3600118 | E50: market for n-butanol | F50: C4H8O | G50: 72.11 | H50: 4 | I50: =H50*Calculations!$C$35/G50 -> 0.66625988 | J50: Source : 26-03-2026 - https://pubchem.ncbi.nlm.nih.gov/compound/261
A51: 20164013 | B51: Polyacetals, in primary forms | C51: Polyoxymethylene | D51: =INDEX('PRODCOM screening and matching'!$P$5:$P$1000, MATCH(A51, 'PRODCOM screening and matching'!$C$5:$C$1000, 0))/1000000000 -> 0.35609375 | E51: manual:3.64 | F51: (CH2O)n | G51: =1*Calculations!$C$35+2*Calculations!$C$37+1*Calculations!$C$36 -> 30.026 | H51: 1 | I51: =H51*Calculations!$C$35/G51 -> 0.40001998 | J51: Source : 26-03-2026 - https://en.wikipedia.org/wiki/Polyoxymethylene
A52: 20143215 | B52: Ethyl acetate | C52: Ethyl acetate | D52: =INDEX('PRODCOM screening and matching'!$P$5:$P$1000, MATCH(A52, 'PRODCOM screening and matching'!$C$5:$C$1000, 0))/1000000000 -> 0.34131205 | E52: market for ethyl acetate | F52: C4H8O2 | G52: 88.11 | H52: 4 | I52: =H52*Calculations!$C$35/G52 -> 0.54527295 | J52: Source : 26-03-2026 - https://pubchem.ncbi.nlm.nih.gov/compound/8857
A53: 20146333 | B53: 2,2-Oxydiethanol (diethylene glycol; digol) | C53: Diethylene glycol | D53: =INDEX('PRODCOM screening and matching'!$P$5:$P$1000, MATCH(A53, 'PRODCOM screening and matching'!$C$5:$C$1000, 0))/1000000000 -> 0.32842485 | E53: market for diethylene glycol | F53: C4H10O3 | G53: 106.12 | H53: 4 | I53: =H53*Calculations!$C$35/G53 -> 0.45273276 | J53: Source : 26-03-2026 - https://pubchem.ncbi.nlm.nih.gov/compound/8117
A54: 20165250 | B54: Polymers of vinyl acetate, in primary forms (excluding in aqueous dispersion) | C54: Polyvinyl acetate | D54: =INDEX('PRODCOM screening and matching'!$P$5:$P$1000, MATCH(A54, 'PRODCOM screening and matching'!$C$5:$C$1000, 0))/1000000000 -> 0.32017296 | E54: market for vinyl acetate | F54: (C4H6O2)x | G54: 86.08905 | H54: 4 | I54: =H54*Calculations!$C$35/G54 -> 0.5580733 | J54: Source : 26-03-2026 - https://pubchem.ncbi.nlm.nih.gov/compound/Poly_vinyl-acetate
A55: 20141243 | B55: o-Xylene | C55: o-Xylene | D55: =INDEX('PRODCOM screening and matching'!$P$5:$P$1000, MATCH(A55, 'PRODCOM screening and matching'!$C$5:$C$1000, 0))/1000000000 -> 0.26076013 | E55: market for o-xylene | F55: C8H10 | G55: 106.16 | H55: 8 | I55: =H55*Calculations!$C$35/G55 -> 0.90512434 | J55: Source : 26-03-2026 - https://pubchem.ncbi.nlm.nih.gov/compound/7237
...

Sheet Export
A1: =Hotspots!A4 -> PRODCOM code | B1: =Hotspots!B4 -> Long name | C1: =Hotspots!C4 -> Figure name | D1: =Hotspots!D4 -> Quantity (Mt) | E1: =Hotspots!E4 -> Ecoinvent 3.11 activity name proxy | F1: =Hotspots!F4 -> Molecular formula (MF) | G1: =Hotspots!G4 -> Molecular weight (MW) | H1: =Hotspots!H4 -> Carbon atoms | I1: =Hotspots!I4 -> Carbon mass share
A2: =Hotspots!A5 -> 20165130 | B2: =Hotspots!B5 -> Polypropylene, in primary forms | C2: =Hotspots!C5 -> Polypropylene | D2: =Hotspots!D5 -> 10.4389 | E2: =Hotspots!E5 -> market for polypropylene, granulate | F2: =Hotspots!F5 -> (C3H6)x | G2: =Hotspots!G5 -> 42.081 | H2: =Hotspots!H5 -> 3 | I2: =Hotspots!I5 -> 0.85627718
A3: =Hotspots!A6 -> 20141140 | B3: =Hotspots!B6 -> Propene (propylene) | C3: =Hotspots!C6 -> Propylene | D3: =Hotspots!D6 -> 9.3803663 | E3: =Hotspots!E6 -> market for propylene | F3: =Hotspots!F6 -> C3H6 | G3: =Hotspots!G6 -> 42.08 | H3: =Hotspots!H6 -> 3 | I3: =Hotspots!I6 -> 0.85629753
A4: =Hotspots!A7 -> 20141130 | B4: =Hotspots!B7 -> Ethylene | C4: =Hotspots!C7 -> Ethylene | D4: =Hotspots!D7 -> 9.244465 | E4: =Hotspots!E7 -> market for ethylene | F4: =Hotspots!F7 -> C2H4 | G4: =Hotspots!G7 -> 28.05 | H4: =Hotspots!H7 -> 2 | I4: =Hotspots!I7 -> 0.85639929
A5: =Hotspots!A8 -> 20161050 | B5: =Hotspots!B8 -> Polyethylene having a specific gravity of >= 0,94, in primary forms | C5: =Hotspots!C8 -> Polyethylene | D5: =Hotspots!D8 -> 7.2096672 | E5: =Hotspots!E8 -> market for polyethylene, high density, granulate | F5: =Hotspots!F8 -> (C2H4)n | G5: =Hotspots!G8 -> 28.054 | H5: =Hotspots!H8 -> 2 | I5: =Hotspots!I8 -> 0.85627718
A6: =Hotspots!A9 -> 20142210 | B6: =Hotspots!B9 -> Methanol (methyl alcohol) | C6: =Hotspots!C9 -> Methanol | D6: =Hotspots!D9 -> 7.1230811 | E6: =Hotspots!E9 -> market for methanol | F6: =Hotspots!F9 -> CH4O | G6: =Hotspots!G9 -> 32.042 | H6: =Hotspots!H9 -> 1 | I6: =Hotspots!I9 -> 0.37485176
A7: =Hotspots!A10 -> 20141223 | B7: =Hotspots!B10 -> Benzene | C7: =Hotspots!C10 -> Benzene | D7: =Hotspots!D10 -> 5.990571 | E7: =Hotspots!E10 -> market for benzene | F7: =Hotspots!F10 -> C6H6 | G7: =Hotspots!G10 -> 78.11 | H7: =Hotspots!H10 -> 6 | I7: =Hotspots!I10 -> 0.92262194
A8: =Hotspots!A11 -> 20163010 | B8: =Hotspots!B11 -> Polyvinyl chloride, not mixed with any other substances, in primary forms | C8: =Hotspots!C11 -> Polyvinyl chloride | D8: =Hotspots!D11 -> 4.8304093 | E8: =Hotspots!E11 -> market for polyvinyl chloride, emulsion polymerised | F8: =Hotspots!F11 -> C2H3Cl | G8: =Hotspots!G11 -> 62.5 | H8: =Hotspots!H11 -> 2 | I8: =Hotspots!I11 -> 0.384352
A9: =Hotspots!A12 -> 20161039 | B9: =Hotspots!B12 -> Polyethylene having a specific gravity < 0,94, in primary forms (excluding linear) | C9: =Hotspots!C12 -> Polyethylene | D9: =Hotspots!D12 -> 4.2336403 | E9: =Hotspots!E12 -> market for polyethylene, low density, granulate | F9: =Hotspots!F12 -> (C2H4)n | G9: =Hotspots!G12 -> 28.054 | H9: =Hotspots!H12 -> 2 | I9: =Hotspots!I12 -> 0.85627718
A10: =Hotspots!A13 -> 20143430 | B10: =Hotspots!B13 -> Phthalic anhydride; terephthalic acid and its salts | C10: =Hotspots!C13 -> Terephthalic acid | D10: =Hotspots!D13 -> 4.0329537 | E10: =Hotspots!E13 -> market for purified terephthalic acid | F10: =Hotspots!F13 -> C8H6O4 | G10: =Hotspots!G13 -> 166.13 | H10: =Hotspots!H13 -> 8 | I10: =Hotspots!I13 -> 0.57839042
A11: =Hotspots!A14 -> 20164062 | B11: =Hotspots!B14 -> Polyethylene terephthalate in primary forms having a viscosity number of >= 78 ml/g | C11: =Hotspots!C14 -> Polyethylene terephthalate | D11: =Hotspots!D14 -> 3.3092991 | E11: =Hotspots!E14 -> market for polyethylene terephthalate, granulate, amorphous | F11: =Hotspots!F14 -> C12H14O4 | G11: =Hotspots!G14 -> 222.24 | H11: =Hotspots!H14 -> 12 | I11: =Hotspots!I14 -> 0.64854212
A12: =Hotspots!A15 -> 20141250 | B12: =Hotspots!B15 -> Styrene | C12: =Hotspots!C15 -> Styrene | D12: =Hotspots!D15 -> 2.9922404 | E12: =Hotspots!E15 -> market for styrene | F12: =Hotspots!F15 -> C8H8 | G12: =Hotspots!G15 -> 104.15 | H12: =Hotspots!H15 -> 8 | I12: =Hotspots!I15 -> 0.92259241
... A60: =Hotspots!A63 -> 20165450_2 | B60: =Hotspots!B63 -> Polyamide -6 (PA 6) | C60: =Hotspots!C63 -> Polyamide -6 | D60: =Hotspots!D63 -> 0.0079648559 | E60: =Hotspots!E63 -> market for nylon 6 | F60: =Hotspots!F63 -> C30H56N5O6- | G60: =Hotspots!G63 -> 582.8 | H60: =Hotspots!H63 -> 30 | I60: =Hotspots!I63 -> 0.61827385

Sheet References
B3: Citation | C3: Reference with URL
B4: (Khedr, 2023) | C4: Khedr, M.S.F. (2023) “Bio-based polyamide,” Physical Sciences Reviews, 8(7), pp. 827–847. Available at: https://doi.org/10.1515/psr-2020-0076.
B5: (Richter et al., 2024) | C5: Richter, F., Karafilidis, C. and Darmandeh, H. (2024) “Isocyanates, Organic,” Ullmann’s Encyclopedia of Industrial Chemistry. John Wiley & Sons, Ltd, pp. 1–23. Available at: https://doi.org/10.1002/14356007.a14_611.pub2.
B6: (Lorz et al., 2007) | C6: Lorz, P.M. et al. (2007) “Phthalic Acid and Derivatives,” Ullmann’s Encyclopedia of Industrial Chemistry. John Wiley & Sons, Ltd. Available at: https://doi.org/10.1002/14356007.a20_181.pub2.
B7: (Tomás et al., 2024) | C7: Tomás, R.A.F. et al. (2024) “Terephthalic Acid, Dimethyl Terephthalate, and Isophthalic Acid,” Ullmann’s Encyclopedia of Industrial Chemistry. John Wiley & Sons, Ltd, pp. 1–17. Available at: https://doi.org/10.1002/14356007.a26_193.pub3.
B8: (Kim et al., 2016) | C8: Kim, J.-H. et al. (2016) “Isoprene production by Escherichia coli through the exogenous mevalonate pathway with reduced formation of fermentation byproducts,” Microbial Cell Factories, 15(1), p. 214. Available at: https://doi.org/10.1186/s12934-016-0612-6.
B9: (Aldridge et al., 2021) | C9: Aldridge, J. et al. (2021) “Anaerobic Production of Isoprene by Engineered Methanosarcina Species Archaea,” Applied and Environmental Microbiology, 87(6), pp. e02417-20. Available at: https://doi.org/10.1128/AEM.02417-20.
B10: (Biddy et al., 2016) | C10: Biddy, M.J., Scarlata, C. and Kinchin, C. (2016) Chemicals from Biomass: A Market Assessment of Bioproducts with Near-Term Potential. NREL/TP--5100-65509, 1244312, p. NREL/TP--5100-65509, 1244312. Available at: https://doi.org/10.2172/1244312.
B11: (US EPA, 2022) | C11: US EPA (2022) “Chemical Data Reporting (CDR) Data 2020.” Available at: https://www.epa.gov/chemical-data-reporting/access-chemical-data-reporting-data#2020.
B12: (Sheldon and Brady, 2022) | C12: Sheldon, R.A. and Brady, D. (2022) “Green Chemistry, Biocatalysis, and the Chemical Industry of the Future,” ChemSusChem, 15(9), p. e202102628. Available at: https://doi.org/10.1002/cssc.202102628.
B13: (Hahn et al., 2013) | C13: Hahn, H.-D. et al. (2013) “Butanols,” in Ullmann’s Encyclopedia of Industrial Chemistry. John Wiley & Sons, Ltd. Available at: https://doi.org/10.1002/14356007.a04_463.pub3.
B14: (Falbe et al., 2013) | C14: Falbe, J. et al. (2013) “Alcohols, Aliphatic,” in Ullmann’s Encyclopedia of Industrial Chemistry. John Wiley & Sons, Ltd. Available at: https://doi.org/10.1002/14356007.a01_279.pub2.
... B20: (Hong and Xu, 2012) | C20: Hong, J. and Xu, X. (2012) “Environmental impact assessment of caprolactam production – a case study in China,” Journal of Cleaner Production, 27, pp. 103–108. Available at: https://doi.org/10.1016/j.jclepro.2011.12.037.
