Workbook

Sheet README
B2: README sheet
B5: General information
B7: Main paper title | C7: Residual biomass to bio-based chemicals and plastics: ex-ante screening methodology for prioritizing high-impact substitutions
B8: Authors | C8: Nicolas LIENART, Thibaut LECOMPTE, Lorie HAMELIN
B9: Contact (Nicolas Lienart) | C9: nicolas.lienart@insa-toulouse.fr
B10: Contact (Thibaut Lecompte) | C10: thibaut.lecompte@univ-ubs.fr
B11: Contact (Lorie Hamelin) | C11: lorie.hamelin@insa-toulouse.fr
B12: Description | C12: This file is contains the underlying data used to generate the Figure 2 in the main manuscript. It is corresponds to "Output_data/Hotspot products with footprint - processed.csv" file, generated by the following Python notebook: "Python_notebooks/Calculate hotspot products footprints and contributions.ipynb". The estimated GHG footprint of the production of the top products in the EU27, derived from the different representative origins. The upstream GHG footprint contribution of ethylene, propylene, methanol and BTX to the products’ footprint. GHG footprint estimated of the end of life of these products. Estimated total footprint, excluding the use phase, considered irrelevant due to the scope of this study.
B13: Note | C13: This file is part of a set of supplementary materials. Please refer to the main manuscript and the accompanying document to find other materials and for more information on the usage.
B14: Git repository (Forge INRAE) | C14: https://forge.inrae.fr/nicolas.lienart/screen-lca-paper-supplementary-code
B15: Git repository (GitHub) | C15: https://github.com/nicolnt/screen-lca-paper-supplementary-code
B18: Updates
B20: Date | C20: Note
B21: 46147 | C21: Ready for submission
B22: 46250 | C22: Update data and add Polyamides calculations
B23: 46251 | C23: Add sensitivity analysis
B24: 46254 | C24: Fixed PA-6 and PA-6,6 contributions
B25: 46255 | C25: Update figure 2 data and cleanings
B26: 46257 | C26: Update descriptions (README and sheets) + cleanings
B29: Sheet structure
B31: Sheet name | C31: Description
B32: README | C32: This sheet. Contains meta information about this Excel file and its structure.
B33: Figure 2 data | C33: ='Figure 2 data'!$B$1 -> Background data of main manuscript's figure 2 and hotspot products ranking.
B34: Location sensitivity analysis | C34: ='Location sensitivity analysis'!$B$1 -> Sensitivity analysis of Ecoinvent versions 3.11 and 3.12 for similar selected products and regions.
B35: EI version total sensitivity | C35: ='EI version total sensitivity'!$B$1 -> Sensitivity analysis of Ecoinvent versions 3.11 and 3.12 after aggration of the footprint across regions.
B36: PA-6 and PA-6,6 | C36: ='PA-6 and PA-6,6'!$B$1 -> Estimated contribution of some key intermediates to the unit footprint of polyamides (PA-6 and PA-6,6).
B39: Cell color nomenclature
B41: Style name | C41: Description | D41: Color | E41: Example 1 | F41: Example 2 | G41: Example 3
B42: Data Reference | C42: Data with reference (input) | D42: grey background | E42: 15 | F42: 0.041154 | G42: 5.5855e-05
B43: Formula | C43: Cell performing calculations using other cells | D43: blue | E43: 15 | F43: 0.041154 | G43: 5.5855e-05
B44: Data Linked Cell | C44: Cell refering to another, without transformation | D44: brown, italics | E44: 15 | F44: 0.041154 | G44: 5.5855e-05
B45: Text Reference | C45: Reference text | D45: small, grey, italic | E45: Bohers, 2024 - Com. Pers. | F45: (Muñoz and Weidema, 2024, p. 4) | G45: [2]
B46: Text Unit | C46: Unit | D46: small, centered | E46: kt.km | F46: MJ LHV/kg DM | G46: °C

Sheet Figure 2 data
A1: Sheet description: | B1: Background data of main manuscript's figure 2 and hotspot products ranking.
A2: Note: | B2: Some columns were added to the input file "Hotspot products with footprint - processed.csv". These are: "Unit footprint difference from 3.11 to 3.12" which you can find the use in the sheet "EI version total sensitivity". Whereas the two last columns at the right list products rank in terms of their total GHG footprint including end-of-life.
A4: Long name | B4: Figure name | C4: Quantity (Mt/yr) | D4: Local production share of available quantity (%) | E4: Carbon mass share | F4: propylene - ecoinvent-3.11-cutoff | G4: ethylene - ecoinvent-3.11-cutoff | H4: methanol - ecoinvent-3.11-cutoff | I4: xylene, mixed - ecoinvent-3.11-cutoff | J4: o-xylene - ecoinvent-3.11-cutoff | K4: p-xylene - ecoinvent-3.11-cutoff | L4: toluene, liquid - ecoinvent-3.11-cutoff | M4: benzene - ecoinvent-3.11-cutoff | N4: Unit GHG footprint without end-of-life (IPCC 2021 GWP100, kg CO2e/kg) - ecoinvent-3.11-cutoff | O4: Unit GHG footprint of local production share (IPCC 2021 GWP100, kg CO2e/kg) - ecoinvent-3.11-cutoff | P4: propylene - ecoinvent-3.12-cutoff | Q4: ethylene - ecoinvent-3.12-cutoff | R4: methanol - ecoinvent-3.12-cutoff | S4: xylene, mixed - ecoinvent-3.12-cutoff | T4: o-xylene - ecoinvent-3.12-cutoff | U4: p-xylene - ecoinvent-3.12-cutoff | V4: toluene, liquid - ecoinvent-3.12-cutoff | W4: benzene - ecoinvent-3.12-cutoff | X4: Unit GHG footprint without end-of-life (IPCC 2021 GWP100, kg CO2e/kg) - ecoinvent-3.12-cutoff | Y4: Unit GHG footprint of local production share (IPCC 2021 GWP100, kg CO2e/kg) - ecoinvent-3.12-cutoff | Z4: Unit impact of end-of-life (kg CO2/kg) - ecoinvent-3.11-cutoff | AA4: Unit impact of end-of-life (kg CO2/kg) - ecoinvent-3.12-cutoff | AB4: Unit GHG footprint with end-of-life (IPCC 2021 GWP100, kg CO2e/kg) - ecoinvent-3.11-cutoff | AC4: Total GHG footprint without end-of-life (IPCC 2021 GWP100, kg CO2e/kg) - ecoinvent-3.11-cutoff | AD4: Total GHG footprint with end-of-life (IPCC 2021 GWP100, kg CO2e/kg) - ecoinvent-3.11-cutoff | AE4: Unit GHG footprint with end-of-life (IPCC 2021 GWP100, kg CO2e/kg) - ecoinvent-3.12-cutoff | AF4: Total GHG footprint without end-of-life (IPCC 2021 GWP100, kg CO2e/kg) - ecoinvent-3.12-cutoff | AG4: Total GHG footprint with end-of-life (IPCC 2021 GWP100, kg CO2e/kg) - ecoinvent-3.12-cutoff | AH4: Unit GHG footprint of BTX (IPCC 2021 GWP100, kg CO2e/kg) - ecoinvent-3.11-cutoff | AI4: Unit footprint difference from 3.11 to 3.12 | AJ4: Total GHG footprint with end-of-life (IPCC 2021 GWP100, ranking) - ecoinvent-3.12-cutoff | AK4: Total GHG footprint with end-of-life (IPCC 2021 GWP100, ranking) - ecoinvent-3.11-cutoff
B5: Polyethylene | C5: 16.341803 | D5: 0.79716715 | E5: 0.85627718 | F5: 0 | G5: 2.0253247 | H5: 0.20909822 | I5: 0 | J5: 0 | K5: 0 | L5: 0 | M5: 0 | N5: 2.8520679 | O5: 2.2731411 | P5: 0 | Q5: 1.8783383 | R5: 0.10352275 | S5: 0 | T5: 0 | U5: 0 | V5: 0 | W5: 0 | X5: 2.5203887 | Y5: 1.9489412 | Z5: 0.79146547 | AA5: 0.79141808 | AB5: 3.6435334 | AC5: 46.607933 | AD5: 59.541907 | AE5: 3.3118068 | AF5: 41.187697 | AG5: 54.120896 | AH5: 0 | AI5: =(Hotspot_products_with_footprint___processed__2[[#This Row],[Unit GHG footprint without end-of-life (IPCC 2021 GWP100, kg CO2e/kg) - ecoinvent-3.12-cutoff]]-Hotspot_products_with_footprint___processed__2[[#This Row],[Unit GHG footprint without end-of-life (IPCC 2021 GWP100, kg CO2e/kg) - ecoinvent-3.11-cutoff]])/Hotspot_products_with_footprint___processed__2[[#This Row],[Unit GHG footprint without end-of-life (IPCC 2021 GWP100, kg CO2e/kg) - ecoinvent-3.11-cutoff]] -> -0.11629428 | AJ5: =_xlfn.RANK.AVG(Hotspot_products_with_footprint___processed__2[[#This Row],[Total GHG footprint with end-of-life (IPCC 2021 GWP100, kg CO2e/kg) - ecoinvent-3.12-cutoff]],Hotspot_products_with_footprint___processed__2[Total GHG footprint with end-of-life (IPCC 2021 GWP100, kg CO2e/kg) - ecoinvent-3.12-cutoff]) -> 1 | AK5: =_xlfn.RANK.AVG(Hotspot_products_with_footprint___processed__2[[#This Row],[Total GHG footprint with end-of-life (IPCC 2021 GWP100, kg CO2e/kg) - ecoinvent-3.11-cutoff]],Hotspot_products_with_footprint___processed__2[Total GHG footprint with end-of-life (IPCC 2021 GWP100, kg CO2e/kg) - ecoinvent-3.11-cutoff]) -> 1
A6: Polypropylene, in primary forms | B6: Polypropylene | C6: 11.059816 | D6: 0.86402105 | E6: 0.85627718 | F6: 2.2898038 | G6: 0.087581324 | H6: 0.46613209 | I6: 0 | J6: 0 | K6: 0 | L6: 0 | M6: 0 | N6: 3.0492256 | O6: 2.6345951 | P6: 1.84108 | Q6: 0.097479344 | R6: 0 | S6: 0 | T6: 0 | U6: 0 | V6: 0 | W6: 0 | X6: 2.3416386 | Y6: 2.0240234 | Z6: 0.79146547 | AA6: 0.79141808 | AB6: 3.8406911 | AC6: 33.723875 | AD6: 42.477338 | AE6: 3.1330567 | AF6: 25.898093 | AG6: 34.651032 | AH6: 0 | AI6: =(Hotspot_products_with_footprint___processed__2[[#This Row],[Unit GHG footprint without end-of-life (IPCC 2021 GWP100, kg CO2e/kg) - ecoinvent-3.12-cutoff]]-Hotspot_products_with_footprint___processed__2[[#This Row],[Unit GHG footprint without end-of-life (IPCC 2021 GWP100, kg CO2e/kg) - ecoinvent-3.11-cutoff]])/Hotspot_products_with_footprint___processed__2[[#This Row],[Unit GHG footprint without end-of-life (IPCC 2021 GWP100, kg CO2e/kg) - ecoinvent-3.11-cutoff]] -> -0.23205465 | AJ6: =_xlfn.RANK.AVG(Hotspot_products_with_footprint___processed__2[[#This Row],[Total GHG footprint with end-of-life (IPCC 2021 GWP100, kg CO2e/kg) - ecoinvent-3.12-cutoff]],Hotspot_products_with_footprint___processed__2[Total GHG footprint with end-of-life (IPCC 2021 GWP100, kg CO2e/kg) - ecoinvent-3.12-cutoff]) -> 2 | AK6: =_xlfn.RANK.AVG(Hotspot_products_with_footprint___processed__2[[#This Row],[Total GHG footprint with end-of-life (IPCC 2021 GWP100, kg CO2e/kg) - ecoinvent-3.11-cutoff]],Hotspot_products_with_footprint___processed__2[Total GHG footprint with end-of-life (IPCC 2021 GWP100, kg CO2e/kg) - ecoinvent-3.11-cutoff]) -> 2
A7: Ethylene | B7: Ethylene | C7: 10.337494 | D7: 0.87904863 | E7: 0.85639929 | F7: 0 | G7: 1.8229857 | H7: 0 | I7: 0 | J7: 0 | K7: 0 | L7: 0 | M7: 0 | N7: 1.8233935 | O7: 1.6007453 | P7: 0 | Q7: 1.8790377 | R7: 0 | S7: 0 | T7: 0 | U7: 0 | V7: 0 | W7: 0 | X7: 1.8792151 | Y7: 1.6640826 | Z7: 0.79157834 | AA7: 0.79153094 | AB7: 2.6149718 | AC7: 18.849318 | AD7: 27.032255 | AE7: 2.670746 | AF7: 19.426374 | AG7: 27.60882 | AH7: 0 | AI7: =(Hotspot_products_with_footprint___processed__2[[#This Row],[Unit GHG footprint without end-of-life (IPCC 2021 GWP100, kg CO2e/kg) - ecoinvent-3.12-cutoff]]-Hotspot_products_with_footprint___processed__2[[#This Row],[Unit GHG footprint without end-of-life (IPCC 2021 GWP100, kg CO2e/kg) - ecoinvent-3.11-cutoff]])/Hotspot_products_with_footprint___processed__2[[#This Row],[Unit GHG footprint without end-of-life (IPCC 2021 GWP100, kg CO2e/kg) - ecoinvent-3.11-cutoff]] -> 0.03061414 | AJ7: =_xlfn.RANK.AVG(Hotspot_products_with_footprint___processed__2[[#This Row],[Total GHG footprint with end-of-life (IPCC 2021 GWP100, kg CO2e/kg) - ecoinvent-3.12-cutoff]],Hotspot_products_with_footprint___processed__2[Total GHG footprint with end-of-life (IPCC 2021 GWP100, kg CO2e/kg) - ecoinvent-3.12-cutoff]) -> 3 | AK7: =_xlfn.RANK.AVG(Hotspot_products_with_footprint___processed__2[[#This Row],[Total GHG footprint with end-of-life (IPCC 2021 GWP100, kg CO2e/kg) - ecoinvent-3.11-cutoff]],Hotspot_products_with_footprint___processed__2[Total GHG footprint with end-of-life (IPCC 2021 GWP100, kg CO2e/kg) - ecoinvent-3.11-cutoff]) -> 3
B8: Polystyrene | C8: 3.4565416 | D8: 0.90760447 | E8: 0.9225747 | F8: 0 | G8: 0 | H8: 0 | I8: 0 | J8: 0 | K8: 0 | L8: 0 | M8: 0 | N8: 6.8079037 | O8: 6.2553833 | P8: 0.081772115 | Q8: 0.19288023 | R8: 0 | S8: 0 | T8: 0 | U8: 0 | V8: 0 | W8: 1.0552573 | X8: 6.844138 | Y8: 6.2668995 | Z8: 0.85274493 | AA8: 0.85269386 | AB8: 7.6606486 | AC8: 23.531803 | AD8: 26.479351 | AE8: 7.6968319 | AF8: 23.657048 | AG8: 26.60442 | AH8: 0 | AI8: =(Hotspot_products_with_footprint___processed__2[[#This Row],[Unit GHG footprint without end-of-life (IPCC 2021 GWP100, kg CO2e/kg) - ecoinvent-3.12-cutoff]]-Hotspot_products_with_footprint___processed__2[[#This Row],[Unit GHG footprint without end-of-life (IPCC 2021 GWP100, kg CO2e/kg) - ecoinvent-3.11-cutoff]])/Hotspot_products_with_footprint___processed__2[[#This Row],[Unit GHG footprint without end-of-life (IPCC 2021 GWP100, kg CO2e/kg) - ecoinvent-3.11-cutoff]] -> 0.0053223885 | AJ8: =_xlfn.RANK.AVG(Hotspot_products_with_footprint___processed__2[[#This Row],[Total GHG footprint with end-of-life (IPCC 2021 GWP100, kg CO2e/kg) - ecoinvent-3.12-cutoff]],Hotspot_products_with_footprint___processed__2[Total GHG footprint with end-of-life (IPCC 2021 GWP100, kg CO2e/kg) - ecoinvent-3.12-cutoff]) -> 4 | AK8: =_xlfn.RANK.AVG(Hotspot_products_with_footprint___processed__2[[#This Row],[Total GHG footprint with end-of-life (IPCC 2021 GWP100, kg CO2e/kg) - ecoinvent-3.11-cutoff]],Hotspot_products_with_footprint___processed__2[Total GHG footprint with end-of-life (IPCC 2021 GWP100, kg CO2e/kg) - ecoinvent-3.11-cutoff]) -> 4
A9: Propene (propylene) | B9: Propylene | C9: 9.0817412 | D9: 0.94409419 | E9: 0.85629753 | F9: 1.8227442 | G9: 0 | H9: 0 | I9: 0 | J9: 0 | K9: 0 | L9: 0 | M9: 0 | N9: 1.8227442 | O9: 1.7191931 | P9: 1.8872316 | Q9: 0 | R9: 0 | S9: 0 | T9: 0 | U9: 0 | V9: 0 | W9: 0 | X9: 1.887417 | Y9: 1.7872171 | Z9: 0.79148428 | AA9: 0.79143688 | AB9: 2.6142285 | AC9: 16.553691 | AD9: 23.741747 | AE9: 2.6788539 | AF9: 17.141033 | AG9: 24.328658 | AH9: 0 | AI9: =(Hotspot_products_with_footprint___processed__2[[#This Row],[Unit GHG footprint without end-of-life (IPCC 2021 GWP100, kg CO2e/kg) - ecoinvent-3.12-cutoff]]-Hotspot_products_with_footprint___processed__2[[#This Row],[Unit GHG footprint without end-of-life (IPCC 2021 GWP100, kg CO2e/kg) - ecoinvent-3.11-cutoff]])/Hotspot_products_with_footprint___processed__2[[#This Row],[Unit GHG footprint without end-of-life (IPCC 2021 GWP100, kg CO2e/kg) - ecoinvent-3.11-cutoff]] -> 0.035480987 | AJ9: =_xlfn.RANK.AVG(Hotspot_products_with_footprint___processed__2[[#This Row],[Total GHG footprint with end-of-life (IPCC 2021 GWP100, kg CO2e/kg) - ecoinvent-3.12-cutoff]],Hotspot_products_with_footprint___processed__2[Total GHG footprint with end-of-life (IPCC 2021 GWP100, kg CO2e/kg) - ecoinvent-3.12-cutoff]) -> 5 | AK9: =_xlfn.RANK.AVG(Hotspot_products_with_footprint___processed__2[[#This Row],[Total GHG footprint with end-of-life (IPCC 2021 GWP100, kg CO2e/kg) - ecoinvent-3.11-cutoff]],Hotspot_products_with_footprint___processed__2[Total GHG footprint with end-of-life (IPCC 2021 GWP100, kg CO2e/kg) - ecoinvent-3.11-cutoff]) -> 5
A10: Benzene | B10: Benzene | C10: 6.2344761 | D10: 0.88287081 | E10: 0.92262194 | F10: 0 | G10: 0 | H10: 0 | I10: 0 | J10: 0 | K10: 0 | L10: 0 | M10: 2.0397245 | N10: 2.0708825 | O10: 1.8229158 | P10: 0 | Q10: 0 | R10: 0 | S10: 0 | T10: 0 | U10: 0 | V10: 0 | W10: 2.0795315 | X10: 2.1111133 | Y10: 1.8689277 | Z10: 0.8527886 | AA10: 0.85273753 | AB10: 2.9236711 | AC10: 12.910867 | AD10: 18.227557 | AE10: 2.9638509 | AF10: 13.161686 | AG10: 18.478057 | AH10: 2.0397245 | AI10: =(Hotspot_products_with_footprint___processed__2[[#This Row],[Unit GHG footprint without end-of-life (IPCC 2021 GWP100, kg CO2e/kg) - ecoinvent-3.12-cutoff]]-Hotspot_products_with_footprint___processed__2[[#This Row],[Unit GHG footprint without end-of-life (IPCC 2021 GWP100, kg CO2e/kg) - ecoinvent-3.11-cutoff]])/Hotspot_products_with_footprint___processed__2[[#This Row],[Unit GHG footprint without end-of-life (IPCC 2021 GWP100, kg CO2e/kg) - ecoinvent-3.11-cutoff]] -> 0.019426919 | AJ10: =_xlfn.RANK.AVG(Hotspot_products_with_footprint___processed__2[[#This Row],[Total GHG footprint with end-of-life (IPCC 2021 GWP100, kg CO2e/kg) - ecoinvent-3.12-cutoff]],Hotspot_products_with_footprint___processed__2[Total GHG footprint with end-of-life (IPCC 2021 GWP100, kg CO2e/kg) - ecoinvent-3.12-cutoff]) -> 6 | AK10: =_xlfn.RANK.AVG(Hotspot_products_with_footprint___processed__2[[#This Row],[Total GHG footprint with end-of-life (IPCC 2021 GWP100, kg CO2e/kg) - ecoinvent-3.11-cutoff]],Hotspot_products_with_footprint___processed__2[Total GHG footprint with end-of-life (IPCC 2021 GWP100, kg CO2e/kg) - ecoinvent-3.11-cutoff]) -> 7
B11: Polyethylene terephthalate | C11: 4.2215209 | D11: 0.62536704 | E11: 0.64854212 | F11: 0 | G11: 0.38046779 | H11: 0 | I11: 0 | J11: 0 | K11: 1.396252 | L11: 0 | M11: 0 | N11: 3.7524039 | O11: 2.3466297 | P11: 0 | Q11: 0.21620964 | R11: 0 | S11: 0 | T11: 0 | U11: 1.381782 | V11: 0 | W11: 0 | X11: 3.7004456 | Y11: 2.3141367 | Z11: 0.5994539 | AA11: 0.599418 | AB11: 4.3518578 | AC11: 15.840851 | AD11: 18.371458 | AE11: 4.2998636 | AF11: 15.621508 | AG11: 18.151964 | AH11: 1.396252 | AI11: =(Hotspot_products_with_footprint___processed__2[[#This Row],[Unit GHG footprint without end-of-life (IPCC 2021 GWP100, kg CO2e/kg) - ecoinvent-3.12-cutoff]]-Hotspot_products_with_footprint___processed__2[[#This Row],[Unit GHG footprint without end-of-life (IPCC 2021 GWP100, kg CO2e/kg) - ecoinvent-3.11-cutoff]])/Hotspot_products_with_footprint___processed__2[[#This Row],[Unit GHG footprint without end-of-life (IPCC 2021 GWP100, kg CO2e/kg) - ecoinvent-3.11-cutoff]] -> -0.013846666 | AJ11: =_xlfn.RANK.AVG(Hotspot_products_with_footprint___processed__2[[#This Row],[Total GHG footprint with end-of-life (IPCC 2021 GWP100, kg CO2e/kg) - ecoinvent-3.12-cutoff]],Hotspot_products_with_footprint___processed__2[Total GHG footprint with end-of-life (IPCC 2021 GWP100, kg CO2e/kg) - ecoinvent-3.12-cutoff]) -> 7 | AK11: =_xlfn.RANK.AVG(Hotspot_products_with_footprint___processed__2[[#This Row],[Total GHG footprint with end-of-life (IPCC 2021 GWP100, kg CO2e/kg) - ecoinvent-3.11-cutoff]],Hotspot_products_with_footprint___processed__2[Total GHG footprint with end-of-life (IPCC 2021 GWP100, kg CO2e/kg) - ecoinvent-3.11-cutoff]) -> 6
B12: Polyvinyl chloride | C12: 5.7987685 | D12: 0.89855347 | E12: 0.384352 | F12: 0 | G12: 0.77474741 | H12: 0 | I12: 0 | J12: 0 | K12: 0 | L12: 0 | M12: 0 | N12: 2.3898169 | O12: 2.1059847 | P12: 0 | Q12: 0.80805099 | R12: 0 | S12: 0 | T12: 0 | U12: 0 | V12: 0 | W12: 0 | X12: 2.4470809 | Y12: 2.1681228 | Z12: 0.35526036 | AA12: 0.35523908 | AB12: 2.7450773 | AC12: 13.857995 | AD12: 15.918068 | AE12: 2.80232 | AF12: 14.190056 | AG12: 16.250005 | AH12: 0 | AI12: =(Hotspot_products_with_footprint___processed__2[[#This Row],[Unit GHG footprint without end-of-life (IPCC 2021 GWP100, kg CO2e/kg) - ecoinvent-3.12-cutoff]]-Hotspot_products_with_footprint___processed__2[[#This Row],[Unit GHG footprint without end-of-life (IPCC 2021 GWP100, kg CO2e/kg) - ecoinvent-3.11-cutoff]])/Hotspot_products_with_footprint___processed__2[[#This Row],[Unit GHG footprint without end-of-life (IPCC 2021 GWP100, kg CO2e/kg) - ecoinvent-3.11-cutoff]] -> 0.023961661 | AJ12: =_xlfn.RANK.AVG(Hotspot_products_with_footprint___processed__2[[#This Row],[Total GHG footprint with end-of-life (IPCC 2021 GWP100, kg CO2e/kg) - ecoinvent-3.12-cutoff]],Hotspot_products_with_footprint___processed__2[Total GHG footprint with end-of-life (IPCC 2021 GWP100, kg CO2e/kg) - ecoinvent-3.12-cutoff]) -> 8 | AK12: =_xlfn.RANK.AVG(Hotspot_products_with_footprint___processed__2[[#This Row],[Total GHG footprint with end-of-life (IPCC 2021 GWP100, kg CO2e/kg) - ecoinvent-3.11-cutoff]],Hotspot_products_with_footprint___processed__2[Total GHG footprint with end-of-life (IPCC 2021 GWP100, kg CO2e/kg) - ecoinvent-3.11-cutoff]) -> 8
A13: Styrene | B13: Styrene | C13: 3.6279764 | D13: 0.82690725 | E13: 0.92259241 | F13: 0 | G13: 0.52495977 | H13: 0 | I13: 0 | J13: 0 | K13: 0 | L13: 0 | M13: 1.6193502 | N13: 3.2906245 | O13: 2.6628764 | P13: 0.1566001 | Q13: 0.34269784 | R13: 0.01393295 | S13: 0 | T13: 0 | U13: 0 | V13: 0 | W13: 1.320802 | X13: 3.4341758 | Y13: 2.7761663 | Z13: 0.8527613 | AA13: 0.85271023 | AB13: 4.1433858 | AC13: 11.938308 | AD13: 15.032106 | AE13: 4.2868861 | AF13: 12.459109 | AG13: 15.552721 | AH13: 1.6193502 | AI13: =(Hotspot_products_with_footprint___processed__2[[#This Row],[Unit GHG footprint without end-of-life (IPCC 2021 GWP100, kg CO2e/kg) - ecoinvent-3.12-cutoff]]-Hotspot_products_with_footprint___processed__2[[#This Row],[Unit GHG footprint without end-of-life (IPCC 2021 GWP100, kg CO2e/kg) - ecoinvent-3.11-cutoff]])/Hotspot_products_with_footprint___processed__2[[#This Row],[Unit GHG footprint without end-of-life (IPCC 2021 GWP100, kg CO2e/kg) - ecoinvent-3.11-cutoff]] -> 0.043624346 | AJ13: =_xlfn.RANK.AVG(Hotspot_products_with_footprint___processed__2[[#This Row],[Total GHG footprint with end-of-life (IPCC 2021 GWP100, kg CO2e/kg) - ecoinvent-3.12-cutoff]],Hotspot_products_with_footprint___processed__2[Total GHG footprint with end-of-life (IPCC 2021 GWP100, kg CO2e/kg) - ecoinvent-3.12-cutoff]) -> 9 | AK13: =_xlfn.RANK.AVG(Hotspot_products_with_footprint___processed__2[[#This Row],[Total GHG footprint with end-of-life (IPCC 2021 GWP100, kg CO2e/kg) - ecoinvent-3.11-cutoff]],Hotspot_products_with_footprint___processed__2[Total GHG footprint with end-of-life (IPCC 2021 GWP100, kg CO2e/kg) - ecoinvent-3.11-cutoff]) -> 9
A14: Polyamide -6 (PA 6) | B14: Polyamide -6 | C14: 1.281304 | D14: 0.87748443 | E14: 0.61827385 | F14: 0 | G14: 0 | H14: 0 | I14: 0 | J14: 0 | K14: 0 | L14: 0 | M14: 0 | N14: 9.3128699 | O14: 8.166357 | P14: 0 | Q14: 0 | R14: 0 | S14: 0 | T14: 0 | U14: 0 | V14: 0 | W14: 0 | X14: 9.313357 | Y14: 8.1667954 | Z14: 0.57147664 | AA14: 0.57144242 | AB14: 9.8843465 | AC14: 11.932618 | AD14: 12.664853 | AE14: 9.8847994 | AF14: 11.933242 | AG14: 12.665433 | AH14: 0 | AI14: =(Hotspot_products_with_footprint___processed__2[[#This Row],[Unit GHG footprint without end-of-life (IPCC 2021 GWP100, kg CO2e/kg) - ecoinvent-3.12-cutoff]]-Hotspot_products_with_footprint___processed__2[[#This Row],[Unit GHG footprint without end-of-life (IPCC 2021 GWP100, kg CO2e/kg) - ecoinvent-3.11-cutoff]])/Hotspot_products_with_footprint___processed__2[[#This Row],[Unit GHG footprint without end-of-life (IPCC 2021 GWP100, kg CO2e/kg) - ecoinvent-3.11-cutoff]] -> 5.2307002e-05 | AJ14: =_xlfn.RANK.AVG(Hotspot_products_with_footprint___processed__2[[#This Row],[Total GHG footprint with end-of-life (IPCC 2021 GWP100, kg CO2e/kg) - ecoinvent-3.12-cutoff]],Hotspot_products_with_footprint___processed__2[Total GHG footprint with end-of-life (IPCC 2021 GWP100, kg CO2e/kg) - ecoinvent-3.12-cutoff]) -> 10 | AK14: =_xlfn.RANK.AVG(Hotspot_products_with_footprint___processed__2[[#This Row],[Total GHG footprint with end-of-life (IPCC 2021 GWP100, kg CO2e/kg) - ecoinvent-3.11-cutoff]],Hotspot_products_with_footprint___processed__2[Total GHG footprint with end-of-life (IPCC 2021 GWP100, kg CO2e/kg) - ecoinvent-3.11-cutoff]) -> 10
A15: Phthalic anhydride; terephthalic acid and its salts | B15: Terephthalic acid | C15: 3.4912837 | D15: 0.80199726 | E15: 0.57839042 | F15: 0 | G15: 0 | H15: 0 | I15: 0 | J15: 0 | K15: 1.6028378 | L15: 0 | M15: 0 | N15: 2.5228002 | O15: 2.0232789 | P15: 0 | Q15: 0 | R15: 0 | S15: 0 | T15: 0 | U15: 1.5862268 | V15: 0 | W15: 0 | X15: 2.5077725 | Y15: 2.0112267 | Z15: 0.53461199 | AA15: 0.53457997 | AB15: 3.0574122 | AC15: 8.8078113 | AD15: 10.674293 | AE15: 3.0423524 | AF15: 8.7553452 | AG15: 10.621716 | AH15: 1.6028378 | AI15: =(Hotspot_products_with_footprint___processed__2[[#This Row],[Unit GHG footprint without end-of-life (IPCC 2021 GWP100, kg CO2e/kg) - ecoinvent-3.12-cutoff]]-Hotspot_products_with_footprint___processed__2[[#This Row],[Unit GHG footprint without end-of-life (IPCC 2021 GWP100, kg CO2e/kg) - ecoinvent-3.11-cutoff]])/Hotspot_products_with_footprint___processed__2[[#This Row],[Unit GHG footprint without end-of-life (IPCC 2021 GWP100, kg CO2e/kg) - ecoinvent-3.11-cutoff]] -> -0.0059567623 | AJ15: =_xlfn.RANK.AVG(Hotspot_products_with_footprint___processed__2[[#This Row],[Total GHG footprint with end-of-life (IPCC 2021 GWP100, kg CO2e/kg) - ecoinvent-3.12-cutoff]],Hotspot_products_with_footprint___processed__2[Total GHG footprint with end-of-life (IPCC 2021 GWP100, kg CO2e/kg) - ecoinvent-3.12-cutoff]) -> 11 | AK15: =_xlfn.RANK.AVG(Hotspot_products_with_footprint___processed__2[[#This Row],[Total GHG footprint with end-of-life (IPCC 2021 GWP100, kg CO2e/kg) - ecoinvent-3.11-cutoff]],Hotspot_products_with_footprint___processed__2[Total GHG footprint with end-of-life (IPCC 2021 GWP100, kg CO2e/kg) - ecoinvent-3.11-cutoff]) -> 11
A16: Buta-1,3-diene and isoprene | B16: Butadiene | C16: 2.8089403 | D16: 0.99681721 | E16: 0.88822333 | F16: 0 | G16: 0 | H16: 0 | I16: 0 | J16: 0 | K16: 0 | L16: 0 | M16: 0 | N16: 2.6680622 | O16: 2.6595703 | P16: 0 | Q16: 0 | R16: 0 | S16: 0 | T16: 0 | U16: 0 | V16: 0 | W16: 0 | X16: 2.722181 | Y16: 2.7135169 | Z16: 0.82099362 | AA16: 0.82094445 | AB16: 3.4890558 | AC16: 7.4944273 | AD16: 9.8005493 | AE16: 3.5431255 | AF16: 7.6464438 | AG16: 9.9524278 | AH16: 0 | AI16: =(Hotspot_products_with_footprint___processed__2[[#This Row],[Unit GHG footprint without end-of-life (IPCC 2021 GWP100, kg CO2e/kg) - ecoinvent-3.12-cutoff]]-Hotspot_products_with_footprint___processed__2[[#This Row],[Unit GHG footprint without end-of-life (IPCC 2021 GWP100, kg CO2e/kg) - ecoinvent-3.11-cutoff]])/Hotspot_products_with_footprint___processed__2[[#This Row],[Unit GHG footprint without end-of-life (IPCC 2021 GWP100, kg CO2e/kg) - ecoinvent-3.11-cutoff]] -> 0.020283941 | AJ16: =_xlfn.RANK.AVG(Hotspot_products_with_footprint___processed__2[[#This Row],[Total GHG footprint with end-of-life (IPCC 2021 GWP100, kg CO2e/kg) - ecoinvent-3.12-cutoff]],Hotspot_products_with_footprint___processed__2[Total GHG footprint with end-of-life (IPCC 2021 GWP100, kg CO2e/kg) - ecoinvent-3.12-cutoff]) -> 12 | AK16: =_xlfn.RANK.AVG(Hotspot_products_with_footprint___processed__2[[#This Row],[Total GHG footprint with end-of-life (IPCC 2021 GWP100, kg CO2e/kg) - ecoinvent-3.11-cutoff]],Hotspot_products_with_footprint___processed__2[Total GHG footprint with end-of-life (IPCC 2021 GWP100, kg CO2e/kg) - ecoinvent-3.11-cutoff]) -> 12
A17: Polyamide -6,6 (PA 66) | B17: Polyamide -6,6 | C17: 1.0891084 | D17: 0.87748443 | E17: 0.64258582 | F17: 0 | G17: 0 | H17: 0 | I17: 0 | J17: 0 | K17: 0 | L17: 0 | M17: 0 | N17: 8.2583219 | O17: 7.2412295 | P17: 0 | Q17: 0 | R17: 0 | S17: 0 | T17: 0 | U17: 0 | V17: 0 | W17: 0 | X17: 8.258558 | Y17: 7.2414488 | Z17: 0.59394844 | AA17: 0.59391287 | AB17: 8.8522704 | AC17: 8.9942079 | AD17: 9.6410822 | AE17: 8.8524708 | AF17: 8.994465 | AG17: 9.6413005 | AH17: 0 | AI17: =(Hotspot_products_with_footprint___processed__2[[#This Row],[Unit GHG footprint without end-of-life (IPCC 2021 GWP100, kg CO2e/kg) - ecoinvent-3.12-cutoff]]-Hotspot_products_with_footprint___processed__2[[#This Row],[Unit GHG footprint without end-of-life (IPCC 2021 GWP100, kg CO2e/kg) - ecoinvent-3.11-cutoff]])/Hotspot_products_with_footprint___processed__2[[#This Row],[Unit GHG footprint without end-of-life (IPCC 2021 GWP100, kg CO2e/kg) - ecoinvent-3.11-cutoff]] -> 2.8581649e-05 | AJ17: =_xlfn.RANK.AVG(Hotspot_products_with_footprint___processed__2[[#This Row],[Total GHG footprint with end-of-life (IPCC 2021 GWP100, kg CO2e/kg) - ecoinvent-3.12-cutoff]],Hotspot_products_with_footprint___processed__2[Total GHG footprint with end-of-life (IPCC 2021 GWP100, kg CO2e/kg) - ecoinvent-3.12-cutoff]) -> 13 | AK17: =_xlfn.RANK.AVG(Hotspot_products_with_footprint___processed__2[[#This Row],[Total GHG footprint with end-of-life (IPCC 2021 GWP100, kg CO2e/kg) - ecoinvent-3.11-cutoff]],Hotspot_products_with_footprint___processed__2[Total GHG footprint with end-of-life (IPCC 2021 GWP100, kg CO2e/kg) - ecoinvent-3.11-cutoff]) -> 13
A18: Methanol (methyl alcohol) | B18: Methanol | C18: 6.9047321 | D18: 0.14193165 | E18: 0.37485176 | F18: 0 | G18: 0 | H18: 0.87252981 | I18: 0 | J18: 0 | K18: 0 | L18: 0 | M18: 0 | N18: 0.92062271 | O18: 0.12771242 | P18: 0 | Q18: 0 | R18: 0.77340937 | S18: 0 | T18: 0 | U18: 0 | V18: 0 | W18: 0 | X18: 0.80693462 | Y18: 0.10036032 | Z18: 0.34647919 | AA18: 0.34645844 | AB18: 1.2671019 | AC18: 6.3566531 | AD18: 8.7489991 | AE18: 1.1533931 | AF18: 5.5716674 | AG18: 7.9638701 | AH18: 0 | AI18: =(Hotspot_products_with_footprint___processed__2[[#This Row],[Unit GHG footprint without end-of-life (IPCC 2021 GWP100, kg CO2e/kg) - ecoinvent-3.12-cutoff]]-Hotspot_products_with_footprint___processed__2[[#This Row],[Unit GHG footprint without end-of-life (IPCC 2021 GWP100, kg CO2e/kg) - ecoinvent-3.11-cutoff]])/Hotspot_products_with_footprint___processed__2[[#This Row],[Unit GHG footprint without end-of-life (IPCC 2021 GWP100, kg CO2e/kg) - ecoinvent-3.11-cutoff]] -> -0.12349042 | AJ18: =_xlfn.RANK.AVG(Hotspot_products_with_footprint___processed__2[[#This Row],[Total GHG footprint with end-of-life (IPCC 2021 GWP100, kg CO2e/kg) - ecoinvent-3.12-cutoff]],Hotspot_products_with_footprint___processed__2[Total GHG footprint with end-of-life (IPCC 2021 GWP100, kg CO2e/kg) - ecoinvent-3.12-cutoff]) -> 14 | AK18: =_xlfn.RANK.AVG(Hotspot_products_with_footprint___processed__2[[#This Row],[Total GHG footprint with end-of-life (IPCC 2021 GWP100, kg CO2e/kg) - ecoinvent-3.11-cutoff]],Hotspot_products_with_footprint___processed__2[Total GHG footprint with end-of-life (IPCC 2021 GWP100, kg CO2e/kg) - ecoinvent-3.11-cutoff]) -> 14
A19: Methyloxirane (propylene oxide) | B19: Propylene oxide | C19: 1.6509382 | D19: 0.9816867 | E19: 0.62040289 | F19: 1.3987993 | G19: 0 | H19: 0.0085084549 | I19: 0 | J19: 0 | K19: 0 | L19: 0 | M19: 0 | N19: 3.9956526 | O19: 3.8862974 | P19: 1.0473606 | Q19: 0.095733197 | R19: 0 | S19: 0 | T19: 0 | U19: 0 | V19: 0 | W19: 0.44242597 | X19: 3.8886831 | Y19: 3.8350204 | Z19: 0.57344454 | AA19: 0.57341019 | AB19: 4.5690971 | AC19: 6.5965754 | AD19: 7.5432969 | AE19: 4.4620933 | AF19: 6.4199753 | AG19: 7.3666401 | AH19: 0 | AI19: =(Hotspot_products_with_footprint___processed__2[[#This Row],[Unit GHG footprint without end-of-life (IPCC 2021 GWP100, kg CO2e/kg) - ecoinvent-3.12-cutoff]]-Hotspot_products_with_footprint___processed__2[[#This Row],[Unit GHG footprint without end-of-life (IPCC 2021 GWP100, kg CO2e/kg) - ecoinvent-3.11-cutoff]])/Hotspot_products_with_footprint___processed__2[[#This Row],[Unit GHG footprint without end-of-life (IPCC 2021 GWP100, kg CO2e/kg) - ecoinvent-3.11-cutoff]] -> -0.026771482 | AJ19: =_xlfn.RANK.AVG(Hotspot_products_with_footprint___processed__2[[#This Row],[Total GHG footprint with end-of-life (IPCC 2021 GWP100, kg CO2e/kg) - ecoinvent-3.12-cutoff]],Hotspot_products_with_footprint___processed__2[Total GHG footprint with end-of-life (IPCC 2021 GWP100, kg CO2e/kg) - ecoinvent-3.12-cutoff]) -> 15 | AK19: =_xlfn.RANK.AVG(Hotspot_products_with_footprint___processed__2[[#This Row],[Total GHG footprint with end-of-life (IPCC 2021 GWP100, kg CO2e/kg) - ecoinvent-3.11-cutoff]],Hotspot_products_with_footprint___processed__2[Total GHG footprint with end-of-life (IPCC 2021 GWP100, kg CO2e/kg) - ecoinvent-3.11-cutoff]) -> 15
A20: Adipic acid; its salts and esters | B20: Adipic acid | C20: 0.66765557 | D20: 0.85514301 | E20: 0.49312987 | F20: 0 | G20: 0 | H20: 0 | I20: 0 | J20: 0 | K20: 0 | L20: 0 | M20: 1.4184179 | N20: 9.3705514 | O20: 8.0131615 | P20: 0 | Q20: 0 | R20: 0 | S20: 0 | T20: 0 | U20: 0 | V20: 0 | W20: 1.3618999 | X20: 9.2674948 | Y20: 7.9250334 | Z20: 0.45580483 | AA20: 0.45577753 | AB20: 9.8263562 | AC20: 6.2563008 | AD20: 6.5606214 | AE20: 9.7232723 | AF20: 6.1874945 | AG20: 6.4917969 | AH20: 1.4184179 | AI20: =(Hotspot_products_with_footprint___processed__2[[#This Row],[Unit GHG footprint without end-of-life (IPCC 2021 GWP100, kg CO2e/kg) - ecoinvent-3.12-cutoff]]-Hotspot_products_with_footprint___processed__2[[#This Row],[Unit GHG footprint without end-of-life (IPCC 2021 GWP100, kg CO2e/kg) - ecoinvent-3.11-cutoff]])/Hotspot_products_with_footprint___processed__2[[#This Row],[Unit GHG footprint without end-of-life (IPCC 2021 GWP100, kg CO2e/kg) - ecoinvent-3.11-cutoff]] -> -0.01099792 | AJ20: =_xlfn.RANK.AVG(Hotspot_products_with_footprint___processed__2[[#This Row],[Total GHG footprint with end-of-life (IPCC 2021 GWP100, kg CO2e/kg) - ecoinvent-3.12-cutoff]],Hotspot_products_with_footprint___processed__2[Total GHG footprint with end-of-life (IPCC 2021 GWP100, kg CO2e/kg) - ecoinvent-3.12-cutoff]) -> 16 | AK20: =_xlfn.RANK.AVG(Hotspot_products_with_footprint___processed__2[[#This Row],[Total GHG footprint with end-of-life (IPCC 2021 GWP100, kg CO2e/kg) - ecoinvent-3.11-cutoff]],Hotspot_products_with_footprint___processed__2[Total GHG footprint with end-of-life (IPCC 2021 GWP100, kg CO2e/kg) - ecoinvent-3.11-cutoff]) -> 16
A21: Butene (butylene) and isomers thereof | B21: Butylene | C21: 2.0000467 | D21: 0.99997667 | E21: 0.85632297 | F21: 0 | G21: 0 | H21: 0 | I21: 0 | J21: 0 | K21: 0 | L21: 0 | M21: 0 | N21: 1.823771 | O21: 1.8237285 | P21: 0 | Q21: 0 | R21: 0 | S21: 0 | T21: 0 | U21: 0 | V21: 0 | W21: 0 | X21: 1.9168251 | Y21: 1.9167803 | Z21: 0.79150779 | AA21: 0.7914604 | AB21: 2.6152788 | AC21: 3.6476272 | AD21: 5.2306797 | AE21: 2.7082855 | AF21: 3.8337396 | AG21: 5.4166973 | AH21: 0 | AI21: =(Hotspot_products_with_footprint___processed__2[[#This Row],[Unit GHG footprint without end-of-life (IPCC 2021 GWP100, kg CO2e/kg) - ecoinvent-3.12-cutoff]]-Hotspot_products_with_footprint___processed__2[[#This Row],[Unit GHG footprint without end-of-life (IPCC 2021 GWP100, kg CO2e/kg) - ecoinvent-3.11-cutoff]])/Hotspot_products_with_footprint___processed__2[[#This Row],[Unit GHG footprint without end-of-life (IPCC 2021 GWP100, kg CO2e/kg) - ecoinvent-3.11-cutoff]] -> 0.051022868 | AJ21: =_xlfn.RANK.AVG(Hotspot_products_with_footprint___processed__2[[#This Row],[Total GHG footprint with end-of-life (IPCC 2021 GWP100, kg CO2e/kg) - ecoinvent-3.12-cutoff]],Hotspot_products_with_footprint___processed__2[Total GHG footprint with end-of-life (IPCC 2021 GWP100, kg CO2e/kg) - ecoinvent-3.12-cutoff]) -> 17 | AK21: =_xlfn.RANK.AVG(Hotspot_products_with_footprint___processed__2[[#This Row],[Total GHG footprint with end-of-life (IPCC 2021 GWP100, kg CO2e/kg) - ecoinvent-3.11-cutoff]],Hotspot_products_with_footprint___processed__2[Total GHG footprint with end-of-life (IPCC 2021 GWP100, kg CO2e/kg) - ecoinvent-3.11-cutoff]) -> 17
B22: Polyvinyl acetate | C22: 1.1656359 | D22: 0.94369094 | E22: 0.55806846 | F22: 0 | G22: 0.60815483 | H22: 0.54204056 | I22: 0 | J22: 0 | K22: 0 | L22: 0 | M22: 0 | N22: 3.7664818 | O22: 3.5316817 | P22: 0 | Q22: 0.62808393 | R22: 0.49158701 | S22: 0 | T22: 0 | U22: 0 | V22: 0 | W22: 0 | X22: 3.7929504 | Y22: 3.5579418 | Z22: 0.51582821 | AA22: 0.51579732 | AB22: 4.28231 | AC22: 4.3903463 | AD22: 4.9916142 | AE22: 4.3087477 | AF22: 4.421199 | AG22: 5.0224309 | AH22: 0 | AI22: =(Hotspot_products_with_footprint___processed__2[[#This Row],[Unit GHG footprint without end-of-life (IPCC 2021 GWP100, kg CO2e/kg) - ecoinvent-3.12-cutoff]]-Hotspot_products_with_footprint___processed__2[[#This Row],[Unit GHG footprint without end-of-life (IPCC 2021 GWP100, kg CO2e/kg) - ecoinvent-3.11-cutoff]])/Hotspot_products_with_footprint___processed__2[[#This Row],[Unit GHG footprint without end-of-life (IPCC 2021 GWP100, kg CO2e/kg) - ecoinvent-3.11-cutoff]] -> 0.0070274018 | AJ22: =_xlfn.RANK.AVG(Hotspot_products_with_footprint___processed__2[[#This Row],[Total GHG footprint with end-of-life (IPCC 2021 GWP100, kg CO2e/kg) - ecoinvent-3.12-cutoff]],Hotspot_products_with_footprint___processed__2[Total GHG footprint with end-of-life (IPCC 2021 GWP100, kg CO2e/kg) - ecoinvent-3.12-cutoff]) -> 18 | AK22: =_xlfn.RANK.AVG(Hotspot_products_with_footprint___processed__2[[#This Row],[Total GHG footprint with end-of-life (IPCC 2021 GWP100, kg CO2e/kg) - ecoinvent-3.11-cutoff]],Hotspot_products_with_footprint___processed__2[Total GHG footprint with end-of-life (IPCC 2021 GWP100, kg CO2e/kg) - ecoinvent-3.11-cutoff]) -> 18
A23: Ethylene glycol (ethanediol) | B23: Ethylene glycol | C23: 1.795748 | D23: 0.55687102 | E23: 0.38701466 | F23: 0 | G23: 1.1060938 | H23: 0.065547266 | I23: 0 | J23: 0 | K23: 0 | L23: 0 | M23: 0 | N23: 2.3143899 | O23: 1.0975335 | P23: 0 | Q23: 1.0384735 | R23: 0 | S23: 0 | T23: 0 | U23: 0 | V23: 0 | W23: 0 | X23: 2.2670109 | Y23: 1.1420034 | Z23: 0.35772148 | AA23: 0.35770006 | AB23: 2.6721114 | AC23: 4.1560609 | AD23: 4.7984385 | AE23: 2.624711 | AF23: 4.0709802 | AG23: 4.7133194 | AH23: 0 | AI23: =(Hotspot_products_with_footprint___processed__2[[#This Row],[Unit GHG footprint without end-of-life (IPCC 2021 GWP100, kg CO2e/kg) - ecoinvent-3.12-cutoff]]-Hotspot_products_with_footprint___processed__2[[#This Row],[Unit GHG footprint without end-of-life (IPCC 2021 GWP100, kg CO2e/kg) - ecoinvent-3.11-cutoff]])/Hotspot_products_with_footprint___processed__2[[#This Row],[Unit GHG footprint without end-of-life (IPCC 2021 GWP100, kg CO2e/kg) - ecoinvent-3.11-cutoff]] -> -0.020471468 | AJ23: =_xlfn.RANK.AVG(Hotspot_products_with_footprint___processed__2[[#This Row],[Total GHG footprint with end-of-life (IPCC 2021 GWP100, kg CO2e/kg) - ecoinvent-3.12-cutoff]],Hotspot_products_with_footprint___processed__2[Total GHG footprint with end-of-life (IPCC 2021 GWP100, kg CO2e/kg) - ecoinvent-3.12-cutoff]) -> 19 | AK23: =_xlfn.RANK.AVG(Hotspot_products_with_footprint___processed__2[[#This Row],[Total GHG footprint with end-of-life (IPCC 2021 GWP100, kg CO2e/kg) - ecoinvent-3.11-cutoff]],Hotspot_products_with_footprint___processed__2[Total GHG footprint with end-of-life (IPCC 2021 GWP100, kg CO2e/kg) - ecoinvent-3.11-cutoff]) -> 19
A24: Acrylonitrile-butadiene-styrene (ABS) copolymers, in primary forms | B24: ABS | C24: 0.84621718 | D24: 0.71535186 | E24: 0.85265026 | F24: 0 | G24: 0 | H24: 0 | I24: 0 | J24: 0 | K24: 0 | L24: 0 | M24: 0 | N24: 4.652506 | O24: 3.3281789 | P24: 0 | Q24: 0 | R24: 0 | S24: 0 | T24: 0 | U24: 0 | V24: 0 | W24: 0 | X24: 4.6563134 | Y24: 3.3309024 | Z24: 0.78811308 | AA24: 0.78806588 | AB24: 5.4406191 | AC24: 3.9370306 | AD24: 4.6039454 | AE24: 5.4443793 | AF24: 3.9402524 | AG24: 4.6071273 | AH24: 0 | AI24: =(Hotspot_products_with_footprint___processed__2[[#This Row],[Unit GHG footprint without end-of-life (IPCC 2021 GWP100, kg CO2e/kg) - ecoinvent-3.12-cutoff]]-Hotspot_products_with_footprint___processed__2[[#This Row],[Unit GHG footprint without end-of-life (IPCC 2021 GWP100, kg CO2e/kg) - ecoinvent-3.11-cutoff]])/Hotspot_products_with_footprint___processed__2[[#This Row],[Unit GHG footprint without end-of-life (IPCC 2021 GWP100, kg CO2e/kg) - ecoinvent-3.11-cutoff]] -> 0.00081834015 | AJ24: =_xlfn.RANK.AVG(Hotspot_products_with_footprint___processed__2[[#This Row],[Total GHG footprint with end-of-life (IPCC 2021 GWP100, kg CO2e/kg) - ecoinvent-3.12-cutoff]],Hotspot_products_with_footprint___processed__2[Total GHG footprint with end-of-life (IPCC 2021 GWP100, kg CO2e/kg) - ecoinvent-3.12-cutoff]) -> 20 | AK24: =_xlfn.RANK.AVG(Hotspot_products_with_footprint___processed__2[[#This Row],[Total GHG footprint with end-of-life (IPCC 2021 GWP100, kg CO2e/kg) - ecoinvent-3.11-cutoff]],Hotspot_products_with_footprint___processed__2[Total GHG footprint with end-of-life (IPCC 2021 GWP100, kg CO2e/kg) - ecoinvent-3.11-cutoff]) -> 20
A25: Aniline and its salts (excluding derivatives) | B25: Aniline | C25: 0.88188416 | D25: 0.54958148 | E25: 0.77382154 | F25: 0 | G25: 0 | H25: 0 | I25: 0 | J25: 0 | K25: 0 | L25: 0 | M25: 1.7982059 | N25: 4.041807 | O25: 2.0547061 | P25: 0 | Q25: 0 | R25: 0 | S25: 0 | T25: 0 | U25: 0 | V25: 0 | W25: 1.8139449 | X25: 4.0341592 | Y25: 2.0675814 | Z25: 0.71525091 | AA25: 0.71520808 | AB25: 4.7570579 | AC25: 3.5644056 | AD25: 4.195174 | AE25: 4.7493672 | AF25: 3.5576611 | AG25: 4.1883917 | AH25: 1.7982059 | AI25: =(Hotspot_products_with_footprint___processed__2[[#This Row],[Unit GHG footprint without end-of-life (IPCC 2021 GWP100, kg CO2e/kg) - ecoinvent-3.12-cutoff]]-Hotspot_products_with_footprint___processed__2[[#This Row],[Unit GHG footprint without end-of-life (IPCC 2021 GWP100, kg CO2e/kg) - ecoinvent-3.11-cutoff]])/Hotspot_products_with_footprint___processed__2[[#This Row],[Unit GHG footprint without end-of-life (IPCC 2021 GWP100, kg CO2e/kg) - ecoinvent-3.11-cutoff]] -> -0.0018921813 | AJ25: =_xlfn.RANK.AVG(Hotspot_products_with_footprint___processed__2[[#This Row],[Total GHG footprint with end-of-life (IPCC 2021 GWP100, kg CO2e/kg) - ecoinvent-3.12-cutoff]],Hotspot_products_with_footprint___processed__2[Total GHG footprint with end-of-life (IPCC 2021 GWP100, kg CO2e/kg) - ecoinvent-3.12-cutoff]) -> 21 | AK25: =_xlfn.RANK.AVG(Hotspot_products_with_footprint___processed__2[[#This Row],[Total GHG footprint with end-of-life (IPCC 2021 GWP100, kg CO2e/kg) - ecoinvent-3.11-cutoff]],Hotspot_products_with_footprint___processed__2[Total GHG footprint with end-of-life (IPCC 2021 GWP100, kg CO2e/kg) - ecoinvent-3.11-cutoff]) -> 21
A26: Methylene diphenyl diisocyanate (MDI) | B26: Methylene diphenyl diisocyanate | C26: 0.80713989 | D26: 0.88632048 | E26: 0.71994006 | F26: 0 | G26: 0 | H26: 0.14056402 | I26: 0 | J26: 0 | K26: 0 | L26: 0 | M26: 1.2785377 | N26: 4.3594129 | O26: 3.6884527 | P26: 0 | Q26: 0 | R26: 0.11236074 | S26: 0 | T26: 0 | U26: 0 | V26: 0 | W26: 1.2984377 | X26: 4.3702366 | Y26: 3.7085235 | Z26: 0.66544772 | AA26: 0.66540787 | AB26: 5.0248607 | AC26: 3.5186561 | AD26: 4.0557655 | AE26: 5.0356445 | AF26: 3.5273923 | AG26: 4.0644696 | AH26: 1.2785377 | AI26: =(Hotspot_products_with_footprint___processed__2[[#This Row],[Unit GHG footprint without end-of-life (IPCC 2021 GWP100, kg CO2e/kg) - ecoinvent-3.12-cutoff]]-Hotspot_products_with_footprint___processed__2[[#This Row],[Unit GHG footprint without end-of-life (IPCC 2021 GWP100, kg CO2e/kg) - ecoinvent-3.11-cutoff]])/Hotspot_products_with_footprint___processed__2[[#This Row],[Unit GHG footprint without end-of-life (IPCC 2021 GWP100, kg CO2e/kg) - ecoinvent-3.11-cutoff]] -> 0.0024828307 | AJ26: =_xlfn.RANK.AVG(Hotspot_products_with_footprint___processed__2[[#This Row],[Total GHG footprint with end-of-life (IPCC 2021 GWP100, kg CO2e/kg) - ecoinvent-3.12-cutoff]],Hotspot_products_with_footprint___processed__2[Total GHG footprint with end-of-life (IPCC 2021 GWP100, kg CO2e/kg) - ecoinvent-3.12-cutoff]) -> 22 | AK26: =_xlfn.RANK.AVG(Hotspot_products_with_footprint___processed__2[[#This Row],[Total GHG footprint with end-of-life (IPCC 2021 GWP100, kg CO2e/kg) - ecoinvent-3.11-cutoff]],Hotspot_products_with_footprint___processed__2[Total GHG footprint with end-of-life (IPCC 2021 GWP100, kg CO2e/kg) - ecoinvent-3.11-cutoff]) -> 22
A27: p-Xylene | B27: p-Xylene | C27: 1.1919059 | D27: 0.46597636 | E27: 0.90512434 | F27: 0 | G27: 0 | H27: 0 | I27: 0 | J27: 0 | K27: 2.3272589 | L27: 0 | M27: 0 | N27: 2.3702606 | O27: 1.0511815 | P27: 0 | Q27: 0 | R27: 0 | S27: 0 | T27: 0 | U27: 2.3164478 | V27: 0 | W27: 0 | X27: 2.3594663 | Y27: 1.0582346 | Z27: 0.83661539 | AA27: 0.83656529 | AB27: 3.206876 | AC27: 2.8251277 | AD27: 3.8222946 | AE27: 3.1960316 | AF27: 2.812262 | AG27: 3.8093691 | AH27: 2.3272589 | AI27: =(Hotspot_products_with_footprint___processed__2[[#This Row],[Unit GHG footprint without end-of-life (IPCC 2021 GWP100, kg CO2e/kg) - ecoinvent-3.12-cutoff]]-Hotspot_products_with_footprint___processed__2[[#This Row],[Unit GHG footprint without end-of-life (IPCC 2021 GWP100, kg CO2e/kg) - ecoinvent-3.11-cutoff]])/Hotspot_products_with_footprint___processed__2[[#This Row],[Unit GHG footprint without end-of-life (IPCC 2021 GWP100, kg CO2e/kg) - ecoinvent-3.11-cutoff]] -> -0.0045540421 | AJ27: =_xlfn.RANK.AVG(Hotspot_products_with_footprint___processed__2[[#This Row],[Total GHG footprint with end-of-life (IPCC 2021 GWP100, kg CO2e/kg) - ecoinvent-3.12-cutoff]],Hotspot_products_with_footprint___processed__2[Total GHG footprint with end-of-life (IPCC 2021 GWP100, kg CO2e/kg) - ecoinvent-3.12-cutoff]) -> 23 | AK27: =_xlfn.RANK.AVG(Hotspot_products_with_footprint___processed__2[[#This Row],[Total GHG footprint with end-of-life (IPCC 2021 GWP100, kg CO2e/kg) - ecoinvent-3.11-cutoff]],Hotspot_products_with_footprint___processed__2[Total GHG footprint with end-of-life (IPCC 2021 GWP100, kg CO2e/kg) - ecoinvent-3.11-cutoff]) -> 23
A28: Acrylonitrile | B28: Acrylonitrile | C28: 0.7050691 | D28: 0.85098042 | E28: 0.67909913 | F28: 2.0256107 | G28: 0 | H28: 0.33981589 | I28: 0 | J28: 0 | K28: 0 | L28: 0 | M28: 0 | N28: 4.2530783 | O28: 3.6192864 | P28: 2.38111 | Q28: 0 | R28: 0.7273549 | S28: 0 | T28: 0 | U28: 0 | V28: 0 | W28: 0 | X28: 4.560202 | Y28: 3.8806426 | Z28: 0.62769805 | AA28: 0.62766046 | AB28: 4.8807764 | AC28: 2.9987141 | AD28: 3.4412846 | AE28: 5.1878624 | AF28: 3.2152575 | AG28: 3.6578015 | AH28: 0 | AI28: =(Hotspot_products_with_footprint___processed__2[[#This Row],[Unit GHG footprint without end-of-life (IPCC 2021 GWP100, kg CO2e/kg) - ecoinvent-3.12-cutoff]]-Hotspot_products_with_footprint___processed__2[[#This Row],[Unit GHG footprint without end-of-life (IPCC 2021 GWP100, kg CO2e/kg) - ecoinvent-3.11-cutoff]])/Hotspot_products_with_footprint___processed__2[[#This Row],[Unit GHG footprint without end-of-life (IPCC 2021 GWP100, kg CO2e/kg) - ecoinvent-3.11-cutoff]] -> 0.072212084 | AJ28: =_xlfn.RANK.AVG(Hotspot_products_with_footprint___processed__2[[#This Row],[Total GHG footprint with end-of-life (IPCC 2021 GWP100, kg CO2e/kg) - ecoinvent-3.12-cutoff]],Hotspot_products_with_footprint___processed__2[Total GHG footprint with end-of-life (IPCC 2021 GWP100, kg CO2e/kg) - ecoinvent-3.12-cutoff]) -> 24 | AK28: =_xlfn.RANK.AVG(Hotspot_products_with_footprint___processed__2[[#This Row],[Total GHG footprint with end-of-life (IPCC 2021 GWP100, kg CO2e/kg) - ecoinvent-3.11-cutoff]],Hotspot_products_with_footprint___processed__2[Total GHG footprint with end-of-life (IPCC 2021 GWP100, kg CO2e/kg) - ecoinvent-3.11-cutoff]) -> 25
A29: Propylene glycol (propane-1,2-diol) | B29: Propylene glycol | C29: 0.8480267 | D29: 0.94336652 | E29: 0.47355763 | F29: 1.1345319 | G29: 0 | H29: 0.015324448 | I29: 0 | J29: 0 | K29: 0 | L29: 0 | M29: 0 | N29: 3.6807731 | O29: 3.394633 | P29: 0.85972843 | Q29: 0.043325595 | R29: 0.015354897 | S29: 0 | T29: 0 | U29: 0 | V29: 0 | W29: 0.33888787 | X29: 3.6263996 | Y29: 3.3615332 | Z29: 0.437714 | AA29: 0.43768779 | AB29: 4.1184871 | AC29: 3.1213939 | AD29: 3.4925871 | AE29: 4.0640873 | AF29: 3.0752836 | AG29: 3.4464546 | AH29: 0 | AI29: =(Hotspot_products_with_footprint___processed__2[[#This Row],[Unit GHG footprint without end-of-life (IPCC 2021 GWP100, kg CO2e/kg) - ecoinvent-3.12-cutoff]]-Hotspot_products_with_footprint___processed__2[[#This Row],[Unit GHG footprint without end-of-life (IPCC 2021 GWP100, kg CO2e/kg) - ecoinvent-3.11-cutoff]])/Hotspot_products_with_footprint___processed__2[[#This Row],[Unit GHG footprint without end-of-life (IPCC 2021 GWP100, kg CO2e/kg) - ecoinvent-3.11-cutoff]] -> -0.014772325 | AJ29: =_xlfn.RANK.AVG(Hotspot_products_with_footprint___processed__2[[#This Row],[Total GHG footprint with end-of-life (IPCC 2021 GWP100, kg CO2e/kg) - ecoinvent-3.12-cutoff]],Hotspot_products_with_footprint___processed__2[Total GHG footprint with end-of-life (IPCC 2021 GWP100, kg CO2e/kg) - ecoinvent-3.12-cutoff]) -> 25 | AK29: =_xlfn.RANK.AVG(Hotspot_products_with_footprint___processed__2[[#This Row],[Total GHG footprint with end-of-life (IPCC 2021 GWP100, kg CO2e/kg) - ecoinvent-3.11-cutoff]],Hotspot_products_with_footprint___processed__2[Total GHG footprint with end-of-life (IPCC 2021 GWP100, kg CO2e/kg) - ecoinvent-3.11-cutoff]) -> 24
A30: Acetone | B30: Acetone | C30: 1.0908528 | D30: 0.92846916 | E30: 0.62040289 | F30: 0.5393341 | G30: 0 | H30: 0 | I30: 0 | J30: 0 | K30: 0 | L30: 0 | M30: 0.90714275 | N30: 2.3764657 | O30: 2.1781584 | P30: 0.55494801 | Q30: 0 | R30: 0.0083501376 | S30: 0 | T30: 0 | U30: 0 | V30: 0 | W30: 0.92516332 | X30: 2.4212604 | Y30: 2.2186032 | Z30: 0.57344454 | AA30: 0.57341019 | AB30: 2.9499102 | AC30: 2.5923742 | AD30: 3.2179178 | AE30: 2.9946706 | AF30: 2.6412387 | AG30: 3.2667449 | AH30: 0.90714275 | AI30: =(Hotspot_products_with_footprint___processed__2[[#This Row],[Unit GHG footprint without end-of-life (IPCC 2021 GWP100, kg CO2e/kg) - ecoinvent-3.12-cutoff]]-Hotspot_products_with_footprint___processed__2[[#This Row],[Unit GHG footprint without end-of-life (IPCC 2021 GWP100, kg CO2e/kg) - ecoinvent-3.11-cutoff]])/Hotspot_products_with_footprint___processed__2[[#This Row],[Unit GHG footprint without end-of-life (IPCC 2021 GWP100, kg CO2e/kg) - ecoinvent-3.11-cutoff]] -> 0.01884933 | AJ30: =_xlfn.RANK.AVG(Hotspot_products_with_footprint___processed__2[[#This Row],[Total GHG footprint with end-of-life (IPCC 2021 GWP100, kg CO2e/kg) - ecoinvent-3.12-cutoff]],Hotspot_products_with_footprint___processed__2[Total GHG footprint with end-of-life (IPCC 2021 GWP100, kg CO2e/kg) - ecoinvent-3.12-cutoff]) -> 26 | AK30: =_xlfn.RANK.AVG(Hotspot_products_with_footprint___processed__2[[#This Row],[Total GHG footprint with end-of-life (IPCC 2021 GWP100, kg CO2e/kg) - ecoinvent-3.11-cutoff]],Hotspot_products_with_footprint___processed__2[Total GHG footprint with end-of-life (IPCC 2021 GWP100, kg CO2e/kg) - ecoinvent-3.11-cutoff]) -> 27
A31: Esters of acrylic acid | B31: Esters of acrylic acid | C31: 0.60486187 | D31: 0.66130801 | E31: 0.65598546 | F31: 1.5141786 | G31: 0 | H31: 0.084834187 | I31: 0 | J31: 0 | K31: 0 | L31: 0 | M31: 0 | N31: 5.0474475 | O31: 3.2582523 | P31: 1.6122145 | Q31: 0 | R31: 0.31633236 | S31: 0 | T31: 0 | U31: 0 | V31: 0 | W31: 0 | X31: 4.7059811 | Y31: 2.9583587 | Z31: 0.60633385 | AA31: 0.60629754 | AB31: 5.6537814 | AC31: 3.0530086 | AD31: 3.4197568 | AE31: 5.3122786 | AF31: 2.8464685 | AG31: 3.2131948 | AH31: 0 | AI31: =(Hotspot_products_with_footprint___processed__2[[#This Row],[Unit GHG footprint without end-of-life (IPCC 2021 GWP100, kg CO2e/kg) - ecoinvent-3.12-cutoff]]-Hotspot_products_with_footprint___processed__2[[#This Row],[Unit GHG footprint without end-of-life (IPCC 2021 GWP100, kg CO2e/kg) - ecoinvent-3.11-cutoff]])/Hotspot_products_with_footprint___processed__2[[#This Row],[Unit GHG footprint without end-of-life (IPCC 2021 GWP100, kg CO2e/kg) - ecoinvent-3.11-cutoff]] -> -0.067651311 | AJ31: =_xlfn.RANK.AVG(Hotspot_products_with_footprint___processed__2[[#This Row],[Total GHG footprint with end-of-life (IPCC 2021 GWP100, kg CO2e/kg) - ecoinvent-3.12-cutoff]],Hotspot_products_with_footprint___processed__2[Total GHG footprint with end-of-life (IPCC 2021 GWP100, kg CO2e/kg) - ecoinvent-3.12-cutoff]) -> 27 | AK31: =_xlfn.RANK.AVG(Hotspot_products_with_footprint___processed__2[[#This Row],[Total GHG footprint with end-of-life (IPCC 2021 GWP100, kg CO2e/kg) - ecoinvent-3.11-cutoff]],Hotspot_products_with_footprint___processed__2[Total GHG footprint with end-of-life (IPCC 2021 GWP100, kg CO2e/kg) - ecoinvent-3.11-cutoff]) -> 26
A32: Toluene | B32: Toluene | C32: 1.1203816 | D32: 0.97878773 | E32: 0.91249186 | F32: 0 | G32: 0 | H32: 0 | I32: 0 | J32: 0 | K32: 0 | L32: 1.5751178 | M32: 0 | N32: 1.6040023 | O32: 1.5699777 | P32: 0 | Q32: 0 | R32: 0 | S32: 0 | T32: 0 | U32: 0 | V32: 1.5979644 | W32: 0 | X32: 1.6269595 | Y32: 1.5924479 | Z32: 0.84342526 | AA32: 0.84337475 | AB32: 2.4474275 | AC32: 1.7970946 | AD32: 2.7420528 | AE32: 2.4703342 | AF32: 1.8228155 | AG32: 2.767717 | AH32: 1.5751178 | AI32: =(Hotspot_products_with_footprint___processed__2[[#This Row],[Unit GHG footprint without end-of-life (IPCC 2021 GWP100, kg CO2e/kg) - ecoinvent-3.12-cutoff]]-Hotspot_products_with_footprint___processed__2[[#This Row],[Unit GHG footprint without end-of-life (IPCC 2021 GWP100, kg CO2e/kg) - ecoinvent-3.11-cutoff]])/Hotspot_products_with_footprint___processed__2[[#This Row],[Unit GHG footprint without end-of-life (IPCC 2021 GWP100, kg CO2e/kg) - ecoinvent-3.11-cutoff]] -> 0.014312443 | AJ32: =_xlfn.RANK.AVG(Hotspot_products_with_footprint___processed__2[[#This Row],[Total GHG footprint with end-of-life (IPCC 2021 GWP100, kg CO2e/kg) - ecoinvent-3.12-cutoff]],Hotspot_products_with_footprint___processed__2[Total GHG footprint with end-of-life (IPCC 2021 GWP100, kg CO2e/kg) - ecoinvent-3.12-cutoff]) -> 28 | AK32: =_xlfn.RANK.AVG(Hotspot_products_with_footprint___processed__2[[#This Row],[Total GHG footprint with end-of-life (IPCC 2021 GWP100, kg CO2e/kg) - ecoinvent-3.11-cutoff]],Hotspot_products_with_footprint___processed__2[Total GHG footprint with end-of-life (IPCC 2021 GWP100, kg CO2e/kg) - ecoinvent-3.11-cutoff]) -> 29
A33: Cyclohexane | B33: Cyclohexane | C33: 0.68331502 | D33: 0.35122893 | E33: 0.85629753 | F33: 0 | G33: 0 | H33: 0 | I33: 0 | J33: 0 | K33: 0 | L33: 0 | M33: 2.1042734 | N33: 3.346811 | O33: 1.1754968 | P33: 0 | Q33: 0 | R33: 0 | S33: 0 | T33: 0 | U33: 0 | V33: 0 | W33: 2.0204269 | X33: 3.2313182 | Y33: 1.1349324 | Z33: 0.79148428 | AA33: 0.79143688 | AB33: 4.1382952 | AC33: 2.2869262 | AD33: 2.8277593 | AE33: 4.0227551 | AF33: 2.2080083 | AG33: 2.748809 | AH33: 2.1042734 | AI33: =(Hotspot_products_with_footprint___processed__2[[#This Row],[Unit GHG footprint without end-of-life (IPCC 2021 GWP100, kg CO2e/kg) - ecoinvent-3.12-cutoff]]-Hotspot_products_with_footprint___processed__2[[#This Row],[Unit GHG footprint without end-of-life (IPCC 2021 GWP100, kg CO2e/kg) - ecoinvent-3.11-cutoff]])/Hotspot_products_with_footprint___processed__2[[#This Row],[Unit GHG footprint without end-of-life (IPCC 2021 GWP100, kg CO2e/kg) - ecoinvent-3.11-cutoff]] -> -0.034508294 | AJ33: =_xlfn.RANK.AVG(Hotspot_products_with_footprint___processed__2[[#This Row],[Total GHG footprint with end-of-life (IPCC 2021 GWP100, kg CO2e/kg) - ecoinvent-3.12-cutoff]],Hotspot_products_with_footprint___processed__2[Total GHG footprint with end-of-life (IPCC 2021 GWP100, kg CO2e/kg) - ecoinvent-3.12-cutoff]) -> 29 | AK33: =_xlfn.RANK.AVG(Hotspot_products_with_footprint___processed__2[[#This Row],[Total GHG footprint with end-of-life (IPCC 2021 GWP100, kg CO2e/kg) - ecoinvent-3.11-cutoff]],Hotspot_products_with_footprint___processed__2[Total GHG footprint with end-of-life (IPCC 2021 GWP100, kg CO2e/kg) - ecoinvent-3.11-cutoff]) -> 28
A34: Oxirane (ethylene oxide) | B34: Ethylene oxide | C34: 0.88675938 | D34: 0.99498026 | E34: 0.54533485 | F34: 0 | G34: 1.4494602 | H34: 0 | I34: 0 | J34: 0 | K34: 0 | L34: 0 | M34: 0 | N34: 2.484765 | O34: 2.4722922 | P34: 0 | Q34: 1.5022957 | R34: 0 | S34: 0 | T34: 0 | U34: 0 | V34: 0 | W34: 0 | X34: 2.5852853 | Y34: 2.5723078 | Z34: 0.5040584 | AA34: 0.50402821 | AB34: 2.9888234 | AC34: 2.2033887 | AD34: 2.6503672 | AE34: 3.0893135 | AF34: 2.2925259 | AG34: 2.7394777 | AH34: 0 | AI34: =(Hotspot_products_with_footprint___processed__2[[#This Row],[Unit GHG footprint without end-of-life (IPCC 2021 GWP100, kg CO2e/kg) - ecoinvent-3.12-cutoff]]-Hotspot_products_with_footprint___processed__2[[#This Row],[Unit GHG footprint without end-of-life (IPCC 2021 GWP100, kg CO2e/kg) - ecoinvent-3.11-cutoff]])/Hotspot_products_with_footprint___processed__2[[#This Row],[Unit GHG footprint without end-of-life (IPCC 2021 GWP100, kg CO2e/kg) - ecoinvent-3.11-cutoff]] -> 0.040454613 | AJ34: =_xlfn.RANK.AVG(Hotspot_products_with_footprint___processed__2[[#This Row],[Total GHG footprint with end-of-life (IPCC 2021 GWP100, kg CO2e/kg) - ecoinvent-3.12-cutoff]],Hotspot_products_with_footprint___processed__2[Total GHG footprint with end-of-life (IPCC 2021 GWP100, kg CO2e/kg) - ecoinvent-3.12-cutoff]) -> 30 | AK34: =_xlfn.RANK.AVG(Hotspot_products_with_footprint___processed__2[[#This Row],[Total GHG footprint with end-of-life (IPCC 2021 GWP100, kg CO2e/kg) - ecoinvent-3.11-cutoff]],Hotspot_products_with_footprint___processed__2[Total GHG footprint with end-of-life (IPCC 2021 GWP100, kg CO2e/kg) - ecoinvent-3.11-cutoff]) -> 31
... A55: Chloromethane (methyl chloride) and chloroethane (ethyl chloride) | B55: Chloromethane | C55: 0.30089411 | D55: 0.9970285 | E55: 0.23788869 | F55: 0 | G55: 0 | H55: 0.59860106 | I55: 0 | J55: 0 | K55: 0 | L55: 0 | M55: 0 | N55: 2.8318778 | O55: 2.8234629 | P55: 0 | Q55: 0 | R55: 0.47039902 | S55: 0 | T55: 0 | U55: 0 | V55: 0 | W55: 0 | X55: 2.722985 | Y55: 2.7148937 | Z55: 0.21988287 | AA55: 0.2198697 | AB55: 3.0517607 | AC55: 0.85209534 | AD55: 0.9182568 | AE55: 2.9428547 | AF55: 0.81933014 | AG55: 0.88548763 | AH55: 0 | AI55: =(Hotspot_products_with_footprint___processed__2[[#This Row],[Unit GHG footprint without end-of-life (IPCC 2021 GWP100, kg CO2e/kg) - ecoinvent-3.12-cutoff]]-Hotspot_products_with_footprint___processed__2[[#This Row],[Unit GHG footprint without end-of-life (IPCC 2021 GWP100, kg CO2e/kg) - ecoinvent-3.11-cutoff]])/Hotspot_products_with_footprint___processed__2[[#This Row],[Unit GHG footprint without end-of-life (IPCC 2021 GWP100, kg CO2e/kg) - ecoinvent-3.11-cutoff]] -> -0.038452504 | AJ55: =_xlfn.RANK.AVG(Hotspot_products_with_footprint___processed__2[[#This Row],[Total GHG footprint with end-of-life (IPCC 2021 GWP100, kg CO2e/kg) - ecoinvent-3.12-cutoff]],Hotspot_products_with_footprint___processed__2[Total GHG footprint with end-of-life (IPCC 2021 GWP100, kg CO2e/kg) - ecoinvent-3.12-cutoff]) -> 51 | AK55: =_xlfn.RANK.AVG(Hotspot_products_with_footprint___processed__2[[#This Row],[Total GHG footprint with end-of-life (IPCC 2021 GWP100, kg CO2e/kg) - ecoinvent-3.11-cutoff]],Hotspot_products_with_footprint___processed__2[Total GHG footprint with end-of-life (IPCC 2021 GWP100, kg CO2e/kg) - ecoinvent-3.11-cutoff]) -> 51

Sheet Location sensitivity analysis
A1: Sheet description: | B1: Sensitivity analysis of Ecoinvent versions 3.11 and 3.12 for similar selected products and regions.
A2: Note: | B2: Ecoinvent licence does not allow to provide raw unit footprint data.
B4: % change from 3.11 to 3.12
A5: location | B5: GLO | C5: CN | D5: ZA | E5: RER | F5: US | K5: Results
A6: activity
A7: market for polypropylene, granulate | B7: =IFERROR((('[1]Ecoinvent 3.11-3.12 location 2'!G4-'[1]Ecoinvent 3.11-3.12 location 2'!B4)/'[1]Ecoinvent 3.11-3.12 location 2'!B4), "") | C7: =IFERROR((('[1]Ecoinvent 3.11-3.12 location 2'!H4-'[1]Ecoinvent 3.11-3.12 location 2'!C4)/'[1]Ecoinvent 3.11-3.12 location 2'!C4), "") | D7: =IFERROR((('[1]Ecoinvent 3.11-3.12 location 2'!I4-'[1]Ecoinvent 3.11-3.12 location 2'!D4)/'[1]Ecoinvent 3.11-3.12 location 2'!D4), "") | E7: =IFERROR((('[1]Ecoinvent 3.11-3.12 location 2'!J4-'[1]Ecoinvent 3.11-3.12 location 2'!E4)/'[1]Ecoinvent 3.11-3.12 location 2'!E4), "") | F7: =IFERROR((('[1]Ecoinvent 3.11-3.12 location 2'!K4-'[1]Ecoinvent 3.11-3.12 location 2'!F4)/'[1]Ecoinvent 3.11-3.12 location 2'!F4), "") | K7: N (not empty) | L7: {=SUMPRODUCT(--('Location sensitivity analysis'!B7:F59<>""))} -> 50
A8: market for ethylene | B8: =IFERROR((('[1]Ecoinvent 3.11-3.12 location 2'!G5-'[1]Ecoinvent 3.11-3.12 location 2'!B5)/'[1]Ecoinvent 3.11-3.12 location 2'!B5), "") | C8: =IFERROR((('[1]Ecoinvent 3.11-3.12 location 2'!H5-'[1]Ecoinvent 3.11-3.12 location 2'!C5)/'[1]Ecoinvent 3.11-3.12 location 2'!C5), "") -> -0.021380906 | D8: =IFERROR((('[1]Ecoinvent 3.11-3.12 location 2'!I5-'[1]Ecoinvent 3.11-3.12 location 2'!D5)/'[1]Ecoinvent 3.11-3.12 location 2'!D5), "") -> -0.4287776 | E8: =IFERROR((('[1]Ecoinvent 3.11-3.12 location 2'!J5-'[1]Ecoinvent 3.11-3.12 location 2'!E5)/'[1]Ecoinvent 3.11-3.12 location 2'!E5), "") | F8: =IFERROR((('[1]Ecoinvent 3.11-3.12 location 2'!K5-'[1]Ecoinvent 3.11-3.12 location 2'!F5)/'[1]Ecoinvent 3.11-3.12 location 2'!F5), "") | K8: MEAN | L8: =AVERAGE('Location sensitivity analysis'!B7:F59) -> -0.018664317
A9: market for propylene | B9: =IFERROR((('[1]Ecoinvent 3.11-3.12 location 2'!G6-'[1]Ecoinvent 3.11-3.12 location 2'!B6)/'[1]Ecoinvent 3.11-3.12 location 2'!B6), "") | C9: =IFERROR((('[1]Ecoinvent 3.11-3.12 location 2'!H6-'[1]Ecoinvent 3.11-3.12 location 2'!C6)/'[1]Ecoinvent 3.11-3.12 location 2'!C6), "") -> -0.032219837 | D9: =IFERROR((('[1]Ecoinvent 3.11-3.12 location 2'!I6-'[1]Ecoinvent 3.11-3.12 location 2'!D6)/'[1]Ecoinvent 3.11-3.12 location 2'!D6), "") -> -0.048539137 | E9: =IFERROR((('[1]Ecoinvent 3.11-3.12 location 2'!J6-'[1]Ecoinvent 3.11-3.12 location 2'!E6)/'[1]Ecoinvent 3.11-3.12 location 2'!E6), "") | F9: =IFERROR((('[1]Ecoinvent 3.11-3.12 location 2'!K6-'[1]Ecoinvent 3.11-3.12 location 2'!F6)/'[1]Ecoinvent 3.11-3.12 location 2'!F6), "") | K9: MEDIAN | L9: =MEDIAN('Location sensitivity analysis'!B7:F59) -> 0.0026137375
